<?xml version='1.0' encoding='utf-8'?>
<robot name="xarm7">
  <link name="link_base">
    <inertial>
      <origin rpy="0 0 0" xyz="-0.021131 -0.0016302 0.056488" />
      <mass value="0.88556" />
      <inertia ixx="0.0030595" ixy="0.00012259" ixz="-0.00062705" iyy="0.0037783" iyz="0.00027023" izz="0.0020125" />
      </inertial>
    <visual>
      <geometry>
        <mesh filename="meshes/visual/link_base.glb" />
        </geometry>
      <origin rpy="0 0 0" xyz="0 0 0" />
      </visual>
    <collision>
      <geometry>
        <mesh filename="meshes/collision/link_base.obj" />
        </geometry>
      <origin rpy="0 0 0" xyz="0 0 0" />
      </collision>
    </link>
  <link name="link1">
    <inertial>
      <origin rpy="0 0 0" xyz="-0.0002 0.02905 -0.01233" />
      <mass value="2.382" />
      <inertia ixx="0.0056905" ixy="-1.579e-05" ixz="5.125e-06" iyy="0.0049566" iyz="-0.000873378" izz="0.003316654" />
      </inertial>
    <visual>
      <geometry>
        <mesh filename="meshes/visual/link1.glb" />
        </geometry>
      <origin rpy="0 0 0" xyz="0 0 0" />
      </visual>
    <collision>
      <geometry>
        <mesh filename="meshes/collision/link1.obj" />
        </geometry>
      <origin rpy="0 0 0" xyz="0 0 0" />
      </collision>
    </link>
  <joint name="xarm7_joint1" type="revolute">
    <origin rpy="0 0 0" xyz="0 0 0.267" />
    <parent link="link_base" />
    <child link="link1" />
    <axis xyz="0 0 1" />
    <limit effort="50" lower="-6.28318530718" upper="6.28318530718" velocity="3.14" />
    <dynamics damping="10" friction="1" />
    </joint>
  <link name="link2">
    <inertial>
      <origin rpy="0 0 0" xyz="0.00022 -0.12856 0.01735" />
      <mass value="1.869" />
      <inertia ixx="0.0095989" ixy="1.541e-06" ixz="5.56e-06" iyy="0.00382472" iyz="-0.00317156" izz="0.007565669" />
      </inertial>
    <visual>
      <geometry>
        <mesh filename="meshes/visual/link2.glb" />
        </geometry>
      <origin rpy="0 0 0" xyz="0 0 0" />
      </visual>
    <collision>
      <geometry>
        <mesh filename="meshes/collision/link2.obj" />
        </geometry>
      <origin rpy="0 0 0" xyz="0 0 0" />
      </collision>
    </link>
  <joint name="xarm7_joint2" type="revolute">
    <origin rpy="-1.5708 0 0" xyz="0 0 0" />
    <parent link="link1" />
    <child link="link2" />
    <axis xyz="0 0 1" />
    <limit effort="50" lower="-2.059" upper="2.0944" velocity="3.14" />
    <dynamics damping="10" friction="1" />
    </joint>
  <link name="link3">
    <inertial>
      <origin rpy="0 0 0" xyz="0.0466 -0.02463 -0.00768" />
      <mass value="1.6383" />
      <inertia ixx="0.00310955" ixy="0.00030837" ixz="-0.00058453" iyy="0.00264483" iyz="0.000338893" izz="0.0026624" />
      </inertial>
    <visual>
      <geometry>
        <mesh filename="meshes/visual/link3.glb" />
        </geometry>
      <origin rpy="0 0 0" xyz="0 0 0" />
      </visual>
    <collision>
      <geometry>
        <mesh filename="meshes/collision/link3.obj" />
        </geometry>
      <origin rpy="0 0 0" xyz="0 0 0" />
      </collision>
    </link>
  <joint name="xarm7_joint3" type="revolute">
    <origin rpy="1.5708 0 0" xyz="0 -0.293 0" />
    <parent link="link2" />
    <child link="link3" />
    <axis xyz="0 0 1" />
    <limit effort="30" lower="-6.28318530718" upper="6.28318530718" velocity="3.14" />
    <dynamics damping="5" friction="1" />
    </joint>
  <link name="link4">
    <inertial>
      <origin rpy="0 0 0" xyz="0.07047 -0.11575 0.012" />
      <mass value="1.7269" />
      <inertia ixx="0.005889" ixy="0.00137112" ixz="0.00088143" iyy="0.00359703" iyz="-0.001762155" izz="0.00543244" />
      </inertial>
    <visual>
      <geometry>
        <mesh filename="meshes/visual/link4.glb" />
        </geometry>
      <origin rpy="0 0 0" xyz="0 0 0" />
      </visual>
    <collision>
      <geometry>
        <mesh filename="meshes/collision/link4.obj" />
        </geometry>
      <origin rpy="0 0 0" xyz="0 0 0" />
      </collision>
    </link>
  <joint name="xarm7_joint4" type="revolute">
    <origin rpy="1.5708 0 0" xyz="0.0525 0 0" />
    <parent link="link3" />
    <child link="link4" />
    <axis xyz="0 0 1" />
    <limit effort="30" lower="-0.19198" upper="3.927" velocity="3.14" />
    <dynamics damping="5" friction="1" />
    </joint>
  <link name="link5">
    <inertial>
      <origin rpy="0 0 0" xyz="-0.00032 0.01604 -0.026" />
      <mass value="1.3203" />
      <inertia ixx="0.00534665" ixy="1.5117e-05" ixz="-3.69e-07" iyy="0.0049779" iyz="-0.00022132" izz="0.0013624" />
      </inertial>
    <visual>
      <geometry>
        <mesh filename="meshes/visual/link5.glb" />
        </geometry>
      <origin rpy="0 0 0" xyz="0 0 0" />
      </visual>
    <collision>
      <geometry>
        <mesh filename="meshes/collision/link5.obj" />
        </geometry>
      <origin rpy="0 0 0" xyz="0 0 0" />
      </collision>
    </link>
  <joint name="xarm7_joint5" type="revolute">
    <origin rpy="1.5708 0 0" xyz="0.0775 -0.3425 0" />
    <parent link="link4" />
    <child link="link5" />
    <axis xyz="0 0 1" />
    <limit effort="30" lower="-6.28318530718" upper="6.28318530718" velocity="3.14" />
    <dynamics damping="5" friction="1" />
    </joint>
  <link name="link6">
    <inertial>
      <origin rpy="0 0 0" xyz="0.06469 0.03278 0.02141" />
      <mass value="1.325" />
      <inertia ixx="0.0014745" ixy="-0.000488" ixz="0.0002953" iyy="0.0019037" iyz="0.00014749" izz="0.0023652" />
      </inertial>
    <visual>
      <geometry>
        <mesh filename="meshes/visual/link6.glb" />
        </geometry>
      <origin rpy="0 0 0" xyz="0 0 0" />
      </visual>
    <collision>
      <geometry>
        <mesh filename="meshes/collision/link6.obj" />
        </geometry>
      <origin rpy="0 0 0" xyz="0 0 0" />
      </collision>
    </link>
  <joint name="xarm7_joint6" type="revolute">
    <origin rpy="1.5708 0 0" xyz="0 0 0" />
    <parent link="link5" />
    <child link="link6" />
    <axis xyz="0 0 1" />
    <limit effort="20" lower="-1.69297" upper="3.14159265359" velocity="3.14" />
    <dynamics damping="2" friction="1" />
    </joint>
  <link name="link7">
    <inertial>
      <origin rpy="0 0 0" xyz="0 -0.00677 -0.01098" />
      <mass value="0.17" />
      <inertia ixx="9.3e-05" ixy="-0.0" ixz="-0.0" iyy="5.87e-05" iyz="-3.6e-06" izz="0.000132" />
      </inertial>
    <visual>
      <geometry>
        <mesh filename="meshes/visual/link7.glb" />
        </geometry>
      <origin rpy="0 0 0" xyz="0 0 0" />
      </visual>
    <collision>
      <geometry>
        <mesh filename="meshes/collision/link7.obj" />
        </geometry>
      <origin rpy="0 0 0" xyz="0 0 0" />
      </collision>
    </link>
  <joint name="xarm7_joint7" type="revolute">
    <origin rpy="-1.5708 0 0" xyz="0.076 0.097 0" />
    <parent link="link6" />
    <child link="link7" />
    <axis xyz="0 0 1" />
    <limit effort="20" lower="-6.28318530718" upper="6.28318530718" velocity="3.14" />
    <dynamics damping="2" friction="1" />
    </joint>
  <joint name="part_studio_joint" type="fixed">
    <parent link="link7" />
    <child link="palm_link" />
    <origin rpy="3.14 0 0" xyz="0.06 -0.0375 0.0135" />
    </joint>
  <link name="palm_link">
    <visual>
      <origin xyz="-0.020095249652862544332 0.025757756134899473244 -0.034722403578460216134" rpy="0 -0 0" />
      <geometry>
        <mesh filename="leap_hand/palm_lower.stl" />
        </geometry>
      <material name="palm_link_material">
        <color rgba="0.60392156862745094426 0.14901960784313725283 0.14901960784313725283 1.0" />
        </material>
      </visual>
    <collision>
      <origin xyz="-0.020095249652862544332 0.025757756134899473244 -0.034722403578460216134" rpy="0 -0 0" />
      <geometry>
        <mesh filename="leap_hand/palm_lower.stl" />
        </geometry>
      </collision>
    <inertial>
      <origin xyz="0 0 0" rpy="0 0 0" />
      <mass value="0.237" />
      <inertia ixx="0.000354094" ixy="-0.000001193" ixz="-0.000002445" iyy="0.000260915" iyz="-0.000002905" izz="0.000529257" />
      </inertial>
    </link>
  <link name="mcp_joint_1">
    <visual>
      <origin xyz="0.0084069022611744960438 0.0077662438597169954416 0.014657354985032912051" rpy="1.6375789613220999807e-15 -1.0210473302491019535e-30 1.7177968783327987474e-31" />
      <geometry>
        <mesh filename="leap_hand/mcp_joint.stl" />
        </geometry>
      <material name="mcp_joint_1_material">
        <color rgba="0.86666666666666669627 0.86666666666666669627 0.050980392156862744391 1.0" />
        </material>
      </visual>
    <collision>
      <origin xyz="0.0084069022611744960438 0.0077662438597169954416 0.014657354985032912051" rpy="1.6375789613220999807e-15 -1.0210473302491019535e-30 1.7177968783327987474e-31" />
      <geometry>
        <mesh filename="leap_hand/mcp_joint.stl" />
        </geometry>
      </collision>
    <inertial>
      <origin xyz="0 0 0" rpy="0 0 0" />
      <mass value="0.044" />
      <inertia ixx="0.000011499" ixy="0.000003049" ixz="0.000000121" iyy="0.000007796" iyz="0.000000112" izz="0.000014759" />
      </inertial>
    </link>
  <link name="pip_1">
    <visual>
      <origin xyz="0.0096433630922713280131 0.00029999999999998951117 0.00078403401041737645627" rpy="-1.570796326794896558 -1.570796326794896336 0" />
      <geometry>
        <mesh filename="leap_hand/pip.stl" />
        </geometry>
      <material name="pip_1_material">
        <color rgba="0.74901960784313725839 0.74901960784313725839 0.74901960784313725839 1.0" />
        </material>
      </visual>
    <collision>
      <origin xyz="0.0096433630922713280131 0.00029999999999998951117 0.00078403401041737645627" rpy="-1.570796326794896558 -1.570796326794896336 0" />
      <geometry>
        <mesh filename="leap_hand/pip.stl" />
        </geometry>
      </collision>
    <inertial>
      <origin xyz="0 0 0" rpy="0 0 0" />
      <mass value="0.032" />
      <inertia ixx="0.000004798" ixy="0.000000012" ixz="0.000000004" iyy="0.000002862" iyz="0.000000011" izz="0.000004234" />
      </inertial>
    </link>
  <link name="dip_1">
    <visual>
      <origin xyz="0.021133352895225002849 -0.0084321191467048792201 0.0097850881620952408213" rpy="-3.141592653589793116 4.5075111242164408299e-32 4.4395481053923607589e-32" />
      <geometry>
        <mesh filename="leap_hand/dip.stl" />
        </geometry>
      <material name="dip_1_material">
        <color rgba="0.86666666666666669627 0.86666666666666669627 0.050980392156862744391 1.0" />
        </material>
      </visual>
    <collision>
      <origin xyz="0.021133352895225002849 -0.0084321191467048792201 0.0097850881620952408213" rpy="-3.141592653589793116 4.5075111242164408299e-32 4.4395481053923607589e-32" />
      <geometry>
        <mesh filename="leap_hand/dip.stl" />
        </geometry>
      </collision>
    <inertial>
      <origin xyz="0 0 0" rpy="0 0 0" />
      <mass value="0.037" />
      <inertia ixx="0.000005542" ixy="-0.000000607" ixz="-0.000000017" iyy="0.000005727" iyz="-0.000000023" izz="0.000006682" />
      </inertial>
    </link>
  <link name="fingertip_1">
    <visual>
      <origin xyz="0.013286424108533503169 -0.0061142383865419869249 0.014499999999999497666" rpy="3.141592653589793116 1.1993117970061734707e-33 4.4395481053923607589e-32" />
      <geometry>
        <mesh filename="leap_hand/fingertip.stl" />
        </geometry>
      <material name="fingertip_1_material">
        <color rgba="0.86666666666666669627 0.86666666666666669627 0.050980392156862744391 1.0" />
        </material>
      </visual>
    <collision>
      <origin xyz="0.013286424108533503169 -0.0061142383865419869249 0.014499999999999497666" rpy="3.141592653589793116 1.1993117970061734707e-33 4.4395481053923607589e-32" />
      <geometry>
        <mesh filename="leap_hand/fingertip.stl" />
        </geometry>
      </collision>
    <inertial>
      <origin xyz="0 0 0" rpy="0 0 0" />
      <mass value="0.016" />
      <inertia ixx="0.000003368" ixy="0.000000115" ixz="0" iyy="0.000001556" iyz="0" izz="0.000002863" />
      </inertial>
    </link>
  <joint name="leap_joint0" type="revolute">
    <origin xyz="-0.012200000000000007713 0.038099999999999994982 0.014500000000000000736" rpy="-1.570796326794896558 -1.0065212660796336576e-15 1.5707963267948943376" />
    <parent link="mcp_joint_1" />
    <child link="pip_1" />
    <axis xyz="0 0 -1" />
    <limit effort="0.95" velocity="8.48" lower="-1.047" upper="1.047" />
    <joint_properties friction="0.0" />
    </joint>
  <joint name="leap_joint1" type="revolute">
    <origin xyz="-0.0070952496528625457958 0.023057756134899472233 -0.01872240357846021927" rpy="1.5707963267948950037 1.5707963267948945596 0" />
    <parent link="palm_link" />
    <child link="mcp_joint_1" />
    <axis xyz="0 0 -1" />
    <limit effort="0.95" velocity="8.48" lower="-0.314" upper="2.23" />
    <joint_properties friction="0.0" />
    </joint>
  <joint name="leap_joint2" type="revolute">
    <origin xyz="0.01499999999999996822 0.014299999999999904801 -0.012999999999999824196" rpy="1.5707963267948958919 -1.570796326794896336 0" />
    <parent link="pip_1" />
    <child link="dip_1" />
    <axis xyz="0 0 -1" />
    <limit effort="0.95" velocity="8.48" lower="-0.506" upper="1.885" />
    <joint_properties friction="0.0" />
    </joint>
  <joint name="leap_joint3" type="revolute">
    <origin xyz="-4.0880582495572692636e-09 -0.036100004210367367397 0.00020000000000007858714" rpy="4.5935029425113685044e-17 -2.8730071914463794583e-16 4.4395481053923607589e-32" />
    <parent link="dip_1" />
    <child link="fingertip_1" />
    <axis xyz="0 0 -1" />
    <limit effort="0.95" velocity="8.48" lower="-0.366" upper="2.042" />
    <joint_properties friction="0.0" />
    </joint>
  <link name="mcp_joint_2">
    <visual>
      <origin xyz="0.0084069022611744960438 0.0077662438597169954416 0.014657354985032913786" rpy="1.6375789613220999807e-15 -1.0076465469034000467e-30 2.1209300131419907151e-61" />
      <geometry>
        <mesh filename="leap_hand/mcp_joint.stl" />
        </geometry>
      <material name="mcp_joint_1_material">
        <color rgba="0.86666666666666669627 0.86666666666666669627 0.050980392156862744391 1.0" />
        </material>
      </visual>
    <collision>
      <origin xyz="0.0084069022611744960438 0.0077662438597169954416 0.014657354985032913786" rpy="1.6375789613220999807e-15 -1.0076465469034000467e-30 2.1209300131419907151e-61" />
      <geometry>
        <mesh filename="leap_hand/mcp_joint.stl" />
        </geometry>
      </collision>
    <inertial>
      <origin xyz="0 0 0" rpy="0 0 0" />
      <mass value="0.044" />
      <inertia ixx="0.000011499" ixy="0.000003049" ixz="0.000000121" iyy="0.000007796" iyz="0.000000112" izz="0.000014759" />
      </inertial>
    </link>
  <link name="pip_2">
    <visual>
      <origin xyz="0.0096433630922713280131 0.00029999999999999471534 0.00078403401041737645627" rpy="-1.570796326794896558 -1.570796326794896336 0" />
      <geometry>
        <mesh filename="leap_hand/pip.stl" />
        </geometry>
      <material name="pip_1_material">
        <color rgba="0.74901960784313725839 0.74901960784313725839 0.74901960784313725839 1.0" />
        </material>
      </visual>
    <collision>
      <origin xyz="0.0096433630922713280131 0.00029999999999999471534 0.00078403401041737645627" rpy="-1.570796326794896558 -1.570796326794896336 0" />
      <geometry>
        <mesh filename="leap_hand/pip.stl" />
        </geometry>
      </collision>
    <inertial>
      <origin xyz="0 0 0" rpy="0 0 0" />
      <mass value="0.032" />
      <inertia ixx="0.000004798" ixy="0.000000012" ixz="0.000000004" iyy="0.000002862" iyz="0.000000011" izz="0.000004234" />
      </inertial>
    </link>
  <link name="dip_2">
    <visual>
      <origin xyz="0.021133352895225002849 -0.0084321191467048653423 0.0097850881620952373519" rpy="-3.141592653589793116 2.1146933785271955805e-32 1.4408183216511868558e-31" />
      <geometry>
        <mesh filename="leap_hand/dip.stl" />
        </geometry>
      <material name="dip_1_material">
        <color rgba="0.86666666666666669627 0.86666666666666669627 0.050980392156862744391 1.0" />
        </material>
      </visual>
    <collision>
      <origin xyz="0.021133352895225002849 -0.0084321191467048653423 0.0097850881620952373519" rpy="-3.141592653589793116 2.1146933785271955805e-32 1.4408183216511868558e-31" />
      <geometry>
        <mesh filename="leap_hand/dip.stl" />
        </geometry>
      </collision>
    <inertial>
      <origin xyz="0 0 0" rpy="0 0 0" />
      <mass value="0.037" />
      <inertia ixx="0.000005542" ixy="-0.000000607" ixz="-0.000000017" iyy="0.000005727" iyz="-0.000000023" izz="0.000006682" />
      </inertial>
    </link>
  <link name="fingertip_2">
    <visual>
      <origin xyz="0.01328642410853349623 -0.0061142383865420008027 0.014499999999999495931" rpy="3.141592653589793116 -4.3179597882835943107e-33 1.4408183216511868558e-31" />
      <geometry>
        <mesh filename="leap_hand/fingertip.stl" />
        </geometry>
      <material name="fingertip_1_material">
        <color rgba="0.86666666666666669627 0.86666666666666669627 0.050980392156862744391 1.0" />
        </material>
      </visual>
    <collision>
      <origin xyz="0.01328642410853349623 -0.0061142383865420008027 0.014499999999999495931" rpy="3.141592653589793116 -4.3179597882835943107e-33 1.4408183216511868558e-31" />
      <geometry>
        <mesh filename="leap_hand/fingertip.stl" />
        </geometry>
      </collision>
    <inertial>
      <origin xyz="0 0 0" rpy="0 0 0" />
      <mass value="0.016" />
      <inertia ixx="0.000003368" ixy="0.000000115" ixz="0" iyy="0.000001556" iyz="0" izz="0.000002863" />
      </inertial>
    </link>
  <joint name="leap_joint4" type="revolute">
    <origin xyz="-0.012200000000000019856 0.038099999999999981104 0.01450000000000000594" rpy="-1.570796326794896558 -1.0065212760057939085e-15 1.5707963267948943376" />
    <parent link="mcp_joint_2" />
    <child link="pip_2" />
    <axis xyz="0 0 -1" />
    <limit effort="0.95" velocity="8.48" lower="-1.047" upper="1.047" />
    <joint_properties friction="0.0" />
    </joint>
  <joint name="leap_joint5" type="revolute">
    <origin xyz="-0.0070952496528625388569 -0.022392243865100525113 -0.018722403578460229678" rpy="1.570796326794896558 1.570796326794896558 0" />
    <parent link="palm_link" />
    <child link="mcp_joint_2" />
    <axis xyz="0 0 -1" />
    <limit effort="0.95" velocity="8.48" lower="-0.314" upper="2.23" />
    <joint_properties friction="0.0" />
    </joint>
  <joint name="leap_joint6" type="revolute">
    <origin xyz="0.014999999999999975159 0.014300000000000000211 -0.013000000000000018485" rpy="1.5707963267948958919 -1.570796326794896336 0" />
    <parent link="pip_2" />
    <child link="dip_2" />
    <axis xyz="0 0 -1" />
    <limit effort="0.95" velocity="8.48" lower="-0.506" upper="1.885" />
    <joint_properties friction="0.0" />
    </joint>
  <joint name="leap_joint7" type="revolute">
    <origin xyz="1.0061396160665481148e-16 -0.036099999999999854428 0.00020000000000007858714" rpy="4.5935029425113654229e-17 -2.8730071914463794583e-16 1.4408183216511868558e-31" />
    <parent link="dip_2" />
    <child link="fingertip_2" />
    <axis xyz="0 0 -1" />
    <limit effort="0.95" velocity="8.48" lower="-0.366" upper="2.042" />
    <joint_properties friction="0.0" />
    </joint>
  <link name="mcp_joint_3">
    <visual>
      <origin xyz="0.0084069022611744995133 0.0077662438597169963089 0.014657354985032913786" rpy="1.6375789613220999807e-15 -1.0059504988632626953e-30 5.729641584552035421e-32" />
      <geometry>
        <mesh filename="leap_hand/mcp_joint.stl" />
        </geometry>
      <material name="mcp_joint_1_material">
        <color rgba="0.86666666666666669627 0.86666666666666669627 0.050980392156862744391 1.0" />
        </material>
      </visual>
    <collision>
      <origin xyz="0.0084069022611744995133 0.0077662438597169963089 0.014657354985032913786" rpy="1.6375789613220999807e-15 -1.0059504988632626953e-30 5.729641584552035421e-32" />
      <geometry>
        <mesh filename="leap_hand/mcp_joint.stl" />
        </geometry>
      </collision>
    <inertial>
      <origin xyz="0 0 0" rpy="0 0 0" />
      <mass value="0.044" />
      <inertia ixx="0.000011499" ixy="0.000003049" ixz="0.000000121" iyy="0.000007796" iyz="0.000000112" izz="0.000014759" />
      </inertial>
    </link>
  <link name="pip_3">
    <visual>
      <origin xyz="0.0096433630922713314826 0.00029999999999998083755 0.00078403401041737645627" rpy="-1.570796326794896558 -1.570796326794896336 0" />
      <geometry>
        <mesh filename="leap_hand/pip.stl" />
        </geometry>
      <material name="pip_1_material">
        <color rgba="0.74901960784313725839 0.74901960784313725839 0.74901960784313725839 1.0" />
        </material>
      </visual>
    <collision>
      <origin xyz="0.0096433630922713314826 0.00029999999999998083755 0.00078403401041737645627" rpy="-1.570796326794896558 -1.570796326794896336 0" />
      <geometry>
        <mesh filename="leap_hand/pip.stl" />
        </geometry>
      </collision>
    <inertial>
      <origin xyz="0 0 0" rpy="0 0 0" />
      <mass value="0.032" />
      <inertia ixx="0.000004798" ixy="0.000000012" ixz="0.000000004" iyy="0.000002862" iyz="0.000000011" izz="0.000004234" />
      </inertial>
    </link>
  <link name="dip_3">
    <visual>
      <origin xyz="0.021133352895225006318 -0.0084321191467048653423 0.0097850881620952373519" rpy="-3.141592653589793116 -1.4095651113919093005e-33 1.5565411607615035382e-32" />
      <geometry>
        <mesh filename="leap_hand/dip.stl" />
        </geometry>
      <material name="dip_1_material">
        <color rgba="0.86666666666666669627 0.86666666666666669627 0.050980392156862744391 1.0" />
        </material>
      </visual>
    <collision>
      <origin xyz="0.021133352895225006318 -0.0084321191467048653423 0.0097850881620952373519" rpy="-3.141592653589793116 -1.4095651113919093005e-33 1.5565411607615035382e-32" />
      <geometry>
        <mesh filename="leap_hand/dip.stl" />
        </geometry>
      </collision>
    <inertial>
      <origin xyz="0 0 0" rpy="0 0 0" />
      <mass value="0.037" />
      <inertia ixx="0.000005542" ixy="-0.000000607" ixz="-0.000000017" iyy="0.000005727" iyz="-0.000000023" izz="0.000006682" />
      </inertial>
    </link>
  <link name="fingertip_3">
    <visual>
      <origin xyz="0.013286424108533501434 -0.0061142383865419869249 0.0144999999999994994" rpy="3.141592653589793116 8.6170716950575402125e-33 1.5565411607615035382e-32" />
      <geometry>
        <mesh filename="leap_hand/fingertip.stl" />
        </geometry>
      <material name="fingertip_1_material">
        <color rgba="0.86666666666666669627 0.86666666666666669627 0.050980392156862744391 1.0" />
        </material>
      </visual>
    <collision>
      <origin xyz="0.013286424108533501434 -0.0061142383865419869249 0.0144999999999994994" rpy="3.141592653589793116 8.6170716950575402125e-33 1.5565411607615035382e-32" />
      <geometry>
        <mesh filename="leap_hand/fingertip.stl" />
        </geometry>
      </collision>
    <inertial>
      <origin xyz="0 0 0" rpy="0 0 0" />
      <mass value="0.016" />
      <inertia ixx="0.000003368" ixy="0.000000115" ixz="0" iyy="0.000001556" iyz="0" izz="0.000002863" />
      </inertial>
    </link>
  <joint name="leap_joint8" type="revolute">
    <origin xyz="-0.012200000000000004244 0.038100000000000001921 0.014499999999999999001" rpy="-1.570796326794896558 -1.0065212660796360242e-15 1.5707963267948943376" />
    <parent link="mcp_joint_3" />
    <child link="pip_3" />
    <axis xyz="0 0 -1" />
    <limit effort="0.95" velocity="8.48" lower="-1.047" upper="1.047" />
    <joint_properties friction="0.0" />
    </joint>
  <joint name="leap_joint9" type="revolute">
    <origin xyz="-0.0070952454426398371343 -0.067842243865100515521 -0.018722407666402932774" rpy="1.5707963267948950037 1.5707963267948945596 0" />
    <parent link="palm_link" />
    <child link="mcp_joint_3" />
    <axis xyz="0 0 -1" />
    <limit effort="0.95" velocity="8.48" lower="-0.314" upper="2.23" />
    <joint_properties friction="0.0" />
    </joint>
  <joint name="leap_joint10" type="revolute">
    <origin xyz="0.014999999999999971689 0.014299999999999951639 -0.012999999999999959505" rpy="1.5707963267948958919 -1.570796326794896336 0" />
    <parent link="pip_3" />
    <child link="dip_3" />
    <axis xyz="0 0 -1" />
    <limit effort="0.95" velocity="8.48" lower="-0.506" upper="1.885" />
    <joint_properties friction="0.0" />
    </joint>
  <joint name="leap_joint11" type="revolute">
    <origin xyz="9.7144514654701197287e-17 -0.036099999999999868305 0.00020000000000007511769" rpy="4.5935029425113685044e-17 -2.8730071914463799514e-16 1.5565411607615035382e-32" />
    <parent link="dip_3" />
    <child link="fingertip_3" />
    <axis xyz="0 0 -1" />
    <limit effort="0.95" velocity="8.48" lower="-0.366" upper="2.042" />
    <joint_properties friction="0.0" />
    </joint>
  <link name="pip_4">
    <visual>
      <origin xyz="-0.0053566369077286714317 0.00029999999999999991951 0.00078403401041737819099" rpy="-1.570796326794896558 -1.570796326794896336 0" />
      <geometry>
        <mesh filename="leap_hand/pip.stl" />
        </geometry>
      <material name="pip_1_material">
        <color rgba="0.74901960784313725839 0.74901960784313725839 0.74901960784313725839 1.0" />
        </material>
      </visual>
    <collision>
      <origin xyz="-0.0053566369077286714317 0.00029999999999999991951 0.00078403401041737819099" rpy="-1.570796326794896558 -1.570796326794896336 0" />
      <geometry>
        <mesh filename="leap_hand/pip.stl" />
        </geometry>
      </collision>
    <inertial>
      <origin xyz="0 0 0" rpy="0 0 0" />
      <mass value="0.032" />
      <inertia ixx="0.000004798" ixy="0.000000012" ixz="0.000000004" iyy="0.000002862" iyz="0.000000011" izz="0.000004234" />
      </inertial>
    </link>
  <link name="thumb_pip">
    <visual>
      <origin xyz="0.011961920770611186859 -5.3082538364890297089e-16 -0.015852648956664199681" rpy="1.570796326794896558 1.6050198443300152637e-46 -3.9204996250525192755e-59" />
      <geometry>
        <mesh filename="leap_hand/thumb_pip.stl" />
        </geometry>
      <material name="thumb_pip_material">
        <color rgba="0.86666666666666669627 0.86666666666666669627 0.050980392156862744391 1.0" />
        </material>
      </visual>
    <collision>
      <origin xyz="0.011961920770611186859 -5.3082538364890297089e-16 -0.015852648956664199681" rpy="1.570796326794896558 1.6050198443300152637e-46 -3.9204996250525192755e-59" />
      <geometry>
        <mesh filename="leap_hand/thumb_pip.stl" />
        </geometry>
      </collision>
    <inertial>
      <origin xyz="0 0 0" rpy="0 0 0" />
      <mass value="0.003" />
      <inertia ixx="0.000000593" ixy="0" ixz="0" iyy="0.000000549" iyz="0" izz="0.000000224" />
      </inertial>
    </link>
  <link name="thumb_dip">
    <visual>
      <origin xyz="0.043968715707239175439 0.057952952973709198625 -0.0086286764493694757122" rpy="1.9428902930940098942e-16 3.2751579226442200773e-15 1.1123758529657360012e-46" />
      <geometry>
        <mesh filename="leap_hand/thumb_dip.stl" />
        </geometry>
      <material name="thumb_dip_material">
        <color rgba="0.86666666666666669627 0.86666666666666669627 0.050980392156862744391 1.0" />
        </material>
      </visual>
    <collision>
      <origin xyz="0.043968715707239175439 0.057952952973709198625 -0.0086286764493694757122" rpy="1.9428902930940098942e-16 3.2751579226442200773e-15 1.1123758529657360012e-46" />
      <geometry>
        <mesh filename="leap_hand/thumb_dip.stl" />
        </geometry>
      </collision>
    <inertial>
      <origin xyz="0 0 0" rpy="0 0 0" />
      <mass value="0.038" />
      <inertia ixx="0.000008474" ixy="0.000000241" ixz="0.000000026" iyy="0.000003841" iyz="0.000000025" izz="0.000007679" />
      </inertial>
    </link>
  <link name="thumb_fingertip">
    <visual>
      <origin xyz="0.062559538462667388381 0.078459682911396988469 0.048992911807332215068" rpy="4.3790577010156367543e-47 -3.3306690738754701143e-16 1.2042408677791935383e-46" />
      <geometry>
        <mesh filename="leap_hand/thumb_fingertip.stl" />
        </geometry>
      <material name="thumb_fingertip_material">
        <color rgba="0.60392156862745094426 0.14901960784313725283 0.14901960784313725283 1.0" />
        </material>
      </visual>
    <collision>
      <origin xyz="0.062559538462667388381 0.078459682911396988469 0.048992911807332215068" rpy="4.3790577010156367543e-47 -3.3306690738754701143e-16 1.2042408677791935383e-46" />
      <geometry>
        <mesh filename="leap_hand/thumb_fingertip.stl" />
        </geometry>
      </collision>
    <inertial>
      <origin xyz="0 0 0" rpy="0 0 0" />
      <mass value="0.049" />
      <inertia ixx="0.000020372" ixy="-0.000000489" ixz="-0.00000003" iyy="0.000004336" iyz="-0.000000097" izz="0.000019845" />
      </inertial>
    </link>
  <joint name="leap_joint12" type="revolute">
    <origin xyz="-0.069395249652862533996 -0.0012422438651005258004 -0.021622403578460215601" rpy="-8.2381766464939424156e-17 1.5707963267948956698 0" />
    <parent link="palm_link" />
    <child link="pip_4" />
    <axis xyz="0 0 -1" />
    <limit effort="0.95" velocity="8.48" lower="-0.349" upper="2.094" />
    <joint_properties friction="0.0" />
    </joint>
  <joint name="leap_joint13" type="revolute">
    <origin xyz="-2.7755575615628913511e-17 0.014300000000000005415 -0.013000000000000011546" rpy="1.5707963267948958919 -1.570796326794896336 0" />
    <parent link="pip_4" />
    <child link="thumb_pip" />
    <axis xyz="0 0 -1" />
    <limit effort="0.95" velocity="8.48" lower="-0.47" upper="2.443" />
    <joint_properties friction="0.0" />
    </joint>
  <joint name="leap_joint14" type="revolute">
    <origin xyz="0 0.014499999999999966041 -0.017000000000000053263" rpy="-1.570796326794896558 1.6050198443300131245e-46 -1.9721522630516624601e-31" />
    <parent link="thumb_pip" />
    <child link="thumb_dip" />
    <axis xyz="0 0 -1" />
    <limit effort="0.95" velocity="8.48" lower="-1.20" upper="1.90" />
    <joint_properties friction="0.0" />
    </joint>
  <joint name="leap_joint15" type="revolute">
    <origin xyz="-1.249000902703301108e-16 0.046599999999999863753 0.00019999999999997710581" rpy="1.5063958491491781023e-44 5.4234187233935260503e-31 3.141592653589793116" />
    <parent link="thumb_dip" />
    <child link="thumb_fingertip" />
    <axis xyz="0 0 -1" />
    <limit effort="0.95" velocity="8.48" lower="-1.34" upper="1.88" />
    <joint_properties friction="0.0" />
    </joint>
  <link name="link_base_sphere1" />
  <joint name="link_base_joint_sphere1" type="fixed">
    <parent link="link_base" />
    <child link="link_base_sphere1" />
    <origin rpy="0 0 0" xyz="-0.009823 -0.00042 0.045933" />
    <axis xyz="0 0 1" />
    </joint>
  <link name="link_base_sphere2" />
  <joint name="link_base_joint_sphere2" type="fixed">
    <parent link="link_base" />
    <child link="link_base_sphere2" />
    <origin rpy="0 0 0" xyz="0.001143 0.001023 0.096427" />
    <axis xyz="0 0 1" />
    </joint>
  <link name="link1_sphere1" />
  <joint name="link1_joint_sphere1" type="fixed">
    <parent link="link1" />
    <child link="link1_sphere1" />
    <origin rpy="0 0 0" xyz="0.000119 0.016853 -0.00018" />
    <axis xyz="0 0 1" />
    </joint>
  <link name="link1_sphere2" />
  <joint name="link1_joint_sphere2" type="fixed">
    <parent link="link1" />
    <child link="link1_sphere2" />
    <origin rpy="0 0 0" xyz="-0.000234 -0.004739 -0.065576" />
    <axis xyz="0 0 1" />
    </joint>
  <link name="link2_sphere1" />
  <joint name="link2_joint_sphere1" type="fixed">
    <parent link="link2" />
    <child link="link2_sphere1" />
    <origin rpy="0 0 0" xyz="-0.00171 -0.095399 0.072802" />
    <axis xyz="0 0 1" />
    </joint>
  <link name="link2_sphere2" />
  <joint name="link2_joint_sphere2" type="fixed">
    <parent link="link2" />
    <child link="link2_sphere2" />
    <origin rpy="0 0 0" xyz="-0.000301 -0.133322 0.001671" />
    <axis xyz="0 0 1" />
    </joint>
  <link name="link2_sphere3" />
  <joint name="link2_joint_sphere3" type="fixed">
    <parent link="link2" />
    <child link="link2_sphere3" />
    <origin rpy="0 0 0" xyz="-0.015401 0.005834 0.096103" />
    <axis xyz="0 0 1" />
    </joint>
  <link name="link2_sphere4" />
  <joint name="link2_joint_sphere4" type="fixed">
    <parent link="link2" />
    <child link="link2_sphere4" />
    <origin rpy="0 0 0" xyz="0.022087 0.000248 0.094505" />
    <axis xyz="0 0 1" />
    </joint>
  <link name="link3_sphere1" />
  <joint name="link3_joint_sphere1" type="fixed">
    <parent link="link3" />
    <child link="link3_sphere1" />
    <origin rpy="0 0 0" xyz="0.013209 0.010032 -0.045652" />
    <axis xyz="0 0 1" />
    </joint>
  <link name="link3_sphere2" />
  <joint name="link3_joint_sphere2" type="fixed">
    <parent link="link3" />
    <child link="link3_sphere2" />
    <origin rpy="0 0 0" xyz="0.050794 -0.003524 -0.000414" />
    <axis xyz="0 0 1" />
    </joint>
  <link name="link4_sphere1" />
  <joint name="link4_joint_sphere1" type="fixed">
    <parent link="link4" />
    <child link="link4_sphere1" />
    <origin rpy="0 0 0" xyz="0.069956 -0.080383 0.061747" />
    <axis xyz="0 0 1" />
    </joint>
  <link name="link4_sphere2" />
  <joint name="link4_joint_sphere2" type="fixed">
    <parent link="link4" />
    <child link="link4_sphere2" />
    <origin rpy="0 0 0" xyz="0.077847 -0.091376 0.014255" />
    <axis xyz="0 0 1" />
    </joint>
  <link name="link4_sphere3" />
  <joint name="link4_joint_sphere3" type="fixed">
    <parent link="link4" />
    <child link="link4_sphere3" />
    <origin rpy="0 0 0" xyz="0.077936 -0.130772 0.007635" />
    <axis xyz="0 0 1" />
    </joint>
  <link name="link4_sphere4" />
  <joint name="link4_joint_sphere4" type="fixed">
    <parent link="link4" />
    <child link="link4_sphere4" />
    <origin rpy="0 0 0" xyz="0.026582 -0.023333 0.083471" />
    <axis xyz="0 0 1" />
    </joint>
  <link name="link4_sphere5" />
  <joint name="link4_joint_sphere5" type="fixed">
    <parent link="link4" />
    <child link="link4_sphere5" />
    <origin rpy="0 0 0" xyz="-0.001109 -0.001125 0.086548" />
    <axis xyz="0 0 1" />
    </joint>
  <link name="link5_sphere1" />
  <joint name="link5_joint_sphere1" type="fixed">
    <parent link="link5" />
    <child link="link5_sphere1" />
    <origin rpy="0 0 0" xyz="0.002048 0.003509 -0.144887" />
    <axis xyz="0 0 1" />
    </joint>
  <link name="link5_sphere2" />
  <joint name="link5_joint_sphere2" type="fixed">
    <parent link="link5" />
    <child link="link5_sphere2" />
    <origin rpy="0 0 0" xyz="-7.5e-05 0.053318 -0.031886" />
    <axis xyz="0 0 1" />
    </joint>
  <link name="link5_sphere3" />
  <joint name="link5_joint_sphere3" type="fixed">
    <parent link="link5" />
    <child link="link5_sphere3" />
    <origin rpy="0 0 0" xyz="-0.00063 0.040215 -0.000145" />
    <axis xyz="0 0 1" />
    </joint>
  <link name="link5_sphere4" />
  <joint name="link5_joint_sphere4" type="fixed">
    <parent link="link5" />
    <child link="link5_sphere4" />
    <origin rpy="0 0 0" xyz="-0.002708 0.042677 -0.109673" />
    <axis xyz="0 0 1" />
    </joint>
  <link name="link5_sphere5" />
  <joint name="link5_joint_sphere5" type="fixed">
    <parent link="link5" />
    <child link="link5_sphere5" />
    <origin rpy="0 0 0" xyz="0.000113 0.061089 -0.080479" />
    <axis xyz="0 0 1" />
    </joint>
  <link name="link6_sphere1" />
  <joint name="link6_joint_sphere1" type="fixed">
    <parent link="link6" />
    <child link="link6_sphere1" />
    <origin rpy="0 0 0" xyz="0.020125 0.000188 0.021902" />
    <axis xyz="0 0 1" />
    </joint>
  <link name="link6_sphere2" />
  <joint name="link6_joint_sphere2" type="fixed">
    <parent link="link6" />
    <child link="link6_sphere2" />
    <origin rpy="0 0 0" xyz="0.075982 0.020571 6.9e-05" />
    <axis xyz="0 0 1" />
    </joint>
  <link name="link7_sphere1" />
  <joint name="link7_joint_sphere1" type="fixed">
    <parent link="link7" />
    <child link="link7_sphere1" />
    <origin rpy="0 0 0" xyz="0.000157 0.001368 -0.013522" />
    <axis xyz="0 0 1" />
    </joint>
  <link name="link7_sphere2" />
  <joint name="link7_joint_sphere2" type="fixed">
    <parent link="link7" />
    <child link="link7_sphere2" />
    <origin rpy="0 0 0" xyz="-0.009807 -0.014766 -0.013716" />
    <axis xyz="0 0 1" />
    </joint>
  <link name="palm_link_sphere1" />
  <joint name="palm_link_joint_sphere1" type="fixed">
    <parent link="palm_link" />
    <child link="palm_link_sphere1" />
    <origin rpy="0 0 0" xyz="-0.0481 -0.005964 -0.011237" />
    <axis xyz="0 0 1" />
    </joint>
  <link name="palm_link_sphere2" />
  <joint name="palm_link_joint_sphere2" type="fixed">
    <parent link="palm_link" />
    <child link="palm_link_sphere2" />
    <origin rpy="0 0 0" xyz="-0.07555 -0.060855 -0.011421" />
    <axis xyz="0 0 1" />
    </joint>
  <link name="palm_link_sphere3" />
  <joint name="palm_link_joint_sphere3" type="fixed">
    <parent link="palm_link" />
    <child link="palm_link_sphere3" />
    <origin rpy="0 0 0" xyz="-0.056243 -0.062219 -0.010825" />
    <axis xyz="0 0 1" />
    </joint>
  <link name="palm_link_sphere4" />
  <joint name="palm_link_joint_sphere4" type="fixed">
    <parent link="palm_link" />
    <child link="palm_link_sphere4" />
    <origin rpy="0 0 0" xyz="-0.028286 -0.074571 -0.010349" />
    <axis xyz="0 0 1" />
    </joint>
  <link name="palm_link_sphere5" />
  <joint name="palm_link_joint_sphere5" type="fixed">
    <parent link="palm_link" />
    <child link="palm_link_sphere5" />
    <origin rpy="0 0 0" xyz="-0.083564 -0.016429 -0.004875" />
    <axis xyz="0 0 1" />
    </joint>
  <link name="palm_link_sphere6" />
  <joint name="palm_link_joint_sphere6" type="fixed">
    <parent link="palm_link" />
    <child link="palm_link_sphere6" />
    <origin rpy="0 0 0" xyz="-0.025046 0.004803 -0.009687" />
    <axis xyz="0 0 1" />
    </joint>
  <link name="palm_link_sphere7" />
  <joint name="palm_link_joint_sphere7" type="fixed">
    <parent link="palm_link" />
    <child link="palm_link_sphere7" />
    <origin rpy="0 0 0" xyz="-0.023402 -0.035435 -0.008173" />
    <axis xyz="0 0 1" />
    </joint>
  <link name="palm_link_sphere8" />
  <joint name="palm_link_joint_sphere8" type="fixed">
    <parent link="palm_link" />
    <child link="palm_link_sphere8" />
    <origin rpy="0 0 0" xyz="-0.068316 0.007944 0.00117" />
    <axis xyz="0 0 1" />
    </joint>
  <link name="mcp_joint_1_sphere1" />
  <joint name="mcp_joint_1_joint_sphere1" type="fixed">
    <parent link="mcp_joint_1" />
    <child link="mcp_joint_1_sphere1" />
    <origin rpy="0 0 0" xyz="-0.028628 0.030571 0.017573" />
    <axis xyz="0 0 1" />
    </joint>
  <link name="mcp_joint_1_sphere2" />
  <joint name="mcp_joint_1_joint_sphere2" type="fixed">
    <parent link="mcp_joint_1" />
    <child link="mcp_joint_1_sphere2" />
    <origin rpy="0 0 0" xyz="-0.026983 0.047353 0.01569" />
    <axis xyz="0 0 1" />
    </joint>
  <link name="mcp_joint_1_sphere3" />
  <joint name="mcp_joint_1_joint_sphere3" type="fixed">
    <parent link="mcp_joint_1" />
    <child link="mcp_joint_1_sphere3" />
    <origin rpy="0 0 0" xyz="-0.017935 0.023523 0.01044" />
    <axis xyz="0 0 1" />
    </joint>
  <link name="mcp_joint_1_sphere4" />
  <joint name="mcp_joint_1_joint_sphere4" type="fixed">
    <parent link="mcp_joint_1" />
    <child link="mcp_joint_1_sphere4" />
    <origin rpy="0 0 0" xyz="-0.00555 0.017187 0.024811" />
    <axis xyz="0 0 1" />
    </joint>
  <link name="mcp_joint_1_sphere5" />
  <joint name="mcp_joint_1_joint_sphere5" type="fixed">
    <parent link="mcp_joint_1" />
    <child link="mcp_joint_1_sphere5" />
    <origin rpy="0 0 0" xyz="0.006035 0.017813 0.019707" />
    <axis xyz="0 0 1" />
    </joint>
  <link name="mcp_joint_1_sphere6" />
  <joint name="mcp_joint_1_joint_sphere6" type="fixed">
    <parent link="mcp_joint_1" />
    <child link="mcp_joint_1_sphere6" />
    <origin rpy="0 0 0" xyz="0.001205 0.013901 0.002144" />
    <axis xyz="0 0 1" />
    </joint>
  <link name="mcp_joint_1_sphere7" />
  <joint name="mcp_joint_1_joint_sphere7" type="fixed">
    <parent link="mcp_joint_1" />
    <child link="mcp_joint_1_sphere7" />
    <origin rpy="0 0 0" xyz="-0.001248 0.002706 -0.001246" />
    <axis xyz="0 0 1" />
    </joint>
  <link name="mcp_joint_1_sphere8" />
  <joint name="mcp_joint_1_joint_sphere8" type="fixed">
    <parent link="mcp_joint_1" />
    <child link="mcp_joint_1_sphere8" />
    <origin rpy="0 0 0" xyz="0.001095 0.003706 0.030422" />
    <axis xyz="0 0 1" />
    </joint>
  <link name="pip_1_sphere1" />
  <joint name="pip_1_joint_sphere1" type="fixed">
    <parent link="pip_1" />
    <child link="pip_1_sphere1" />
    <origin rpy="0 0 0" xyz="0.012929 -0.000323 -0.011826" />
    <axis xyz="0 0 1" />
    </joint>
  <link name="pip_1_sphere2" />
  <joint name="pip_1_joint_sphere2" type="fixed">
    <parent link="pip_1" />
    <child link="pip_1_sphere2" />
    <origin rpy="0 0 0" xyz="0.001318 0.000372 -0.012005" />
    <axis xyz="0 0 1" />
    </joint>
  <link name="dip_1_sphere1" />
  <joint name="dip_1_joint_sphere1" type="fixed">
    <parent link="dip_1" />
    <child link="dip_1_sphere1" />
    <origin rpy="0 0 0" xyz="0.005323 -0.02955 0.01443" />
    <axis xyz="0 0 1" />
    </joint>
  <link name="dip_1_sphere2" />
  <joint name="dip_1_joint_sphere2" type="fixed">
    <parent link="dip_1" />
    <child link="dip_1_sphere2" />
    <origin rpy="0 0 0" xyz="0.000654 -0.005122 -0.000563" />
    <axis xyz="0 0 1" />
    </joint>
  <link name="dip_1_sphere3" />
  <joint name="dip_1_joint_sphere3" type="fixed">
    <parent link="dip_1" />
    <child link="dip_1_sphere3" />
    <origin rpy="0 0 0" xyz="-0.000725 -0.011987 0.027286" />
    <axis xyz="0 0 1" />
    </joint>
  <link name="dip_1_sphere4" />
  <joint name="dip_1_joint_sphere4" type="fixed">
    <parent link="dip_1" />
    <child link="dip_1_sphere4" />
    <origin rpy="0 0 0" xyz="0.000749 -0.000617 0.030803" />
    <axis xyz="0 0 1" />
    </joint>
  <link name="fingertip_1_sphere1" />
  <joint name="fingertip_1_joint_sphere1" type="fixed">
    <parent link="fingertip_1" />
    <child link="fingertip_1_sphere1" />
    <origin rpy="0 0 0" xyz="-0.001197 -0.035075 0.015797" />
    <axis xyz="0 0 1" />
    </joint>
  <link name="fingertip_1_sphere2" />
  <joint name="fingertip_1_joint_sphere2" type="fixed">
    <parent link="fingertip_1" />
    <child link="fingertip_1_sphere2" />
    <origin rpy="0 0 0" xyz="-0.001103 -0.021174 0.008437" />
    <axis xyz="0 0 1" />
    </joint>
  <link name="fingertip_1_sphere3" />
  <joint name="fingertip_1_joint_sphere3" type="fixed">
    <parent link="fingertip_1" />
    <child link="fingertip_1_sphere3" />
    <origin rpy="0 0 0" xyz="0.00261 -0.012336 0.002176" />
    <axis xyz="0 0 1" />
    </joint>
  <link name="fingertip_1_sphere4" />
  <joint name="fingertip_1_joint_sphere4" type="fixed">
    <parent link="fingertip_1" />
    <child link="fingertip_1_sphere4" />
    <origin rpy="0 0 0" xyz="-0.001025 -0.004133 0.029141" />
    <axis xyz="0 0 1" />
    </joint>
  <link name="fingertip_1_sphere5" />
  <joint name="fingertip_1_joint_sphere5" type="fixed">
    <parent link="fingertip_1" />
    <child link="fingertip_1_sphere5" />
    <origin rpy="0 0 0" xyz="0.00022 -0.015805 0.026884" />
    <axis xyz="0 0 1" />
    </joint>
  <link name="fingertip_1_sphere6" />
  <joint name="fingertip_1_joint_sphere6" type="fixed">
    <parent link="fingertip_1" />
    <child link="fingertip_1_sphere6" />
    <origin rpy="0 0 0" xyz="-0.002069 -0.001072 -0.001277" />
    <axis xyz="0 0 1" />
    </joint>
  <link name="mcp_joint_2_sphere1" />
  <joint name="mcp_joint_2_joint_sphere1" type="fixed">
    <parent link="mcp_joint_2" />
    <child link="mcp_joint_2_sphere1" />
    <origin rpy="0 0 0" xyz="-0.028628 0.030571 0.017573" />
    <axis xyz="0 0 1" />
    </joint>
  <link name="mcp_joint_2_sphere2" />
  <joint name="mcp_joint_2_joint_sphere2" type="fixed">
    <parent link="mcp_joint_2" />
    <child link="mcp_joint_2_sphere2" />
    <origin rpy="0 0 0" xyz="-0.026983 0.047353 0.01569" />
    <axis xyz="0 0 1" />
    </joint>
  <link name="mcp_joint_2_sphere3" />
  <joint name="mcp_joint_2_joint_sphere3" type="fixed">
    <parent link="mcp_joint_2" />
    <child link="mcp_joint_2_sphere3" />
    <origin rpy="0 0 0" xyz="-0.017935 0.023523 0.01044" />
    <axis xyz="0 0 1" />
    </joint>
  <link name="mcp_joint_2_sphere4" />
  <joint name="mcp_joint_2_joint_sphere4" type="fixed">
    <parent link="mcp_joint_2" />
    <child link="mcp_joint_2_sphere4" />
    <origin rpy="0 0 0" xyz="-0.00555 0.017187 0.024811" />
    <axis xyz="0 0 1" />
    </joint>
  <link name="mcp_joint_2_sphere5" />
  <joint name="mcp_joint_2_joint_sphere5" type="fixed">
    <parent link="mcp_joint_2" />
    <child link="mcp_joint_2_sphere5" />
    <origin rpy="0 0 0" xyz="0.006035 0.017813 0.019707" />
    <axis xyz="0 0 1" />
    </joint>
  <link name="mcp_joint_2_sphere6" />
  <joint name="mcp_joint_2_joint_sphere6" type="fixed">
    <parent link="mcp_joint_2" />
    <child link="mcp_joint_2_sphere6" />
    <origin rpy="0 0 0" xyz="0.001205 0.013901 0.002144" />
    <axis xyz="0 0 1" />
    </joint>
  <link name="mcp_joint_2_sphere7" />
  <joint name="mcp_joint_2_joint_sphere7" type="fixed">
    <parent link="mcp_joint_2" />
    <child link="mcp_joint_2_sphere7" />
    <origin rpy="0 0 0" xyz="-0.001248 0.002706 -0.001246" />
    <axis xyz="0 0 1" />
    </joint>
  <link name="mcp_joint_2_sphere8" />
  <joint name="mcp_joint_2_joint_sphere8" type="fixed">
    <parent link="mcp_joint_2" />
    <child link="mcp_joint_2_sphere8" />
    <origin rpy="0 0 0" xyz="0.001095 0.003706 0.030422" />
    <axis xyz="0 0 1" />
    </joint>
  <link name="pip_2_sphere1" />
  <joint name="pip_2_joint_sphere1" type="fixed">
    <parent link="pip_2" />
    <child link="pip_2_sphere1" />
    <origin rpy="0 0 0" xyz="0.012929 -0.000323 -0.011826" />
    <axis xyz="0 0 1" />
    </joint>
  <link name="pip_2_sphere2" />
  <joint name="pip_2_joint_sphere2" type="fixed">
    <parent link="pip_2" />
    <child link="pip_2_sphere2" />
    <origin rpy="0 0 0" xyz="0.001318 0.000372 -0.012005" />
    <axis xyz="0 0 1" />
    </joint>
  <link name="dip_2_sphere1" />
  <joint name="dip_2_joint_sphere1" type="fixed">
    <parent link="dip_2" />
    <child link="dip_2_sphere1" />
    <origin rpy="0 0 0" xyz="0.005323 -0.02955 0.01443" />
    <axis xyz="0 0 1" />
    </joint>
  <link name="dip_2_sphere2" />
  <joint name="dip_2_joint_sphere2" type="fixed">
    <parent link="dip_2" />
    <child link="dip_2_sphere2" />
    <origin rpy="0 0 0" xyz="0.000654 -0.005122 -0.000563" />
    <axis xyz="0 0 1" />
    </joint>
  <link name="dip_2_sphere3" />
  <joint name="dip_2_joint_sphere3" type="fixed">
    <parent link="dip_2" />
    <child link="dip_2_sphere3" />
    <origin rpy="0 0 0" xyz="-0.000725 -0.011987 0.027286" />
    <axis xyz="0 0 1" />
    </joint>
  <link name="dip_2_sphere4" />
  <joint name="dip_2_joint_sphere4" type="fixed">
    <parent link="dip_2" />
    <child link="dip_2_sphere4" />
    <origin rpy="0 0 0" xyz="0.000749 -0.000617 0.030803" />
    <axis xyz="0 0 1" />
    </joint>
  <link name="fingertip_2_sphere1" />
  <joint name="fingertip_2_joint_sphere1" type="fixed">
    <parent link="fingertip_2" />
    <child link="fingertip_2_sphere1" />
    <origin rpy="0 0 0" xyz="-0.001197 -0.035075 0.015797" />
    <axis xyz="0 0 1" />
    </joint>
  <link name="fingertip_2_sphere2" />
  <joint name="fingertip_2_joint_sphere2" type="fixed">
    <parent link="fingertip_2" />
    <child link="fingertip_2_sphere2" />
    <origin rpy="0 0 0" xyz="-0.001103 -0.021174 0.008437" />
    <axis xyz="0 0 1" />
    </joint>
  <link name="fingertip_2_sphere3" />
  <joint name="fingertip_2_joint_sphere3" type="fixed">
    <parent link="fingertip_2" />
    <child link="fingertip_2_sphere3" />
    <origin rpy="0 0 0" xyz="0.00261 -0.012336 0.002176" />
    <axis xyz="0 0 1" />
    </joint>
  <link name="fingertip_2_sphere4" />
  <joint name="fingertip_2_joint_sphere4" type="fixed">
    <parent link="fingertip_2" />
    <child link="fingertip_2_sphere4" />
    <origin rpy="0 0 0" xyz="-0.001025 -0.004133 0.029141" />
    <axis xyz="0 0 1" />
    </joint>
  <link name="fingertip_2_sphere5" />
  <joint name="fingertip_2_joint_sphere5" type="fixed">
    <parent link="fingertip_2" />
    <child link="fingertip_2_sphere5" />
    <origin rpy="0 0 0" xyz="0.00022 -0.015805 0.026884" />
    <axis xyz="0 0 1" />
    </joint>
  <link name="fingertip_2_sphere6" />
  <joint name="fingertip_2_joint_sphere6" type="fixed">
    <parent link="fingertip_2" />
    <child link="fingertip_2_sphere6" />
    <origin rpy="0 0 0" xyz="-0.002069 -0.001072 -0.001277" />
    <axis xyz="0 0 1" />
    </joint>
  <link name="mcp_joint_3_sphere1" />
  <joint name="mcp_joint_3_joint_sphere1" type="fixed">
    <parent link="mcp_joint_3" />
    <child link="mcp_joint_3_sphere1" />
    <origin rpy="0 0 0" xyz="-0.028628 0.030571 0.017573" />
    <axis xyz="0 0 1" />
    </joint>
  <link name="mcp_joint_3_sphere2" />
  <joint name="mcp_joint_3_joint_sphere2" type="fixed">
    <parent link="mcp_joint_3" />
    <child link="mcp_joint_3_sphere2" />
    <origin rpy="0 0 0" xyz="-0.026983 0.047353 0.01569" />
    <axis xyz="0 0 1" />
    </joint>
  <link name="mcp_joint_3_sphere3" />
  <joint name="mcp_joint_3_joint_sphere3" type="fixed">
    <parent link="mcp_joint_3" />
    <child link="mcp_joint_3_sphere3" />
    <origin rpy="0 0 0" xyz="-0.017935 0.023523 0.01044" />
    <axis xyz="0 0 1" />
    </joint>
  <link name="mcp_joint_3_sphere4" />
  <joint name="mcp_joint_3_joint_sphere4" type="fixed">
    <parent link="mcp_joint_3" />
    <child link="mcp_joint_3_sphere4" />
    <origin rpy="0 0 0" xyz="-0.00555 0.017187 0.024811" />
    <axis xyz="0 0 1" />
    </joint>
  <link name="mcp_joint_3_sphere5" />
  <joint name="mcp_joint_3_joint_sphere5" type="fixed">
    <parent link="mcp_joint_3" />
    <child link="mcp_joint_3_sphere5" />
    <origin rpy="0 0 0" xyz="0.006035 0.017813 0.019707" />
    <axis xyz="0 0 1" />
    </joint>
  <link name="mcp_joint_3_sphere6" />
  <joint name="mcp_joint_3_joint_sphere6" type="fixed">
    <parent link="mcp_joint_3" />
    <child link="mcp_joint_3_sphere6" />
    <origin rpy="0 0 0" xyz="0.001205 0.013901 0.002144" />
    <axis xyz="0 0 1" />
    </joint>
  <link name="mcp_joint_3_sphere7" />
  <joint name="mcp_joint_3_joint_sphere7" type="fixed">
    <parent link="mcp_joint_3" />
    <child link="mcp_joint_3_sphere7" />
    <origin rpy="0 0 0" xyz="-0.001248 0.002706 -0.001246" />
    <axis xyz="0 0 1" />
    </joint>
  <link name="mcp_joint_3_sphere8" />
  <joint name="mcp_joint_3_joint_sphere8" type="fixed">
    <parent link="mcp_joint_3" />
    <child link="mcp_joint_3_sphere8" />
    <origin rpy="0 0 0" xyz="0.001095 0.003706 0.030422" />
    <axis xyz="0 0 1" />
    </joint>
  <link name="pip_3_sphere1" />
  <joint name="pip_3_joint_sphere1" type="fixed">
    <parent link="pip_3" />
    <child link="pip_3_sphere1" />
    <origin rpy="0 0 0" xyz="0.012929 -0.000323 -0.011826" />
    <axis xyz="0 0 1" />
    </joint>
  <link name="pip_3_sphere2" />
  <joint name="pip_3_joint_sphere2" type="fixed">
    <parent link="pip_3" />
    <child link="pip_3_sphere2" />
    <origin rpy="0 0 0" xyz="0.001318 0.000372 -0.012005" />
    <axis xyz="0 0 1" />
    </joint>
  <link name="dip_3_sphere1" />
  <joint name="dip_3_joint_sphere1" type="fixed">
    <parent link="dip_3" />
    <child link="dip_3_sphere1" />
    <origin rpy="0 0 0" xyz="0.005323 -0.02955 0.01443" />
    <axis xyz="0 0 1" />
    </joint>
  <link name="dip_3_sphere2" />
  <joint name="dip_3_joint_sphere2" type="fixed">
    <parent link="dip_3" />
    <child link="dip_3_sphere2" />
    <origin rpy="0 0 0" xyz="0.000654 -0.005122 -0.000563" />
    <axis xyz="0 0 1" />
    </joint>
  <link name="dip_3_sphere3" />
  <joint name="dip_3_joint_sphere3" type="fixed">
    <parent link="dip_3" />
    <child link="dip_3_sphere3" />
    <origin rpy="0 0 0" xyz="-0.000725 -0.011987 0.027286" />
    <axis xyz="0 0 1" />
    </joint>
  <link name="dip_3_sphere4" />
  <joint name="dip_3_joint_sphere4" type="fixed">
    <parent link="dip_3" />
    <child link="dip_3_sphere4" />
    <origin rpy="0 0 0" xyz="0.000749 -0.000617 0.030803" />
    <axis xyz="0 0 1" />
    </joint>
  <link name="fingertip_3_sphere1" />
  <joint name="fingertip_3_joint_sphere1" type="fixed">
    <parent link="fingertip_3" />
    <child link="fingertip_3_sphere1" />
    <origin rpy="0 0 0" xyz="-0.001197 -0.035075 0.015797" />
    <axis xyz="0 0 1" />
    </joint>
  <link name="fingertip_3_sphere2" />
  <joint name="fingertip_3_joint_sphere2" type="fixed">
    <parent link="fingertip_3" />
    <child link="fingertip_3_sphere2" />
    <origin rpy="0 0 0" xyz="-0.001103 -0.021174 0.008437" />
    <axis xyz="0 0 1" />
    </joint>
  <link name="fingertip_3_sphere3" />
  <joint name="fingertip_3_joint_sphere3" type="fixed">
    <parent link="fingertip_3" />
    <child link="fingertip_3_sphere3" />
    <origin rpy="0 0 0" xyz="0.00261 -0.012336 0.002176" />
    <axis xyz="0 0 1" />
    </joint>
  <link name="fingertip_3_sphere4" />
  <joint name="fingertip_3_joint_sphere4" type="fixed">
    <parent link="fingertip_3" />
    <child link="fingertip_3_sphere4" />
    <origin rpy="0 0 0" xyz="-0.001025 -0.004133 0.029141" />
    <axis xyz="0 0 1" />
    </joint>
  <link name="fingertip_3_sphere5" />
  <joint name="fingertip_3_joint_sphere5" type="fixed">
    <parent link="fingertip_3" />
    <child link="fingertip_3_sphere5" />
    <origin rpy="0 0 0" xyz="0.00022 -0.015805 0.026884" />
    <axis xyz="0 0 1" />
    </joint>
  <link name="fingertip_3_sphere6" />
  <joint name="fingertip_3_joint_sphere6" type="fixed">
    <parent link="fingertip_3" />
    <child link="fingertip_3_sphere6" />
    <origin rpy="0 0 0" xyz="-0.002069 -0.001072 -0.001277" />
    <axis xyz="0 0 1" />
    </joint>
  <link name="pip_4_sphere1" />
  <joint name="pip_4_joint_sphere1" type="fixed">
    <parent link="pip_4" />
    <child link="pip_4_sphere1" />
    <origin rpy="0 0 0" xyz="-0.002071 -0.000323 -0.011826" />
    <axis xyz="0 0 1" />
    </joint>
  <link name="pip_4_sphere2" />
  <joint name="pip_4_joint_sphere2" type="fixed">
    <parent link="pip_4" />
    <child link="pip_4_sphere2" />
    <origin rpy="0 0 0" xyz="-0.013682 0.000372 -0.012005" />
    <axis xyz="0 0 1" />
    </joint>
  <link name="thumb_pip_sphere1" />
  <joint name="thumb_pip_joint_sphere1" type="fixed">
    <parent link="thumb_pip" />
    <child link="thumb_pip_sphere1" />
    <origin rpy="0 0 0" xyz="0.00683 -0.006651 -0.00254" />
    <axis xyz="0 0 1" />
    </joint>
  <link name="thumb_pip_sphere2" />
  <joint name="thumb_pip_joint_sphere2" type="fixed">
    <parent link="thumb_pip" />
    <child link="thumb_pip_sphere2" />
    <origin rpy="0 0 0" xyz="0.000703 -0.015074 -0.008942" />
    <axis xyz="0 0 1" />
    </joint>
  <link name="thumb_pip_sphere3" />
  <joint name="thumb_pip_joint_sphere3" type="fixed">
    <parent link="thumb_pip" />
    <child link="thumb_pip_sphere3" />
    <origin rpy="0 0 0" xyz="-0.005225 0.014941 -0.007987" />
    <axis xyz="0 0 1" />
    </joint>
  <link name="thumb_pip_sphere4" />
  <joint name="thumb_pip_joint_sphere4" type="fixed">
    <parent link="thumb_pip" />
    <child link="thumb_pip_sphere4" />
    <origin rpy="0 0 0" xyz="0.006314 0.012934 -0.003469" />
    <axis xyz="0 0 1" />
    </joint>
  <link name="thumb_pip_sphere5" />
  <joint name="thumb_pip_joint_sphere5" type="fixed">
    <parent link="thumb_pip" />
    <child link="thumb_pip_sphere5" />
    <origin rpy="0 0 0" xyz="0.001344 0.0159 -0.016081" />
    <axis xyz="0 0 1" />
    </joint>
  <link name="thumb_pip_sphere6" />
  <joint name="thumb_pip_joint_sphere6" type="fixed">
    <parent link="thumb_pip" />
    <child link="thumb_pip_sphere6" />
    <origin rpy="0 0 0" xyz="-0.006961 -0.010044 -0.00237" />
    <axis xyz="0 0 1" />
    </joint>
  <link name="thumb_pip_sphere7" />
  <joint name="thumb_pip_joint_sphere7" type="fixed">
    <parent link="thumb_pip" />
    <child link="thumb_pip_sphere7" />
    <origin rpy="0 0 0" xyz="-0.00033 -0.0159 -0.016379" />
    <axis xyz="0 0 1" />
    </joint>
  <link name="thumb_pip_sphere8" />
  <joint name="thumb_pip_joint_sphere8" type="fixed">
    <parent link="thumb_pip" />
    <child link="thumb_pip_sphere8" />
    <origin rpy="0 0 0" xyz="-0.003339 0.0042 -0.0015" />
    <axis xyz="0 0 1" />
    </joint>
  <link name="thumb_dip_sphere1" />
  <joint name="thumb_dip_joint_sphere1" type="fixed">
    <parent link="thumb_dip" />
    <child link="thumb_dip_sphere1" />
    <origin rpy="0 0 0" xyz="-0.002391 0.020324 -0.015194" />
    <axis xyz="0 0 1" />
    </joint>
  <link name="thumb_dip_sphere2" />
  <joint name="thumb_dip_joint_sphere2" type="fixed">
    <parent link="thumb_dip" />
    <child link="thumb_dip_sphere2" />
    <origin rpy="0 0 0" xyz="-0.0005 0.026043 -0.0097" />
    <axis xyz="0 0 1" />
    </joint>
  <link name="thumb_dip_sphere3" />
  <joint name="thumb_dip_joint_sphere3" type="fixed">
    <parent link="thumb_dip" />
    <child link="thumb_dip_sphere3" />
    <origin rpy="0 0 0" xyz="-0.000777 0.002899 -0.014584" />
    <axis xyz="0 0 1" />
    </joint>
  <link name="thumb_dip_sphere4" />
  <joint name="thumb_dip_joint_sphere4" type="fixed">
    <parent link="thumb_dip" />
    <child link="thumb_dip_sphere4" />
    <origin rpy="0 0 0" xyz="0.000634 0.04201 -0.029237" />
    <axis xyz="0 0 1" />
    </joint>
  <link name="thumb_dip_sphere5" />
  <joint name="thumb_dip_joint_sphere5" type="fixed">
    <parent link="thumb_dip" />
    <child link="thumb_dip_sphere5" />
    <origin rpy="0 0 0" xyz="-0.000601 0.043833 0.001165" />
    <axis xyz="0 0 1" />
    </joint>
  <link name="thumb_fingertip_sphere1" />
  <joint name="thumb_fingertip_joint_sphere1" type="fixed">
    <parent link="thumb_fingertip" />
    <child link="thumb_fingertip_sphere1" />
    <origin rpy="0 0 0" xyz="0.004629 -0.020698 -0.014173" />
    <axis xyz="0 0 1" />
    </joint>
  <link name="thumb_fingertip_sphere2" />
  <joint name="thumb_fingertip_joint_sphere2" type="fixed">
    <parent link="thumb_fingertip" />
    <child link="thumb_fingertip_sphere2" />
    <origin rpy="0 0 0" xyz="0.00149 -0.002234 -0.014372" />
    <axis xyz="0 0 1" />
    </joint>
  <link name="thumb_fingertip_sphere3" />
  <joint name="thumb_fingertip_joint_sphere3" type="fixed">
    <parent link="thumb_fingertip" />
    <child link="thumb_fingertip_sphere3" />
    <origin rpy="0 0 0" xyz="-0.000769 -0.03815 -0.014629" />
    <axis xyz="0 0 1" />
    </joint>
  <link name="thumb_fingertip_sphere4" />
  <joint name="thumb_fingertip_joint_sphere4" type="fixed">
    <parent link="thumb_fingertip" />
    <child link="thumb_fingertip_sphere4" />
    <origin rpy="0 0 0" xyz="-0.001143 -0.051068 -0.014595" />
    <axis xyz="0 0 1" />
    </joint>
  </robot>
