<?xml version='1.0' encoding='utf-8'?>
<robot name="xarm7">
  <link name="link_base">
    <inertial>
      <origin rpy="0 0 0" xyz="-0.021131 -0.0016302 0.056488" />
      <mass value="0.88556" />
      <inertia ixx="0.0030595" ixy="0.00012259" ixz="-0.00062705" iyy="0.0037783" iyz="0.00027023" izz="0.0020125" />
      </inertial>
    <visual>
      <geometry>
        <mesh filename="meshes/visual/link_base.glb" />
        </geometry>
      <origin rpy="0 0 0" xyz="0 0 0" />
      </visual>
    <collision>
      <geometry>
        <mesh filename="meshes/collision/link_base.obj" />
        </geometry>
      <origin rpy="0 0 0" xyz="0 0 0" />
      </collision>
    </link>
  <link name="link1">
    <inertial>
      <origin rpy="0 0 0" xyz="-0.0002 0.02905 -0.01233" />
      <mass value="2.382" />
      <inertia ixx="0.0056905" ixy="-1.579e-05" ixz="5.125e-06" iyy="0.0049566" iyz="-0.000873378" izz="0.003316654" />
      </inertial>
    <visual>
      <geometry>
        <mesh filename="meshes/visual/link1.glb" />
        </geometry>
      <origin rpy="0 0 0" xyz="0 0 0" />
      </visual>
    <collision>
      <geometry>
        <mesh filename="meshes/collision/link1.obj" />
        </geometry>
      <origin rpy="0 0 0" xyz="0 0 0" />
      </collision>
    </link>
  <joint name="xarm7_joint1" type="revolute">
    <origin rpy="0 0 0" xyz="0 0 0.267" />
    <parent link="link_base" />
    <child link="link1" />
    <axis xyz="0 0 1" />
    <limit effort="50" lower="-6.28318530718" upper="6.28318530718" velocity="3.14" />
    <dynamics damping="10" friction="1" />
    </joint>
  <link name="link2">
    <inertial>
      <origin rpy="0 0 0" xyz="0.00022 -0.12856 0.01735" />
      <mass value="1.869" />
      <inertia ixx="0.0095989" ixy="1.541e-06" ixz="5.56e-06" iyy="0.00382472" iyz="-0.00317156" izz="0.007565669" />
      </inertial>
    <visual>
      <geometry>
        <mesh filename="meshes/visual/link2.glb" />
        </geometry>
      <origin rpy="0 0 0" xyz="0 0 0" />
      </visual>
    <collision>
      <geometry>
        <mesh filename="meshes/collision/link2.obj" />
        </geometry>
      <origin rpy="0 0 0" xyz="0 0 0" />
      </collision>
    </link>
  <joint name="xarm7_joint2" type="revolute">
    <origin rpy="-1.5708 0 0" xyz="0 0 0" />
    <parent link="link1" />
    <child link="link2" />
    <axis xyz="0 0 1" />
    <limit effort="50" lower="-2.059" upper="2.0944" velocity="3.14" />
    <dynamics damping="10" friction="1" />
    </joint>
  <link name="link3">
    <inertial>
      <origin rpy="0 0 0" xyz="0.0466 -0.02463 -0.00768" />
      <mass value="1.6383" />
      <inertia ixx="0.00310955" ixy="0.00030837" ixz="-0.00058453" iyy="0.00264483" iyz="0.000338893" izz="0.0026624" />
      </inertial>
    <visual>
      <geometry>
        <mesh filename="meshes/visual/link3.glb" />
        </geometry>
      <origin rpy="0 0 0" xyz="0 0 0" />
      </visual>
    <collision>
      <geometry>
        <mesh filename="meshes/collision/link3.obj" />
        </geometry>
      <origin rpy="0 0 0" xyz="0 0 0" />
      </collision>
    </link>
  <joint name="xarm7_joint3" type="revolute">
    <origin rpy="1.5708 0 0" xyz="0 -0.293 0" />
    <parent link="link2" />
    <child link="link3" />
    <axis xyz="0 0 1" />
    <limit effort="30" lower="-6.28318530718" upper="6.28318530718" velocity="3.14" />
    <dynamics damping="5" friction="1" />
    </joint>
  <link name="link4">
    <inertial>
      <origin rpy="0 0 0" xyz="0.07047 -0.11575 0.012" />
      <mass value="1.7269" />
      <inertia ixx="0.005889" ixy="0.00137112" ixz="0.00088143" iyy="0.00359703" iyz="-0.001762155" izz="0.00543244" />
      </inertial>
    <visual>
      <geometry>
        <mesh filename="meshes/visual/link4.glb" />
        </geometry>
      <origin rpy="0 0 0" xyz="0 0 0" />
      </visual>
    <collision>
      <geometry>
        <mesh filename="meshes/collision/link4.obj" />
        </geometry>
      <origin rpy="0 0 0" xyz="0 0 0" />
      </collision>
    </link>
  <joint name="xarm7_joint4" type="revolute">
    <origin rpy="1.5708 0 0" xyz="0.0525 0 0" />
    <parent link="link3" />
    <child link="link4" />
    <axis xyz="0 0 1" />
    <limit effort="30" lower="-0.19198" upper="3.927" velocity="3.14" />
    <dynamics damping="5" friction="1" />
    </joint>
  <link name="link5">
    <inertial>
      <origin rpy="0 0 0" xyz="-0.00032 0.01604 -0.026" />
      <mass value="1.3203" />
      <inertia ixx="0.00534665" ixy="1.5117e-05" ixz="-3.69e-07" iyy="0.0049779" iyz="-0.00022132" izz="0.0013624" />
      </inertial>
    <visual>
      <geometry>
        <mesh filename="meshes/visual/link5.glb" />
        </geometry>
      <origin rpy="0 0 0" xyz="0 0 0" />
      </visual>
    <collision>
      <geometry>
        <mesh filename="meshes/collision/link5.obj" />
        </geometry>
      <origin rpy="0 0 0" xyz="0 0 0" />
      </collision>
    </link>
  <joint name="xarm7_joint5" type="revolute">
    <origin rpy="1.5708 0 0" xyz="0.0775 -0.3425 0" />
    <parent link="link4" />
    <child link="link5" />
    <axis xyz="0 0 1" />
    <limit effort="30" lower="-6.28318530718" upper="6.28318530718" velocity="3.14" />
    <dynamics damping="5" friction="1" />
    </joint>
  <link name="link6">
    <inertial>
      <origin rpy="0 0 0" xyz="0.06469 0.03278 0.02141" />
      <mass value="1.325" />
      <inertia ixx="0.0014745" ixy="-0.000488" ixz="0.0002953" iyy="0.0019037" iyz="0.00014749" izz="0.0023652" />
      </inertial>
    <visual>
      <geometry>
        <mesh filename="meshes/visual/link6.glb" />
        </geometry>
      <origin rpy="0 0 0" xyz="0 0 0" />
      </visual>
    <collision>
      <geometry>
        <mesh filename="meshes/collision/link6.obj" />
        </geometry>
      <origin rpy="0 0 0" xyz="0 0 0" />
      </collision>
    </link>
  <joint name="xarm7_joint6" type="revolute">
    <origin rpy="1.5708 0 0" xyz="0 0 0" />
    <parent link="link5" />
    <child link="link6" />
    <axis xyz="0 0 1" />
    <limit effort="20" lower="-1.69297" upper="3.14159265359" velocity="3.14" />
    <dynamics damping="2" friction="1" />
    </joint>
  <link name="link7">
    <inertial>
      <origin rpy="0 0 0" xyz="0 -0.00677 -0.01098" />
      <mass value="0.17" />
      <inertia ixx="9.3e-05" ixy="-0.0" ixz="-0.0" iyy="5.87e-05" iyz="-3.6e-06" izz="0.000132" />
      </inertial>
    <visual>
      <geometry>
        <mesh filename="meshes/visual/link7.glb" />
        </geometry>
      <origin rpy="0 0 0" xyz="0 0 0" />
      </visual>
    <collision>
      <geometry>
        <mesh filename="meshes/collision/link7.obj" />
        </geometry>
      <origin rpy="0 0 0" xyz="0 0 0" />
      </collision>
    </link>
  <joint name="xarm7_joint7" type="revolute">
    <origin rpy="-1.5708 0 0" xyz="0.076 0.097 0" />
    <parent link="link6" />
    <child link="link7" />
    <axis xyz="0 0 1" />
    <limit effort="20" lower="-6.28318530718" upper="6.28318530718" velocity="3.14" />
    <dynamics damping="2" friction="1" />
    </joint>
  <joint name="part_studio_joint" type="fixed">
    <parent link="link7" />
    <child link="palm_link" />
    <origin rpy="3.14 0 0" xyz="0.06 -0.0375 0.0135" />
    </joint>
  <link name="palm_link">
    <visual>
      <origin xyz="-0.020095249652862544332 0.025757756134899473244 -0.034722403578460216134" rpy="0 -0 0" />
      <geometry>
        <mesh filename="leap_hand/palm_lower.stl" />
        </geometry>
      <material name="palm_link_material">
        <color rgba="0.60392156862745094426 0.14901960784313725283 0.14901960784313725283 1.0" />
        </material>
      </visual>
    <collision>
      <origin xyz="-0.009 0.008 -0.011" rpy="0 0 0" />
      <geometry>
        <box size="0.022 0.026 0.034" />
        </geometry>
      </collision>
    <collision>
      <origin xyz="-0.009 -0.037 -0.011" rpy="0 0 0" />
      <geometry>
        <box size="0.022 0.026 0.034" />
        </geometry>
      </collision>
    <collision>
      <origin xyz="-0.009 -0.082 -0.011" rpy="0 0 0" />
      <geometry>
        <box size="0.022 0.026 0.034" />
        </geometry>
      </collision>
    <collision>
      <origin xyz="-0.066 -0.078 -0.0115" rpy="0 0 -0.2967" />
      <geometry>
        <box size="0.058 0.02 0.046" />
        </geometry>
      </collision>
    <collision>
      <origin xyz="-0.03 -0.035 -0.003" rpy="0 0 0" />
      <geometry>
        <box size="0.02 0.12 0.03" />
        </geometry>
      </collision>
    <collision>
      <origin xyz="-0.032 -0.035 -0.024" rpy="0 0.785 0" />
      <geometry>
        <box size="0.01 0.12 0.02" />
        </geometry>
      </collision>
    <collision>
      <origin xyz="-0.048 -0.033 -0.0115" rpy="0 0 0" />
      <geometry>
        <box size="0.024 0.116 0.046" />
        </geometry>
      </collision>
    <collision>
      <origin xyz="-0.078 -0.053 -0.0115" rpy="0 0 0" />
      <geometry>
        <box size="0.044 0.052 0.046" />
        </geometry>
      </collision>
    <collision>
      <origin xyz="-0.098 -0.009 -0.006" rpy="0 0 0" />
      <geometry>
        <box size="0.004 0.036 0.034" />
        </geometry>
      </collision>
    <collision>
      <origin xyz="-0.078 -0.003 0.01" rpy="0 0 0" />
      <geometry>
        <box size="0.044 0.056 0.004" />
        </geometry>
      </collision>
    <inertial>
      <origin xyz="0 0 0" rpy="0 0 0" />
      <mass value="0.237" />
      <inertia ixx="0.000354094" ixy="-0.000001193" ixz="-0.000002445" iyy="0.000260915" iyz="-0.000002905" izz="0.000529257" />
      </inertial>
    </link>
  <link name="mcp_joint_1">
    <visual>
      <origin xyz="0.0084069022611744960438 0.0077662438597169954416 0.014657354985032912051" rpy="1.6375789613220999807e-15 -1.0210473302491019535e-30 1.7177968783327987474e-31" />
      <geometry>
        <mesh filename="leap_hand/mcp_joint.stl" />
        </geometry>
      <material name="mcp_joint_1_material">
        <color rgba="0.86666666666666669627 0.86666666666666669627 0.050980392156862744391 1.0" />
        </material>
      </visual>
    <collision>
      <origin xyz="0 0.018 0.0147" rpy="0 0 0" />
      <geometry>
        <box size="0.02 0.006 0.034" />
        </geometry>
      </collision>
    <collision>
      <origin xyz="-0.027 0.042 0.015" rpy="0 0 0" />
      <geometry>
        <box size="0.028 0.04 0.02" />
        </geometry>
      </collision>
    <collision>
      <origin xyz="-0.0262 0.02 0.0146" rpy="0 0 0" />
      <geometry>
        <box size="0.034 0.006 0.02" />
        </geometry>
      </collision>
    <collision>
      <origin xyz="-0.0295 0.035 0.029" rpy="0 0 0" />
      <geometry>
        <box size="0.02 0.024 0.008" />
        </geometry>
      </collision>
    <collision>
      <origin xyz="0 0.005 0.03" rpy="0 0 0" />
      <geometry>
        <box size="0.014 0.02 0.004" />
        </geometry>
      </collision>
    <collision>
      <origin xyz="0 0.005 -0.001" rpy="0 0 0" />
      <geometry>
        <box size="0.014 0.02 0.004" />
        </geometry>
      </collision>
    <inertial>
      <origin xyz="0 0 0" rpy="0 0 0" />
      <mass value="0.044" />
      <inertia ixx="0.000011499" ixy="0.000003049" ixz="0.000000121" iyy="0.000007796" iyz="0.000000112" izz="0.000014759" />
      </inertial>
    </link>
  <link name="pip_1">
    <visual>
      <origin xyz="0.0096433630922713280131 0.00029999999999998951117 0.00078403401041737645627" rpy="-1.570796326794896558 -1.570796326794896336 0" />
      <geometry>
        <mesh filename="leap_hand/pip.stl" />
        </geometry>
      <material name="pip_1_material">
        <color rgba="0.74901960784313725839 0.74901960784313725839 0.74901960784313725839 1.0" />
        </material>
      </visual>
    <collision>
      <origin xyz="0.0075 -0.0002 -0.011" rpy="0 0 0" />
      <geometry>
        <box size="0.034 0.026 0.022" />
        </geometry>
      </collision>
    <inertial>
      <origin xyz="0 0 0" rpy="0 0 0" />
      <mass value="0.032" />
      <inertia ixx="0.000004798" ixy="0.000000012" ixz="0.000000004" iyy="0.000002862" iyz="0.000000011" izz="0.000004234" />
      </inertial>
    </link>
  <link name="dip_1">
    <visual>
      <origin xyz="0.021133352895225002849 -0.0084321191467048792201 0.0097850881620952408213" rpy="-3.141592653589793116 4.5075111242164408299e-32 4.4395481053923607589e-32" />
      <geometry>
        <mesh filename="leap_hand/dip.stl" />
        </geometry>
      <material name="dip_1_material">
        <color rgba="0.86666666666666669627 0.86666666666666669627 0.050980392156862744391 1.0" />
        </material>
      </visual>
    <collision>
      <origin xyz="0 -0.02 0.015" rpy="0 0 0" />
      <geometry>
        <box size="0.016 0.006 0.026" />
        </geometry>
      </collision>
    <collision>
      <origin xyz="0 -0.016 0.015" rpy="0 0 0" />
      <geometry>
        <box size="0.02 0.004 0.034" />
        </geometry>
      </collision>
    <collision>
      <origin xyz="0 -0.0045 0.03" rpy="0 0 0" />
      <geometry>
        <box size="0.014 0.02 0.004" />
        </geometry>
      </collision>
    <collision>
      <origin xyz="0 -0.0045 0" rpy="0 0 0" />
      <geometry>
        <box size="0.014 0.02 0.004" />
        </geometry>
      </collision>
    <collision>
      <origin xyz="0.0075 -0.035 0.015" rpy="0 0 0" />
      <geometry>
        <box size="0.034 0.022 0.026" />
        </geometry>
      </collision>
    <inertial>
      <origin xyz="0 0 0" rpy="0 0 0" />
      <mass value="0.037" />
      <inertia ixx="0.000005542" ixy="-0.000000607" ixz="-0.000000017" iyy="0.000005727" iyz="-0.000000023" izz="0.000006682" />
      </inertial>
    </link>
  <link name="fingertip_1">
    <visual>
      <origin xyz="0.013286424108533503169 -0.0061142383865419869249 0.014499999999999497666" rpy="3.141592653589793116 1.1993117970061734707e-33 4.4395481053923607589e-32" />
      <geometry>
        <mesh filename="leap_hand/fingertip.stl" />
        </geometry>
      <material name="fingertip_1_material">
        <color rgba="0.86666666666666669627 0.86666666666666669627 0.050980392156862744391 1.0" />
        </material>
      </visual>
    <collision>
      <origin xyz="0 -0.017 0.015" rpy="0 0 0" />
      <geometry>
        <box size="0.02 0.006 0.03" />
        </geometry>
      </collision>
    <collision>
      <origin xyz="0 -0.006 0.03" rpy="0 0 0" />
      <geometry>
        <box size="0.014 0.022 0.004" />
        </geometry>
      </collision>
    <collision>
      <origin xyz="0 -0.006 -0.001" rpy="0 0 0" />
      <geometry>
        <box size="0.014 0.022 0.004" />
        </geometry>
      </collision>
    <collision>
      <origin xyz="0 0 0" rpy="0 0 0" />
      <geometry>
        <mesh filename="leap_hand/tip_simplified.obj" />
        </geometry>
      </collision>
    <inertial>
      <origin xyz="0 0 0" rpy="0 0 0" />
      <mass value="0.016" />
      <inertia ixx="0.000003368" ixy="0.000000115" ixz="0" iyy="0.000001556" iyz="0" izz="0.000002863" />
      </inertial>
    </link>
  <joint name="leap_joint0" type="revolute">
    <origin xyz="-0.012200000000000007713 0.038099999999999994982 0.014500000000000000736" rpy="-1.570796326794896558 -1.0065212660796336576e-15 1.5707963267948943376" />
    <parent link="mcp_joint_1" />
    <child link="pip_1" />
    <axis xyz="0 0 -1" />
    <limit effort="0.95" velocity="8.48" lower="-1.047" upper="1.047" />
    <joint_properties friction="0.0" />
    </joint>
  <joint name="leap_joint1" type="revolute">
    <origin xyz="-0.0070952496528625457958 0.023057756134899472233 -0.01872240357846021927" rpy="1.5707963267948950037 1.5707963267948945596 0" />
    <parent link="palm_link" />
    <child link="mcp_joint_1" />
    <axis xyz="0 0 -1" />
    <limit effort="0.95" velocity="8.48" lower="-0.314" upper="2.23" />
    <joint_properties friction="0.0" />
    </joint>
  <joint name="leap_joint2" type="revolute">
    <origin xyz="0.01499999999999996822 0.014299999999999904801 -0.012999999999999824196" rpy="1.5707963267948958919 -1.570796326794896336 0" />
    <parent link="pip_1" />
    <child link="dip_1" />
    <axis xyz="0 0 -1" />
    <limit effort="0.95" velocity="8.48" lower="-0.506" upper="1.885" />
    <joint_properties friction="0.0" />
    </joint>
  <joint name="leap_joint3" type="revolute">
    <origin xyz="-4.0880582495572692636e-09 -0.036100004210367367397 0.00020000000000007858714" rpy="4.5935029425113685044e-17 -2.8730071914463794583e-16 4.4395481053923607589e-32" />
    <parent link="dip_1" />
    <child link="fingertip_1" />
    <axis xyz="0 0 -1" />
    <limit effort="0.95" velocity="8.48" lower="-0.366" upper="2.042" />
    <joint_properties friction="0.0" />
    </joint>
  <link name="mcp_joint_2">
    <visual>
      <origin xyz="0.0084069022611744960438 0.0077662438597169954416 0.014657354985032913786" rpy="1.6375789613220999807e-15 -1.0076465469034000467e-30 2.1209300131419907151e-61" />
      <geometry>
        <mesh filename="leap_hand/mcp_joint.stl" />
        </geometry>
      <material name="mcp_joint_1_material">
        <color rgba="0.86666666666666669627 0.86666666666666669627 0.050980392156862744391 1.0" />
        </material>
      </visual>
    <collision>
      <origin xyz="0 0.018 0.0147" rpy="0 0 0" />
      <geometry>
        <box size="0.02 0.006 0.034" />
        </geometry>
      </collision>
    <collision>
      <origin xyz="-0.027 0.042 0.015" rpy="0 0 0" />
      <geometry>
        <box size="0.028 0.04 0.02" />
        </geometry>
      </collision>
    <collision>
      <origin xyz="-0.0262 0.02 0.0146" rpy="0 0 0" />
      <geometry>
        <box size="0.034 0.006 0.02" />
        </geometry>
      </collision>
    <collision>
      <origin xyz="-0.0295 0.035 0.029" rpy="0 0 0" />
      <geometry>
        <box size="0.02 0.024 0.008" />
        </geometry>
      </collision>
    <collision>
      <origin xyz="0 0.005 0.03" rpy="0 0 0" />
      <geometry>
        <box size="0.014 0.02 0.004" />
        </geometry>
      </collision>
    <collision>
      <origin xyz="0 0.005 -0.001" rpy="0 0 0" />
      <geometry>
        <box size="0.014 0.02 0.004" />
        </geometry>
      </collision>
    <inertial>
      <origin xyz="0 0 0" rpy="0 0 0" />
      <mass value="0.044" />
      <inertia ixx="0.000011499" ixy="0.000003049" ixz="0.000000121" iyy="0.000007796" iyz="0.000000112" izz="0.000014759" />
      </inertial>
    </link>
  <link name="pip_2">
    <visual>
      <origin xyz="0.0096433630922713280131 0.00029999999999999471534 0.00078403401041737645627" rpy="-1.570796326794896558 -1.570796326794896336 0" />
      <geometry>
        <mesh filename="leap_hand/pip.stl" />
        </geometry>
      <material name="pip_1_material">
        <color rgba="0.74901960784313725839 0.74901960784313725839 0.74901960784313725839 1.0" />
        </material>
      </visual>
    <collision>
      <origin xyz="0.0075 -0.0002 -0.011" rpy="0 0 0" />
      <geometry>
        <box size="0.034 0.026 0.022" />
        </geometry>
      </collision>
    <inertial>
      <origin xyz="0 0 0" rpy="0 0 0" />
      <mass value="0.032" />
      <inertia ixx="0.000004798" ixy="0.000000012" ixz="0.000000004" iyy="0.000002862" iyz="0.000000011" izz="0.000004234" />
      </inertial>
    </link>
  <link name="dip_2">
    <visual>
      <origin xyz="0.021133352895225002849 -0.0084321191467048653423 0.0097850881620952373519" rpy="-3.141592653589793116 2.1146933785271955805e-32 1.4408183216511868558e-31" />
      <geometry>
        <mesh filename="leap_hand/dip.stl" />
        </geometry>
      <material name="dip_1_material">
        <color rgba="0.86666666666666669627 0.86666666666666669627 0.050980392156862744391 1.0" />
        </material>
      </visual>
    <collision>
      <origin xyz="0 -0.02 0.015" rpy="0 0 0" />
      <geometry>
        <box size="0.016 0.006 0.026" />
        </geometry>
      </collision>
    <collision>
      <origin xyz="0 -0.016 0.015" rpy="0 0 0" />
      <geometry>
        <box size="0.02 0.004 0.034" />
        </geometry>
      </collision>
    <collision>
      <origin xyz="0 -0.0045 0.03" rpy="0 0 0" />
      <geometry>
        <box size="0.014 0.02 0.004" />
        </geometry>
      </collision>
    <collision>
      <origin xyz="0 -0.0045 0" rpy="0 0 0" />
      <geometry>
        <box size="0.014 0.02 0.004" />
        </geometry>
      </collision>
    <collision>
      <origin xyz="0.0075 -0.035 0.015" rpy="0 0 0" />
      <geometry>
        <box size="0.034 0.022 0.026" />
        </geometry>
      </collision>
    <inertial>
      <origin xyz="0 0 0" rpy="0 0 0" />
      <mass value="0.037" />
      <inertia ixx="0.000005542" ixy="-0.000000607" ixz="-0.000000017" iyy="0.000005727" iyz="-0.000000023" izz="0.000006682" />
      </inertial>
    </link>
  <link name="fingertip_2">
    <visual>
      <origin xyz="0.01328642410853349623 -0.0061142383865420008027 0.014499999999999495931" rpy="3.141592653589793116 -4.3179597882835943107e-33 1.4408183216511868558e-31" />
      <geometry>
        <mesh filename="leap_hand/fingertip.stl" />
        </geometry>
      <material name="fingertip_1_material">
        <color rgba="0.86666666666666669627 0.86666666666666669627 0.050980392156862744391 1.0" />
        </material>
      </visual>
    <collision>
      <origin xyz="0 -0.017 0.015" rpy="0 0 0" />
      <geometry>
        <box size="0.02 0.006 0.03" />
        </geometry>
      </collision>
    <collision>
      <origin xyz="0 -0.006 0.03" rpy="0 0 0" />
      <geometry>
        <box size="0.014 0.022 0.004" />
        </geometry>
      </collision>
    <collision>
      <origin xyz="0 -0.006 -0.001" rpy="0 0 0" />
      <geometry>
        <box size="0.014 0.022 0.004" />
        </geometry>
      </collision>
    <collision>
      <origin xyz="0 0 0" rpy="0 0 0" />
      <geometry>
        <mesh filename="leap_hand/tip_simplified.obj" />
        </geometry>
      </collision>
    <inertial>
      <origin xyz="0 0 0" rpy="0 0 0" />
      <mass value="0.016" />
      <inertia ixx="0.000003368" ixy="0.000000115" ixz="0" iyy="0.000001556" iyz="0" izz="0.000002863" />
      </inertial>
    </link>
  <joint name="leap_joint4" type="revolute">
    <origin xyz="-0.012200000000000019856 0.038099999999999981104 0.01450000000000000594" rpy="-1.570796326794896558 -1.0065212760057939085e-15 1.5707963267948943376" />
    <parent link="mcp_joint_2" />
    <child link="pip_2" />
    <axis xyz="0 0 -1" />
    <limit effort="0.95" velocity="8.48" lower="-1.047" upper="1.047" />
    <joint_properties friction="0.0" />
    </joint>
  <joint name="leap_joint5" type="revolute">
    <origin xyz="-0.0070952496528625388569 -0.022392243865100525113 -0.018722403578460229678" rpy="1.570796326794896558 1.570796326794896558 0" />
    <parent link="palm_link" />
    <child link="mcp_joint_2" />
    <axis xyz="0 0 -1" />
    <limit effort="0.95" velocity="8.48" lower="-0.314" upper="2.23" />
    <joint_properties friction="0.0" />
    </joint>
  <joint name="leap_joint6" type="revolute">
    <origin xyz="0.014999999999999975159 0.014300000000000000211 -0.013000000000000018485" rpy="1.5707963267948958919 -1.570796326794896336 0" />
    <parent link="pip_2" />
    <child link="dip_2" />
    <axis xyz="0 0 -1" />
    <limit effort="0.95" velocity="8.48" lower="-0.506" upper="1.885" />
    <joint_properties friction="0.0" />
    </joint>
  <joint name="leap_joint7" type="revolute">
    <origin xyz="1.0061396160665481148e-16 -0.036099999999999854428 0.00020000000000007858714" rpy="4.5935029425113654229e-17 -2.8730071914463794583e-16 1.4408183216511868558e-31" />
    <parent link="dip_2" />
    <child link="fingertip_2" />
    <axis xyz="0 0 -1" />
    <limit effort="0.95" velocity="8.48" lower="-0.366" upper="2.042" />
    <joint_properties friction="0.0" />
    </joint>
  <link name="mcp_joint_3">
    <visual>
      <origin xyz="0.0084069022611744995133 0.0077662438597169963089 0.014657354985032913786" rpy="1.6375789613220999807e-15 -1.0059504988632626953e-30 5.729641584552035421e-32" />
      <geometry>
        <mesh filename="leap_hand/mcp_joint.stl" />
        </geometry>
      <material name="mcp_joint_1_material">
        <color rgba="0.86666666666666669627 0.86666666666666669627 0.050980392156862744391 1.0" />
        </material>
      </visual>
    <collision>
      <origin xyz="0 0.018 0.0147" rpy="0 0 0" />
      <geometry>
        <box size="0.02 0.006 0.034" />
        </geometry>
      </collision>
    <collision>
      <origin xyz="-0.027 0.042 0.015" rpy="0 0 0" />
      <geometry>
        <box size="0.028 0.04 0.02" />
        </geometry>
      </collision>
    <collision>
      <origin xyz="-0.0262 0.02 0.0146" rpy="0 0 0" />
      <geometry>
        <box size="0.034 0.006 0.02" />
        </geometry>
      </collision>
    <collision>
      <origin xyz="-0.0295 0.035 0.029" rpy="0 0 0" />
      <geometry>
        <box size="0.02 0.024 0.008" />
        </geometry>
      </collision>
    <collision>
      <origin xyz="0 0.005 0.03" rpy="0 0 0" />
      <geometry>
        <box size="0.014 0.02 0.004" />
        </geometry>
      </collision>
    <collision>
      <origin xyz="0 0.005 -0.001" rpy="0 0 0" />
      <geometry>
        <box size="0.014 0.02 0.004" />
        </geometry>
      </collision>
    <inertial>
      <origin xyz="0 0 0" rpy="0 0 0" />
      <mass value="0.044" />
      <inertia ixx="0.000011499" ixy="0.000003049" ixz="0.000000121" iyy="0.000007796" iyz="0.000000112" izz="0.000014759" />
      </inertial>
    </link>
  <link name="pip_3">
    <visual>
      <origin xyz="0.0096433630922713314826 0.00029999999999998083755 0.00078403401041737645627" rpy="-1.570796326794896558 -1.570796326794896336 0" />
      <geometry>
        <mesh filename="leap_hand/pip.stl" />
        </geometry>
      <material name="pip_1_material">
        <color rgba="0.74901960784313725839 0.74901960784313725839 0.74901960784313725839 1.0" />
        </material>
      </visual>
    <collision>
      <origin xyz="0.0075 -0.0002 -0.011" rpy="0 0 0" />
      <geometry>
        <box size="0.034 0.026 0.022" />
        </geometry>
      </collision>
    <inertial>
      <origin xyz="0 0 0" rpy="0 0 0" />
      <mass value="0.032" />
      <inertia ixx="0.000004798" ixy="0.000000012" ixz="0.000000004" iyy="0.000002862" iyz="0.000000011" izz="0.000004234" />
      </inertial>
    </link>
  <link name="dip_3">
    <visual>
      <origin xyz="0.021133352895225006318 -0.0084321191467048653423 0.0097850881620952373519" rpy="-3.141592653589793116 -1.4095651113919093005e-33 1.5565411607615035382e-32" />
      <geometry>
        <mesh filename="leap_hand/dip.stl" />
        </geometry>
      <material name="dip_1_material">
        <color rgba="0.86666666666666669627 0.86666666666666669627 0.050980392156862744391 1.0" />
        </material>
      </visual>
    <collision>
      <origin xyz="0 -0.02 0.015" rpy="0 0 0" />
      <geometry>
        <box size="0.016 0.006 0.026" />
        </geometry>
      </collision>
    <collision>
      <origin xyz="0 -0.016 0.015" rpy="0 0 0" />
      <geometry>
        <box size="0.02 0.004 0.034" />
        </geometry>
      </collision>
    <collision>
      <origin xyz="0 -0.0045 0.03" rpy="0 0 0" />
      <geometry>
        <box size="0.014 0.02 0.004" />
        </geometry>
      </collision>
    <collision>
      <origin xyz="0 -0.0045 0" rpy="0 0 0" />
      <geometry>
        <box size="0.014 0.02 0.004" />
        </geometry>
      </collision>
    <collision>
      <origin xyz="0.0075 -0.035 0.015" rpy="0 0 0" />
      <geometry>
        <box size="0.034 0.022 0.026" />
        </geometry>
      </collision>
    <inertial>
      <origin xyz="0 0 0" rpy="0 0 0" />
      <mass value="0.037" />
      <inertia ixx="0.000005542" ixy="-0.000000607" ixz="-0.000000017" iyy="0.000005727" iyz="-0.000000023" izz="0.000006682" />
      </inertial>
    </link>
  <link name="fingertip_3">
    <visual>
      <origin xyz="0.013286424108533501434 -0.0061142383865419869249 0.0144999999999994994" rpy="3.141592653589793116 8.6170716950575402125e-33 1.5565411607615035382e-32" />
      <geometry>
        <mesh filename="leap_hand/fingertip.stl" />
        </geometry>
      <material name="fingertip_1_material">
        <color rgba="0.86666666666666669627 0.86666666666666669627 0.050980392156862744391 1.0" />
        </material>
      </visual>
    <collision>
      <origin xyz="0 -0.017 0.015" rpy="0 0 0" />
      <geometry>
        <box size="0.02 0.006 0.03" />
        </geometry>
      </collision>
    <collision>
      <origin xyz="0 -0.006 0.03" rpy="0 0 0" />
      <geometry>
        <box size="0.014 0.022 0.004" />
        </geometry>
      </collision>
    <collision>
      <origin xyz="0 -0.006 -0.001" rpy="0 0 0" />
      <geometry>
        <box size="0.014 0.022 0.004" />
        </geometry>
      </collision>
    <collision>
      <origin xyz="0 0 0" rpy="0 0 0" />
      <geometry>
        <mesh filename="leap_hand/tip_simplified.obj" />
        </geometry>
      </collision>
    <inertial>
      <origin xyz="0 0 0" rpy="0 0 0" />
      <mass value="0.016" />
      <inertia ixx="0.000003368" ixy="0.000000115" ixz="0" iyy="0.000001556" iyz="0" izz="0.000002863" />
      </inertial>
    </link>
  <joint name="leap_joint8" type="revolute">
    <origin xyz="-0.012200000000000004244 0.038100000000000001921 0.014499999999999999001" rpy="-1.570796326794896558 -1.0065212660796360242e-15 1.5707963267948943376" />
    <parent link="mcp_joint_3" />
    <child link="pip_3" />
    <axis xyz="0 0 -1" />
    <limit effort="0.95" velocity="8.48" lower="-1.047" upper="1.047" />
    <joint_properties friction="0.0" />
    </joint>
  <joint name="leap_joint9" type="revolute">
    <origin xyz="-0.0070952454426398371343 -0.067842243865100515521 -0.018722407666402932774" rpy="1.5707963267948950037 1.5707963267948945596 0" />
    <parent link="palm_link" />
    <child link="mcp_joint_3" />
    <axis xyz="0 0 -1" />
    <limit effort="0.95" velocity="8.48" lower="-0.314" upper="2.23" />
    <joint_properties friction="0.0" />
    </joint>
  <joint name="leap_joint10" type="revolute">
    <origin xyz="0.014999999999999971689 0.014299999999999951639 -0.012999999999999959505" rpy="1.5707963267948958919 -1.570796326794896336 0" />
    <parent link="pip_3" />
    <child link="dip_3" />
    <axis xyz="0 0 -1" />
    <limit effort="0.95" velocity="8.48" lower="-0.506" upper="1.885" />
    <joint_properties friction="0.0" />
    </joint>
  <joint name="leap_joint11" type="revolute">
    <origin xyz="9.7144514654701197287e-17 -0.036099999999999868305 0.00020000000000007511769" rpy="4.5935029425113685044e-17 -2.8730071914463799514e-16 1.5565411607615035382e-32" />
    <parent link="dip_3" />
    <child link="fingertip_3" />
    <axis xyz="0 0 -1" />
    <limit effort="0.95" velocity="8.48" lower="-0.366" upper="2.042" />
    <joint_properties friction="0.0" />
    </joint>
  <link name="pip_4">
    <visual>
      <origin xyz="-0.0053566369077286714317 0.00029999999999999991951 0.00078403401041737819099" rpy="-1.570796326794896558 -1.570796326794896336 0" />
      <geometry>
        <mesh filename="leap_hand/pip.stl" />
        </geometry>
      <material name="pip_1_material">
        <color rgba="0.74901960784313725839 0.74901960784313725839 0.74901960784313725839 1.0" />
        </material>
      </visual>
    <collision>
      <origin xyz="0.0075 -0.0002 -0.011" rpy="0 0 0" />
      <geometry>
        <box size="0.034 0.026 0.022" />
        </geometry>
      </collision>
    <inertial>
      <origin xyz="0 0 0" rpy="0 0 0" />
      <mass value="0.032" />
      <inertia ixx="0.000004798" ixy="0.000000012" ixz="0.000000004" iyy="0.000002862" iyz="0.000000011" izz="0.000004234" />
      </inertial>
    </link>
  <link name="thumb_pip">
    <visual>
      <origin xyz="0.011961920770611186859 -5.3082538364890297089e-16 -0.015852648956664199681" rpy="1.570796326794896558 1.6050198443300152637e-46 -3.9204996250525192755e-59" />
      <geometry>
        <mesh filename="leap_hand/thumb_pip.stl" />
        </geometry>
      <material name="thumb_pip_material">
        <color rgba="0.86666666666666669627 0.86666666666666669627 0.050980392156862744391 1.0" />
        </material>
      </visual>
    <collision>
      <origin xyz="0 0 -0.0015" rpy="0 0 0" />
      <geometry>
        <box size="0.018 0.033 0.004" />
        </geometry>
      </collision>
    <collision>
      <origin xyz="0 -0.015 -0.013" rpy="0 0 0" />
      <geometry>
        <box size="0.014 0.004 0.02" />
        </geometry>
      </collision>
    <collision>
      <origin xyz="0 0.015 -0.013" rpy="0 0 0" />
      <geometry>
        <box size="0.014 0.004 0.02" />
        </geometry>
      </collision>
    <inertial>
      <origin xyz="0 0 0" rpy="0 0 0" />
      <mass value="0.003" />
      <inertia ixx="0.000000593" ixy="0" ixz="0" iyy="0.000000549" iyz="0" izz="0.000000224" />
      </inertial>
    </link>
  <link name="thumb_dip">
    <visual>
      <origin xyz="0.043968715707239175439 0.057952952973709198625 -0.0086286764493694757122" rpy="1.9428902930940098942e-16 3.2751579226442200773e-15 1.1123758529657360012e-46" />
      <geometry>
        <mesh filename="leap_hand/thumb_dip.stl" />
        </geometry>
      <material name="thumb_dip_material">
        <color rgba="0.86666666666666669627 0.86666666666666669627 0.050980392156862744391 1.0" />
        </material>
      </visual>
    <collision>
      <origin xyz="0 0.0105 -0.014" rpy="0 0 0" />
      <geometry>
        <box size="0.02 0.04 0.024" />
        </geometry>
      </collision>
    <collision>
      <origin xyz="0 0.031 -0.015" rpy="0 0 0" />
      <geometry>
        <box size="0.02 0.004 0.032" />
        </geometry>
      </collision>
    <collision>
      <origin xyz="0 0.042 0.001" rpy="0 0 0" />
      <geometry>
        <box size="0.014 0.02 0.004" />
        </geometry>
      </collision>
    <collision>
      <origin xyz="0 0.042 -0.029" rpy="0 0 0" />
      <geometry>
        <box size="0.014 0.02 0.004" />
        </geometry>
      </collision>
    <collision>
      <origin xyz="-0.0135 0.0175 -0.011656" rpy="0 0 0" />
      <geometry>
        <box size="0.01 0.024 0.018" />
        </geometry>
      </collision>
    <inertial>
      <origin xyz="0 0 0" rpy="0 0 0" />
      <mass value="0.038" />
      <inertia ixx="0.000008474" ixy="0.000000241" ixz="0.000000026" iyy="0.000003841" iyz="0.000000025" izz="0.000007679" />
      </inertial>
    </link>
  <link name="thumb_fingertip">
    <visual>
      <origin xyz="0.062559538462667388381 0.078459682911396988469 0.048992911807332215068" rpy="4.3790577010156367543e-47 -3.3306690738754701143e-16 1.2042408677791935383e-46" />
      <geometry>
        <mesh filename="leap_hand/thumb_fingertip.stl" />
        </geometry>
      <material name="thumb_fingertip_material">
        <color rgba="0.60392156862745094426 0.14901960784313725283 0.14901960784313725283 1.0" />
        </material>
      </visual>
    <collision>
      <origin xyz="0 -0.0085 -0.015" rpy="0 0 0" />
      <geometry>
        <box size="0.02 0.036 0.024" />
        </geometry>
      </collision>
    <collision>
      <origin xyz="0 -0.029 -0.014" rpy="0 0 0" />
      <geometry>
        <box size="0.02 0.004 0.03" />
        </geometry>
      </collision>
    <collision>
      <origin xyz="0.015 -0.0175 -0.0115" rpy="0 0 0" />
      <geometry>
        <box size="0.008 0.024 0.018" />
        </geometry>
      </collision>
    <collision>
      <origin xyz="0 0 0" rpy="0 0 0" />
      <geometry>
        <mesh filename="leap_hand/thumb_tip_simplified.obj" />
        </geometry>
      </collision>
    <inertial>
      <origin xyz="0 0 0" rpy="0 0 0" />
      <mass value="0.049" />
      <inertia ixx="0.000020372" ixy="-0.000000489" ixz="-0.00000003" iyy="0.000004336" iyz="-0.000000097" izz="0.000019845" />
      </inertial>
    </link>
  <joint name="leap_joint12" type="revolute">
    <origin xyz="-0.069395249652862533996 -0.0012422438651005258004 -0.021622403578460215601" rpy="-8.2381766464939424156e-17 1.5707963267948956698 0" />
    <parent link="palm_link" />
    <child link="pip_4" />
    <axis xyz="0 0 -1" />
    <limit effort="0.95" velocity="8.48" lower="-0.349" upper="2.094" />
    <joint_properties friction="0.0" />
    </joint>
  <joint name="leap_joint13" type="revolute">
    <origin xyz="-2.7755575615628913511e-17 0.014300000000000005415 -0.013000000000000011546" rpy="1.5707963267948958919 -1.570796326794896336 0" />
    <parent link="pip_4" />
    <child link="thumb_pip" />
    <axis xyz="0 0 -1" />
    <limit effort="0.95" velocity="8.48" lower="-0.47" upper="2.443" />
    <joint_properties friction="0.0" />
    </joint>
  <joint name="leap_joint14" type="revolute">
    <origin xyz="0 0.014499999999999966041 -0.017000000000000053263" rpy="-1.570796326794896558 1.6050198443300131245e-46 -1.9721522630516624601e-31" />
    <parent link="thumb_pip" />
    <child link="thumb_dip" />
    <axis xyz="0 0 -1" />
    <limit effort="0.95" velocity="8.48" lower="-1.20" upper="1.90" />
    <joint_properties friction="0.0" />
    </joint>
  <joint name="leap_joint15" type="revolute">
    <origin xyz="-1.249000902703301108e-16 0.046599999999999863753 0.00019999999999997710581" rpy="1.5063958491491781023e-44 5.4234187233935260503e-31 3.141592653589793116" />
    <parent link="thumb_dip" />
    <child link="thumb_fingertip" />
    <axis xyz="0 0 -1" />
    <limit effort="0.95" velocity="8.48" lower="-1.34" upper="1.88" />
    <joint_properties friction="0.0" />
    </joint>
  <link name="link_base_sphere1" />
  <joint name="link_base_joint_sphere1" type="fixed">
    <parent link="link_base" />
    <child link="link_base_sphere1" />
    <origin rpy="0 0 0" xyz="-0.009823 -0.00042 0.045933" />
    <axis xyz="0 0 1" />
    </joint>
  <link name="link_base_sphere2" />
  <joint name="link_base_joint_sphere2" type="fixed">
    <parent link="link_base" />
    <child link="link_base_sphere2" />
    <origin rpy="0 0 0" xyz="0.001143 0.001023 0.096427" />
    <axis xyz="0 0 1" />
    </joint>
  <link name="link1_sphere1" />
  <joint name="link1_joint_sphere1" type="fixed">
    <parent link="link1" />
    <child link="link1_sphere1" />
    <origin rpy="0 0 0" xyz="0.000119 0.016853 -0.00018" />
    <axis xyz="0 0 1" />
    </joint>
  <link name="link1_sphere2" />
  <joint name="link1_joint_sphere2" type="fixed">
    <parent link="link1" />
    <child link="link1_sphere2" />
    <origin rpy="0 0 0" xyz="-0.000234 -0.004739 -0.065576" />
    <axis xyz="0 0 1" />
    </joint>
  <link name="link2_sphere1" />
  <joint name="link2_joint_sphere1" type="fixed">
    <parent link="link2" />
    <child link="link2_sphere1" />
    <origin rpy="0 0 0" xyz="-0.00171 -0.095399 0.072802" />
    <axis xyz="0 0 1" />
    </joint>
  <link name="link2_sphere2" />
  <joint name="link2_joint_sphere2" type="fixed">
    <parent link="link2" />
    <child link="link2_sphere2" />
    <origin rpy="0 0 0" xyz="-0.000301 -0.133322 0.001671" />
    <axis xyz="0 0 1" />
    </joint>
  <link name="link2_sphere3" />
  <joint name="link2_joint_sphere3" type="fixed">
    <parent link="link2" />
    <child link="link2_sphere3" />
    <origin rpy="0 0 0" xyz="-0.015401 0.005834 0.096103" />
    <axis xyz="0 0 1" />
    </joint>
  <link name="link2_sphere4" />
  <joint name="link2_joint_sphere4" type="fixed">
    <parent link="link2" />
    <child link="link2_sphere4" />
    <origin rpy="0 0 0" xyz="0.022087 0.000248 0.094505" />
    <axis xyz="0 0 1" />
    </joint>
  <link name="link3_sphere1" />
  <joint name="link3_joint_sphere1" type="fixed">
    <parent link="link3" />
    <child link="link3_sphere1" />
    <origin rpy="0 0 0" xyz="0.013209 0.010032 -0.045652" />
    <axis xyz="0 0 1" />
    </joint>
  <link name="link3_sphere2" />
  <joint name="link3_joint_sphere2" type="fixed">
    <parent link="link3" />
    <child link="link3_sphere2" />
    <origin rpy="0 0 0" xyz="0.050794 -0.003524 -0.000414" />
    <axis xyz="0 0 1" />
    </joint>
  <link name="link4_sphere1" />
  <joint name="link4_joint_sphere1" type="fixed">
    <parent link="link4" />
    <child link="link4_sphere1" />
    <origin rpy="0 0 0" xyz="0.069956 -0.080383 0.061747" />
    <axis xyz="0 0 1" />
    </joint>
  <link name="link4_sphere2" />
  <joint name="link4_joint_sphere2" type="fixed">
    <parent link="link4" />
    <child link="link4_sphere2" />
    <origin rpy="0 0 0" xyz="0.077847 -0.091376 0.014255" />
    <axis xyz="0 0 1" />
    </joint>
  <link name="link4_sphere3" />
  <joint name="link4_joint_sphere3" type="fixed">
    <parent link="link4" />
    <child link="link4_sphere3" />
    <origin rpy="0 0 0" xyz="0.077936 -0.130772 0.007635" />
    <axis xyz="0 0 1" />
    </joint>
  <link name="link4_sphere4" />
  <joint name="link4_joint_sphere4" type="fixed">
    <parent link="link4" />
    <child link="link4_sphere4" />
    <origin rpy="0 0 0" xyz="0.026582 -0.023333 0.083471" />
    <axis xyz="0 0 1" />
    </joint>
  <link name="link4_sphere5" />
  <joint name="link4_joint_sphere5" type="fixed">
    <parent link="link4" />
    <child link="link4_sphere5" />
    <origin rpy="0 0 0" xyz="-0.001109 -0.001125 0.086548" />
    <axis xyz="0 0 1" />
    </joint>
  <link name="link5_sphere1" />
  <joint name="link5_joint_sphere1" type="fixed">
    <parent link="link5" />
    <child link="link5_sphere1" />
    <origin rpy="0 0 0" xyz="0.002048 0.003509 -0.144887" />
    <axis xyz="0 0 1" />
    </joint>
  <link name="link5_sphere2" />
  <joint name="link5_joint_sphere2" type="fixed">
    <parent link="link5" />
    <child link="link5_sphere2" />
    <origin rpy="0 0 0" xyz="-7.5e-05 0.053318 -0.031886" />
    <axis xyz="0 0 1" />
    </joint>
  <link name="link5_sphere3" />
  <joint name="link5_joint_sphere3" type="fixed">
    <parent link="link5" />
    <child link="link5_sphere3" />
    <origin rpy="0 0 0" xyz="-0.00063 0.040215 -0.000145" />
    <axis xyz="0 0 1" />
    </joint>
  <link name="link5_sphere4" />
  <joint name="link5_joint_sphere4" type="fixed">
    <parent link="link5" />
    <child link="link5_sphere4" />
    <origin rpy="0 0 0" xyz="-0.002708 0.042677 -0.109673" />
    <axis xyz="0 0 1" />
    </joint>
  <link name="link5_sphere5" />
  <joint name="link5_joint_sphere5" type="fixed">
    <parent link="link5" />
    <child link="link5_sphere5" />
    <origin rpy="0 0 0" xyz="0.000113 0.061089 -0.080479" />
    <axis xyz="0 0 1" />
    </joint>
  <link name="link6_sphere1" />
  <joint name="link6_joint_sphere1" type="fixed">
    <parent link="link6" />
    <child link="link6_sphere1" />
    <origin rpy="0 0 0" xyz="0.020125 0.000188 0.021902" />
    <axis xyz="0 0 1" />
    </joint>
  <link name="link6_sphere2" />
  <joint name="link6_joint_sphere2" type="fixed">
    <parent link="link6" />
    <child link="link6_sphere2" />
    <origin rpy="0 0 0" xyz="0.075982 0.020571 6.9e-05" />
    <axis xyz="0 0 1" />
    </joint>
  <link name="link7_sphere1" />
  <joint name="link7_joint_sphere1" type="fixed">
    <parent link="link7" />
    <child link="link7_sphere1" />
    <origin rpy="0 0 0" xyz="0.000157 0.001368 -0.013522" />
    <axis xyz="0 0 1" />
    </joint>
  <link name="link7_sphere2" />
  <joint name="link7_joint_sphere2" type="fixed">
    <parent link="link7" />
    <child link="link7_sphere2" />
    <origin rpy="0 0 0" xyz="-0.009807 -0.014766 -0.013716" />
    <axis xyz="0 0 1" />
    </joint>
  <link name="palm_link_sphere1" />
  <joint name="palm_link_joint_sphere1" type="fixed">
    <parent link="palm_link" />
    <child link="palm_link_sphere1" />
    <origin rpy="0 0 0" xyz="-0.078 -0.053 -0.0115" />
    <axis xyz="0 0 1" />
    </joint>
  <link name="palm_link_sphere2" />
  <joint name="palm_link_joint_sphere2" type="fixed">
    <parent link="palm_link" />
    <child link="palm_link_sphere2" />
    <origin rpy="0 0 0" xyz="-0.048 -0.028875 -0.01042" />
    <axis xyz="0 0 1" />
    </joint>
  <link name="palm_link_sphere3" />
  <joint name="palm_link_joint_sphere3" type="fixed">
    <parent link="palm_link" />
    <child link="palm_link_sphere3" />
    <origin rpy="0 0 0" xyz="-0.048 0.001307 -0.022502" />
    <axis xyz="0 0 1" />
    </joint>
  <link name="palm_link_sphere4" />
  <joint name="palm_link_joint_sphere4" type="fixed">
    <parent link="palm_link" />
    <child link="palm_link_sphere4" />
    <origin rpy="0 0 0" xyz="-0.047999 -0.055233 -0.012001" />
    <axis xyz="0 0 1" />
    </joint>
  <link name="palm_link_sphere5" />
  <joint name="palm_link_joint_sphere5" type="fixed">
    <parent link="palm_link" />
    <child link="palm_link_sphere5" />
    <origin rpy="0 0 0" xyz="-0.048 -0.079001 -0.011502" />
    <axis xyz="0 0 1" />
    </joint>
  <link name="palm_link_sphere6" />
  <joint name="palm_link_joint_sphere6" type="fixed">
    <parent link="palm_link" />
    <child link="palm_link_sphere6" />
    <origin rpy="0 0 0" xyz="-0.048111 -0.083471 -0.0115" />
    <axis xyz="0 0 1" />
    </joint>
  <link name="palm_link_sphere7" />
  <joint name="palm_link_joint_sphere7" type="fixed">
    <parent link="palm_link" />
    <child link="palm_link_sphere7" />
    <origin rpy="0 0 0" xyz="-0.048 0.006352 -0.003678" />
    <axis xyz="0 0 1" />
    </joint>
  <link name="palm_link_sphere8" />
  <joint name="palm_link_joint_sphere8" type="fixed">
    <parent link="palm_link" />
    <child link="palm_link_sphere8" />
    <origin rpy="0 0 0" xyz="-0.072741 -0.075939 -0.023339" />
    <axis xyz="0 0 1" />
    </joint>
  <link name="palm_link_sphere9" />
  <joint name="palm_link_joint_sphere9" type="fixed">
    <parent link="palm_link" />
    <child link="palm_link_sphere9" />
    <origin rpy="0 0 0" xyz="-0.075006 -0.075247 -0.001375" />
    <axis xyz="0 0 1" />
    </joint>
  <link name="palm_link_sphere10" />
  <joint name="palm_link_joint_sphere10" type="fixed">
    <parent link="palm_link" />
    <child link="palm_link_sphere10" />
    <origin rpy="0 0 0" xyz="-0.03 -0.013925 -0.003518" />
    <axis xyz="0 0 1" />
    </joint>
  <link name="palm_link_sphere11" />
  <joint name="palm_link_joint_sphere11" type="fixed">
    <parent link="palm_link" />
    <child link="palm_link_sphere11" />
    <origin rpy="0 0 0" xyz="-0.030001 -0.040293 -0.008" />
    <axis xyz="0 0 1" />
    </joint>
  <link name="palm_link_sphere12" />
  <joint name="palm_link_joint_sphere12" type="fixed">
    <parent link="palm_link" />
    <child link="palm_link_sphere12" />
    <origin rpy="0 0 0" xyz="-0.009 0.008 -0.017" />
    <axis xyz="0 0 1" />
    </joint>
  <link name="palm_link_sphere13" />
  <joint name="palm_link_joint_sphere13" type="fixed">
    <parent link="palm_link" />
    <child link="palm_link_sphere13" />
    <origin rpy="0 0 0" xyz="-0.009001 0.008 -0.005" />
    <axis xyz="0 0 1" />
    </joint>
  <link name="palm_link_sphere14" />
  <joint name="palm_link_joint_sphere14" type="fixed">
    <parent link="palm_link" />
    <child link="palm_link_sphere14" />
    <origin rpy="0 0 0" xyz="-0.009 -0.037 -0.017" />
    <axis xyz="0 0 1" />
    </joint>
  <link name="palm_link_sphere15" />
  <joint name="palm_link_joint_sphere15" type="fixed">
    <parent link="palm_link" />
    <child link="palm_link_sphere15" />
    <origin rpy="0 0 0" xyz="-0.009001 -0.037 -0.005" />
    <axis xyz="0 0 1" />
    </joint>
  <link name="palm_link_sphere16" />
  <joint name="palm_link_joint_sphere16" type="fixed">
    <parent link="palm_link" />
    <child link="palm_link_sphere16" />
    <origin rpy="0 0 0" xyz="-0.009 -0.082 -0.017" />
    <axis xyz="0 0 1" />
    </joint>
  <link name="palm_link_sphere17" />
  <joint name="palm_link_joint_sphere17" type="fixed">
    <parent link="palm_link" />
    <child link="palm_link_sphere17" />
    <origin rpy="0 0 0" xyz="-0.009001 -0.082 -0.005" />
    <axis xyz="0 0 1" />
    </joint>
  <link name="palm_link_sphere18" />
  <joint name="palm_link_joint_sphere18" type="fixed">
    <parent link="palm_link" />
    <child link="palm_link_sphere18" />
    <origin rpy="0 0 0" xyz="-0.03 0.010755 0.002" />
    <axis xyz="0 0 1" />
    </joint>
  <link name="palm_link_sphere19" />
  <joint name="palm_link_joint_sphere19" type="fixed">
    <parent link="palm_link" />
    <child link="palm_link_sphere19" />
    <origin rpy="0 0 0" xyz="-0.029997 -0.034841 0.002003" />
    <axis xyz="0 0 1" />
    </joint>
  <link name="palm_link_sphere20" />
  <joint name="palm_link_joint_sphere20" type="fixed">
    <parent link="palm_link" />
    <child link="palm_link_sphere20" />
    <origin rpy="0 0 0" xyz="-0.029999 0.010858 -0.008003" />
    <axis xyz="0 0 1" />
    </joint>
  <link name="palm_link_sphere21" />
  <joint name="palm_link_joint_sphere21" type="fixed">
    <parent link="palm_link" />
    <child link="palm_link_sphere21" />
    <origin rpy="0 0 0" xyz="-0.029999 -0.060492 -0.001707" />
    <axis xyz="0 0 1" />
    </joint>
  <link name="palm_link_sphere22" />
  <joint name="palm_link_joint_sphere22" type="fixed">
    <parent link="palm_link" />
    <child link="palm_link_sphere22" />
    <origin rpy="0 0 0" xyz="-0.030001 -0.081354 -0.008001" />
    <axis xyz="0 0 1" />
    </joint>
  <link name="palm_link_sphere23" />
  <joint name="palm_link_joint_sphere23" type="fixed">
    <parent link="palm_link" />
    <child link="palm_link_sphere23" />
    <origin rpy="0 0 0" xyz="-0.03 -0.083762 0.002" />
    <axis xyz="0 0 1" />
    </joint>
  <link name="palm_link_sphere24" />
  <joint name="palm_link_joint_sphere24" type="fixed">
    <parent link="palm_link" />
    <child link="palm_link_sphere24" />
    <origin rpy="0 0 0" xyz="-0.031989 -0.071381 -0.023989" />
    <axis xyz="0 0 1" />
    </joint>
  <link name="palm_link_sphere25" />
  <joint name="palm_link_joint_sphere25" type="fixed">
    <parent link="palm_link" />
    <child link="palm_link_sphere25" />
    <origin rpy="0 0 0" xyz="-0.032313 -0.055604 -0.024313" />
    <axis xyz="0 0 1" />
    </joint>
  <link name="palm_link_sphere26" />
  <joint name="palm_link_joint_sphere26" type="fixed">
    <parent link="palm_link" />
    <child link="palm_link_sphere26" />
    <origin rpy="0 0 0" xyz="-0.032 -0.087726 -0.023999" />
    <axis xyz="0 0 1" />
    </joint>
  <link name="palm_link_sphere27" />
  <joint name="palm_link_joint_sphere27" type="fixed">
    <parent link="palm_link" />
    <child link="palm_link_sphere27" />
    <origin rpy="0 0 0" xyz="-0.032 0.001981 -0.024" />
    <axis xyz="0 0 1" />
    </joint>
  <link name="palm_link_sphere28" />
  <joint name="palm_link_joint_sphere28" type="fixed">
    <parent link="palm_link" />
    <child link="palm_link_sphere28" />
    <origin rpy="0 0 0" xyz="-0.032 0.017733 -0.024" />
    <axis xyz="0 0 1" />
    </joint>
  <link name="palm_link_sphere29" />
  <joint name="palm_link_joint_sphere29" type="fixed">
    <parent link="palm_link" />
    <child link="palm_link_sphere29" />
    <origin rpy="0 0 0" xyz="-0.031428 -0.041055 -0.023428" />
    <axis xyz="0 0 1" />
    </joint>
  <link name="palm_link_sphere30" />
  <joint name="palm_link_joint_sphere30" type="fixed">
    <parent link="palm_link" />
    <child link="palm_link_sphere30" />
    <origin rpy="0 0 0" xyz="-0.032287 -0.027111 -0.024288" />
    <axis xyz="0 0 1" />
    </joint>
  <link name="palm_link_sphere31" />
  <joint name="palm_link_joint_sphere31" type="fixed">
    <parent link="palm_link" />
    <child link="palm_link_sphere31" />
    <origin rpy="0 0 0" xyz="-0.03173 -0.0126 -0.02373" />
    <axis xyz="0 0 1" />
    </joint>
  <link name="palm_link_sphere32" />
  <joint name="palm_link_joint_sphere32" type="fixed">
    <parent link="palm_link" />
    <child link="palm_link_sphere32" />
    <origin rpy="0 0 0" xyz="-0.082469 0.013555 0.01" />
    <axis xyz="0 0 1" />
    </joint>
  <link name="palm_link_sphere33" />
  <joint name="palm_link_joint_sphere33" type="fixed">
    <parent link="palm_link" />
    <child link="palm_link_sphere33" />
    <origin rpy="0 0 0" xyz="-0.065778 0.01688 0.01" />
    <axis xyz="0 0 1" />
    </joint>
  <link name="palm_link_sphere34" />
  <joint name="palm_link_joint_sphere34" type="fixed">
    <parent link="palm_link" />
    <child link="palm_link_sphere34" />
    <origin rpy="0 0 0" xyz="-0.065559 -0.000665 0.01" />
    <axis xyz="0 0 1" />
    </joint>
  <link name="palm_link_sphere35" />
  <joint name="palm_link_joint_sphere35" type="fixed">
    <parent link="palm_link" />
    <child link="palm_link_sphere35" />
    <origin rpy="0 0 0" xyz="-0.074894 -0.019508 0.01" />
    <axis xyz="0 0 1" />
    </joint>
  <link name="palm_link_sphere36" />
  <joint name="palm_link_joint_sphere36" type="fixed">
    <parent link="palm_link" />
    <child link="palm_link_sphere36" />
    <origin rpy="0 0 0" xyz="-0.090468 -0.022658 0.01" />
    <axis xyz="0 0 1" />
    </joint>
  <link name="palm_link_sphere37" />
  <joint name="palm_link_joint_sphere37" type="fixed">
    <parent link="palm_link" />
    <child link="palm_link_sphere37" />
    <origin rpy="0 0 0" xyz="-0.089653 -0.00586 0.01" />
    <axis xyz="0 0 1" />
    </joint>
  <link name="palm_link_sphere38" />
  <joint name="palm_link_joint_sphere38" type="fixed">
    <parent link="palm_link" />
    <child link="palm_link_sphere38" />
    <origin rpy="0 0 0" xyz="-0.0946 0.013656 0.01" />
    <axis xyz="0 0 1" />
    </joint>
  <link name="palm_link_sphere39" />
  <joint name="palm_link_joint_sphere39" type="fixed">
    <parent link="palm_link" />
    <child link="palm_link_sphere39" />
    <origin rpy="0 0 0" xyz="-0.062443 -0.0204 0.010001" />
    <axis xyz="0 0 1" />
    </joint>
  <link name="palm_link_sphere40" />
  <joint name="palm_link_joint_sphere40" type="fixed">
    <parent link="palm_link" />
    <child link="palm_link_sphere40" />
    <origin rpy="0 0 0" xyz="-0.098 -0.009537 0.002595" />
    <axis xyz="0 0 1" />
    </joint>
  <link name="palm_link_sphere41" />
  <joint name="palm_link_joint_sphere41" type="fixed">
    <parent link="palm_link" />
    <child link="palm_link_sphere41" />
    <origin rpy="0 0 0" xyz="-0.098 -0.019812 -0.017496" />
    <axis xyz="0 0 1" />
    </joint>
  <link name="palm_link_sphere42" />
  <joint name="palm_link_joint_sphere42" type="fixed">
    <parent link="palm_link" />
    <child link="palm_link_sphere42" />
    <origin rpy="0 0 0" xyz="-0.098 -0.020571 0.004727" />
    <axis xyz="0 0 1" />
    </joint>
  <link name="palm_link_sphere43" />
  <joint name="palm_link_joint_sphere43" type="fixed">
    <parent link="palm_link" />
    <child link="palm_link_sphere43" />
    <origin rpy="0 0 0" xyz="-0.098 0.002 0.005396" />
    <axis xyz="0 0 1" />
    </joint>
  <link name="palm_link_sphere44" />
  <joint name="palm_link_joint_sphere44" type="fixed">
    <parent link="palm_link" />
    <child link="palm_link_sphere44" />
    <origin rpy="0 0 0" xyz="-0.098 -0.008835 -0.014573" />
    <axis xyz="0 0 1" />
    </joint>
  <link name="palm_link_sphere45" />
  <joint name="palm_link_joint_sphere45" type="fixed">
    <parent link="palm_link" />
    <child link="palm_link_sphere45" />
    <origin rpy="0 0 0" xyz="-0.098 0.003618 -0.008074" />
    <axis xyz="0 0 1" />
    </joint>
  <link name="palm_link_sphere46" />
  <joint name="palm_link_joint_sphere46" type="fixed">
    <parent link="palm_link" />
    <child link="palm_link_sphere46" />
    <origin rpy="0 0 0" xyz="-0.098 -0.019778 -0.006756" />
    <axis xyz="0 0 1" />
    </joint>
  <link name="palm_link_sphere47" />
  <joint name="palm_link_joint_sphere47" type="fixed">
    <parent link="palm_link" />
    <child link="palm_link_sphere47" />
    <origin rpy="0 0 0" xyz="-0.098 0.001251 -0.019496" />
    <axis xyz="0 0 1" />
    </joint>
  <link name="mcp_joint_1_sphere1" />
  <joint name="mcp_joint_1_joint_sphere1" type="fixed">
    <parent link="mcp_joint_1" />
    <child link="mcp_joint_1_sphere1" />
    <origin rpy="0 0 0" xyz="-0.027001 0.031999 0.015" />
    <axis xyz="0 0 1" />
    </joint>
  <link name="mcp_joint_1_sphere2" />
  <joint name="mcp_joint_1_joint_sphere2" type="fixed">
    <parent link="mcp_joint_1" />
    <child link="mcp_joint_1_sphere2" />
    <origin rpy="0 0 0" xyz="-0.026999 0.052001 0.015" />
    <axis xyz="0 0 1" />
    </joint>
  <link name="mcp_joint_1_sphere3" />
  <joint name="mcp_joint_1_joint_sphere3" type="fixed">
    <parent link="mcp_joint_1" />
    <child link="mcp_joint_1_sphere3" />
    <origin rpy="0 0 0" xyz="-0.0295 0.042919 0.029" />
    <axis xyz="0 0 1" />
    </joint>
  <link name="mcp_joint_1_sphere4" />
  <joint name="mcp_joint_1_joint_sphere4" type="fixed">
    <parent link="mcp_joint_1" />
    <child link="mcp_joint_1_sphere4" />
    <origin rpy="0 0 0" xyz="-0.025257 0.030674 0.029" />
    <axis xyz="0 0 1" />
    </joint>
  <link name="mcp_joint_1_sphere5" />
  <joint name="mcp_joint_1_joint_sphere5" type="fixed">
    <parent link="mcp_joint_1" />
    <child link="mcp_joint_1_sphere5" />
    <origin rpy="0 0 0" xyz="-0.018096 0.02 0.007599" />
    <axis xyz="0 0 1" />
    </joint>
  <link name="mcp_joint_1_sphere6" />
  <joint name="mcp_joint_1_joint_sphere6" type="fixed">
    <parent link="mcp_joint_1" />
    <child link="mcp_joint_1_sphere6" />
    <origin rpy="0 0 0" xyz="-0.03524 0.02 0.009029" />
    <axis xyz="0 0 1" />
    </joint>
  <link name="mcp_joint_1_sphere7" />
  <joint name="mcp_joint_1_joint_sphere7" type="fixed">
    <parent link="mcp_joint_1" />
    <child link="mcp_joint_1_sphere7" />
    <origin rpy="0 0 0" xyz="0.006998 0.018 0.006286" />
    <axis xyz="0 0 1" />
    </joint>
  <link name="mcp_joint_1_sphere8" />
  <joint name="mcp_joint_1_joint_sphere8" type="fixed">
    <parent link="mcp_joint_1" />
    <child link="mcp_joint_1_sphere8" />
    <origin rpy="0 0 0" xyz="-0.035439 0.03067 0.029" />
    <axis xyz="0 0 1" />
    </joint>
  <link name="mcp_joint_1_sphere9" />
  <joint name="mcp_joint_1_joint_sphere9" type="fixed">
    <parent link="mcp_joint_1" />
    <child link="mcp_joint_1_sphere9" />
    <origin rpy="0 0 0" xyz="0.006494 0.018 0.023403" />
    <axis xyz="0 0 1" />
    </joint>
  <link name="mcp_joint_1_sphere10" />
  <joint name="mcp_joint_1_joint_sphere10" type="fixed">
    <parent link="mcp_joint_1" />
    <child link="mcp_joint_1_sphere10" />
    <origin rpy="0 0 0" xyz="-0.036193 0.02 0.019267" />
    <axis xyz="0 0 1" />
    </joint>
  <link name="mcp_joint_1_sphere11" />
  <joint name="mcp_joint_1_joint_sphere11" type="fixed">
    <parent link="mcp_joint_1" />
    <child link="mcp_joint_1_sphere11" />
    <origin rpy="0 0 0" xyz="-0.013073 0.02 0.016885" />
    <axis xyz="0 0 1" />
    </joint>
  <link name="mcp_joint_1_sphere12" />
  <joint name="mcp_joint_1_joint_sphere12" type="fixed">
    <parent link="mcp_joint_1" />
    <child link="mcp_joint_1_sphere12" />
    <origin rpy="0 0 0" xyz="-0.003105 0.018 0.002528" />
    <axis xyz="0 0 1" />
    </joint>
  <link name="mcp_joint_1_sphere13" />
  <joint name="mcp_joint_1_joint_sphere13" type="fixed">
    <parent link="mcp_joint_1" />
    <child link="mcp_joint_1_sphere13" />
    <origin rpy="0 0 0" xyz="-0.005154 0.017999 0.014529" />
    <axis xyz="0 0 1" />
    </joint>
  <link name="mcp_joint_1_sphere14" />
  <joint name="mcp_joint_1_joint_sphere14" type="fixed">
    <parent link="mcp_joint_1" />
    <child link="mcp_joint_1_sphere14" />
    <origin rpy="0 0 0" xyz="-0.02314 0.02 0.018738" />
    <axis xyz="0 0 1" />
    </joint>
  <link name="mcp_joint_1_sphere15" />
  <joint name="mcp_joint_1_joint_sphere15" type="fixed">
    <parent link="mcp_joint_1" />
    <child link="mcp_joint_1_sphere15" />
    <origin rpy="0 0 0" xyz="-0.003739 0.018 0.026747" />
    <axis xyz="0 0 1" />
    </joint>
  <link name="mcp_joint_1_sphere16" />
  <joint name="mcp_joint_1_joint_sphere16" type="fixed">
    <parent link="mcp_joint_1" />
    <child link="mcp_joint_1_sphere16" />
    <origin rpy="0 0 0" xyz="0.003682 0.009655 0.03" />
    <axis xyz="0 0 1" />
    </joint>
  <link name="mcp_joint_1_sphere17" />
  <joint name="mcp_joint_1_joint_sphere17" type="fixed">
    <parent link="mcp_joint_1" />
    <child link="mcp_joint_1_sphere17" />
    <origin rpy="0 0 0" xyz="0.003682 0.009655 -0.001" />
    <axis xyz="0 0 1" />
    </joint>
  <link name="mcp_joint_1_sphere18" />
  <joint name="mcp_joint_1_joint_sphere18" type="fixed">
    <parent link="mcp_joint_1" />
    <child link="mcp_joint_1_sphere18" />
    <origin rpy="0 0 0" xyz="-0.003949 0.000145 0.03" />
    <axis xyz="0 0 1" />
    </joint>
  <link name="mcp_joint_1_sphere19" />
  <joint name="mcp_joint_1_joint_sphere19" type="fixed">
    <parent link="mcp_joint_1" />
    <child link="mcp_joint_1_sphere19" />
    <origin rpy="0 0 0" xyz="-0.003949 0.000145 -0.001" />
    <axis xyz="0 0 1" />
    </joint>
  <link name="mcp_joint_1_sphere20" />
  <joint name="mcp_joint_1_joint_sphere20" type="fixed">
    <parent link="mcp_joint_1" />
    <child link="mcp_joint_1_sphere20" />
    <origin rpy="0 0 0" xyz="0.003189 -0.000464 0.03" />
    <axis xyz="0 0 1" />
    </joint>
  <link name="mcp_joint_1_sphere21" />
  <joint name="mcp_joint_1_joint_sphere21" type="fixed">
    <parent link="mcp_joint_1" />
    <child link="mcp_joint_1_sphere21" />
    <origin rpy="0 0 0" xyz="0.003189 -0.000464 -0.001" />
    <axis xyz="0 0 1" />
    </joint>
  <link name="mcp_joint_1_sphere22" />
  <joint name="mcp_joint_1_joint_sphere22" type="fixed">
    <parent link="mcp_joint_1" />
    <child link="mcp_joint_1_sphere22" />
    <origin rpy="0 0 0" xyz="-0.003375 0.010346 0.03" />
    <axis xyz="0 0 1" />
    </joint>
  <link name="mcp_joint_1_sphere23" />
  <joint name="mcp_joint_1_joint_sphere23" type="fixed">
    <parent link="mcp_joint_1" />
    <child link="mcp_joint_1_sphere23" />
    <origin rpy="0 0 0" xyz="-0.003375 0.010346 -0.001" />
    <axis xyz="0 0 1" />
    </joint>
  <link name="pip_1_sphere1" />
  <joint name="pip_1_joint_sphere1" type="fixed">
    <parent link="pip_1" />
    <child link="pip_1_sphere1" />
    <origin rpy="0 0 0" xyz="0.001501 -0.0002 -0.011" />
    <axis xyz="0 0 1" />
    </joint>
  <link name="pip_1_sphere2" />
  <joint name="pip_1_joint_sphere2" type="fixed">
    <parent link="pip_1" />
    <child link="pip_1_sphere2" />
    <origin rpy="0 0 0" xyz="0.013501 -0.0002 -0.010999" />
    <axis xyz="0 0 1" />
    </joint>
  <link name="dip_1_sphere1" />
  <joint name="dip_1_joint_sphere1" type="fixed">
    <parent link="dip_1" />
    <child link="dip_1_sphere1" />
    <origin rpy="0 0 0" xyz="0.0015 -0.035001 0.015" />
    <axis xyz="0 0 1" />
    </joint>
  <link name="dip_1_sphere2" />
  <joint name="dip_1_joint_sphere2" type="fixed">
    <parent link="dip_1" />
    <child link="dip_1_sphere2" />
    <origin rpy="0 0 0" xyz="0.0135 -0.035 0.014999" />
    <axis xyz="0 0 1" />
    </joint>
  <link name="dip_1_sphere3" />
  <joint name="dip_1_joint_sphere3" type="fixed">
    <parent link="dip_1" />
    <child link="dip_1_sphere3" />
    <origin rpy="0 0 0" xyz="-0.004874 -0.02 0.009187" />
    <axis xyz="0 0 1" />
    </joint>
  <link name="dip_1_sphere4" />
  <joint name="dip_1_joint_sphere4" type="fixed">
    <parent link="dip_1" />
    <child link="dip_1_sphere4" />
    <origin rpy="0 0 0" xyz="0.004477 -0.02 0.021215" />
    <axis xyz="0 0 1" />
    </joint>
  <link name="dip_1_sphere5" />
  <joint name="dip_1_joint_sphere5" type="fixed">
    <parent link="dip_1" />
    <child link="dip_1_sphere5" />
    <origin rpy="0 0 0" xyz="0.003347 -0.02 0.007914" />
    <axis xyz="0 0 1" />
    </joint>
  <link name="dip_1_sphere6" />
  <joint name="dip_1_joint_sphere6" type="fixed">
    <parent link="dip_1" />
    <child link="dip_1_sphere6" />
    <origin rpy="0 0 0" xyz="-0.003656 -0.02 0.022271" />
    <axis xyz="0 0 1" />
    </joint>
  <link name="dip_1_sphere7" />
  <joint name="dip_1_joint_sphere7" type="fixed">
    <parent link="dip_1" />
    <child link="dip_1_sphere7" />
    <origin rpy="0 0 0" xyz="0.006365 -0.016 0.017072" />
    <axis xyz="0 0 1" />
    </joint>
  <link name="dip_1_sphere8" />
  <joint name="dip_1_joint_sphere8" type="fixed">
    <parent link="dip_1" />
    <child link="dip_1_sphere8" />
    <origin rpy="0 0 0" xyz="-0.005092 -0.016 0.020145" />
    <axis xyz="0 0 1" />
    </joint>
  <link name="dip_1_sphere9" />
  <joint name="dip_1_joint_sphere9" type="fixed">
    <parent link="dip_1" />
    <child link="dip_1_sphere9" />
    <origin rpy="0 0 0" xyz="-0.005261 -0.016 0.010867" />
    <axis xyz="0 0 1" />
    </joint>
  <link name="dip_1_sphere10" />
  <joint name="dip_1_joint_sphere10" type="fixed">
    <parent link="dip_1" />
    <child link="dip_1_sphere10" />
    <origin rpy="0 0 0" xyz="0.00553 -0.016 0.027371" />
    <axis xyz="0 0 1" />
    </joint>
  <link name="dip_1_sphere11" />
  <joint name="dip_1_joint_sphere11" type="fixed">
    <parent link="dip_1" />
    <child link="dip_1_sphere11" />
    <origin rpy="0 0 0" xyz="-0.004669 -0.016 0.028472" />
    <axis xyz="0 0 1" />
    </joint>
  <link name="dip_1_sphere12" />
  <joint name="dip_1_joint_sphere12" type="fixed">
    <parent link="dip_1" />
    <child link="dip_1_sphere12" />
    <origin rpy="0 0 0" xyz="0.003682 0.000155 0.03" />
    <axis xyz="0 0 1" />
    </joint>
  <link name="dip_1_sphere13" />
  <joint name="dip_1_joint_sphere13" type="fixed">
    <parent link="dip_1" />
    <child link="dip_1_sphere13" />
    <origin rpy="0 0 0" xyz="0.003682 0.000155 0.0" />
    <axis xyz="0 0 1" />
    </joint>
  <link name="dip_1_sphere14" />
  <joint name="dip_1_joint_sphere14" type="fixed">
    <parent link="dip_1" />
    <child link="dip_1_sphere14" />
    <origin rpy="0 0 0" xyz="0.00448 -0.016 0.000804" />
    <axis xyz="0 0 1" />
    </joint>
  <link name="dip_1_sphere15" />
  <joint name="dip_1_joint_sphere15" type="fixed">
    <parent link="dip_1" />
    <child link="dip_1_sphere15" />
    <origin rpy="0 0 0" xyz="0.004918 -0.016 0.007209" />
    <axis xyz="0 0 1" />
    </joint>
  <link name="dip_1_sphere16" />
  <joint name="dip_1_joint_sphere16" type="fixed">
    <parent link="dip_1" />
    <child link="dip_1_sphere16" />
    <origin rpy="0 0 0" xyz="-0.005632 -0.016 0.00212" />
    <axis xyz="0 0 1" />
    </joint>
  <link name="dip_1_sphere17" />
  <joint name="dip_1_joint_sphere17" type="fixed">
    <parent link="dip_1" />
    <child link="dip_1_sphere17" />
    <origin rpy="0 0 0" xyz="-0.003949 -0.009355 0.03" />
    <axis xyz="0 0 1" />
    </joint>
  <link name="dip_1_sphere18" />
  <joint name="dip_1_joint_sphere18" type="fixed">
    <parent link="dip_1" />
    <child link="dip_1_sphere18" />
    <origin rpy="0 0 0" xyz="-0.003949 -0.009355 0.0" />
    <axis xyz="0 0 1" />
    </joint>
  <link name="dip_1_sphere19" />
  <joint name="dip_1_joint_sphere19" type="fixed">
    <parent link="dip_1" />
    <child link="dip_1_sphere19" />
    <origin rpy="0 0 0" xyz="0.003189 -0.009964 0.03" />
    <axis xyz="0 0 1" />
    </joint>
  <link name="dip_1_sphere20" />
  <joint name="dip_1_joint_sphere20" type="fixed">
    <parent link="dip_1" />
    <child link="dip_1_sphere20" />
    <origin rpy="0 0 0" xyz="0.003189 -0.009964 0.0" />
    <axis xyz="0 0 1" />
    </joint>
  <link name="dip_1_sphere21" />
  <joint name="dip_1_joint_sphere21" type="fixed">
    <parent link="dip_1" />
    <child link="dip_1_sphere21" />
    <origin rpy="0 0 0" xyz="-0.003375 0.000846 0.03" />
    <axis xyz="0 0 1" />
    </joint>
  <link name="dip_1_sphere22" />
  <joint name="dip_1_joint_sphere22" type="fixed">
    <parent link="dip_1" />
    <child link="dip_1_sphere22" />
    <origin rpy="0 0 0" xyz="-0.003375 0.000846 0.0" />
    <axis xyz="0 0 1" />
    </joint>
  <link name="fingertip_1_sphere1" />
  <joint name="fingertip_1_joint_sphere1" type="fixed">
    <parent link="fingertip_1" />
    <child link="fingertip_1_sphere1" />
    <origin rpy="0 0 0" xyz="-0.000784 -0.032989 0.014514" />
    <axis xyz="0 0 1" />
    </joint>
  <link name="fingertip_1_sphere2" />
  <joint name="fingertip_1_joint_sphere2" type="fixed">
    <parent link="fingertip_1" />
    <child link="fingertip_1_sphere2" />
    <origin rpy="0 0 0" xyz="-0.006462 -0.017 0.008712" />
    <axis xyz="0 0 1" />
    </joint>
  <link name="fingertip_1_sphere3" />
  <joint name="fingertip_1_joint_sphere3" type="fixed">
    <parent link="fingertip_1" />
    <child link="fingertip_1_sphere3" />
    <origin rpy="0 0 0" xyz="0.006409 -0.017 0.021671" />
    <axis xyz="0 0 1" />
    </joint>
  <link name="fingertip_1_sphere4" />
  <joint name="fingertip_1_joint_sphere4" type="fixed">
    <parent link="fingertip_1" />
    <child link="fingertip_1_sphere4" />
    <origin rpy="0 0 0" xyz="0.003799 -0.017 0.006543" />
    <axis xyz="0 0 1" />
    </joint>
  <link name="fingertip_1_sphere5" />
  <joint name="fingertip_1_joint_sphere5" type="fixed">
    <parent link="fingertip_1" />
    <child link="fingertip_1_sphere5" />
    <origin rpy="0 0 0" xyz="-0.003787 -0.017 0.023887" />
    <axis xyz="0 0 1" />
    </joint>
  <link name="fingertip_1_sphere6" />
  <joint name="fingertip_1_joint_sphere6" type="fixed">
    <parent link="fingertip_1" />
    <child link="fingertip_1_sphere6" />
    <origin rpy="0 0 0" xyz="0.00382 -0.011789 0.03" />
    <axis xyz="0 0 1" />
    </joint>
  <link name="fingertip_1_sphere7" />
  <joint name="fingertip_1_joint_sphere7" type="fixed">
    <parent link="fingertip_1" />
    <child link="fingertip_1_sphere7" />
    <origin rpy="0 0 0" xyz="0.00382 -0.011789 -0.001" />
    <axis xyz="0 0 1" />
    </joint>
  <link name="fingertip_1_sphere8" />
  <joint name="fingertip_1_joint_sphere8" type="fixed">
    <parent link="fingertip_1" />
    <child link="fingertip_1_sphere8" />
    <origin rpy="0 0 0" xyz="0.004645 -0.000566 0.03" />
    <axis xyz="0 0 1" />
    </joint>
  <link name="fingertip_1_sphere9" />
  <joint name="fingertip_1_joint_sphere9" type="fixed">
    <parent link="fingertip_1" />
    <child link="fingertip_1_sphere9" />
    <origin rpy="0 0 0" xyz="0.004645 -0.000566 -0.001" />
    <axis xyz="0 0 1" />
    </joint>
  <link name="fingertip_1_sphere10" />
  <joint name="fingertip_1_joint_sphere10" type="fixed">
    <parent link="fingertip_1" />
    <child link="fingertip_1_sphere10" />
    <origin rpy="0 0 0" xyz="-0.001974 0.002389 0.03" />
    <axis xyz="0 0 1" />
    </joint>
  <link name="fingertip_1_sphere11" />
  <joint name="fingertip_1_joint_sphere11" type="fixed">
    <parent link="fingertip_1" />
    <child link="fingertip_1_sphere11" />
    <origin rpy="0 0 0" xyz="-0.001974 0.002389 -0.001" />
    <axis xyz="0 0 1" />
    </joint>
  <link name="fingertip_1_sphere12" />
  <joint name="fingertip_1_joint_sphere12" type="fixed">
    <parent link="fingertip_1" />
    <child link="fingertip_1_sphere12" />
    <origin rpy="0 0 0" xyz="-0.003256 -0.013027 0.03" />
    <axis xyz="0 0 1" />
    </joint>
  <link name="fingertip_1_sphere13" />
  <joint name="fingertip_1_joint_sphere13" type="fixed">
    <parent link="fingertip_1" />
    <child link="fingertip_1_sphere13" />
    <origin rpy="0 0 0" xyz="-0.003256 -0.013027 -0.001" />
    <axis xyz="0 0 1" />
    </joint>
  <link name="fingertip_1_sphere14" />
  <joint name="fingertip_1_joint_sphere14" type="fixed">
    <parent link="fingertip_1" />
    <child link="fingertip_1_sphere14" />
    <origin rpy="0 0 0" xyz="-0.003284 -0.004644 0.03" />
    <axis xyz="0 0 1" />
    </joint>
  <link name="fingertip_1_sphere15" />
  <joint name="fingertip_1_joint_sphere15" type="fixed">
    <parent link="fingertip_1" />
    <child link="fingertip_1_sphere15" />
    <origin rpy="0 0 0" xyz="-0.003284 -0.004644 -0.001" />
    <axis xyz="0 0 1" />
    </joint>
  <link name="mcp_joint_2_sphere1" />
  <joint name="mcp_joint_2_joint_sphere1" type="fixed">
    <parent link="mcp_joint_2" />
    <child link="mcp_joint_2_sphere1" />
    <origin rpy="0 0 0" xyz="-0.027001 0.031999 0.015" />
    <axis xyz="0 0 1" />
    </joint>
  <link name="mcp_joint_2_sphere2" />
  <joint name="mcp_joint_2_joint_sphere2" type="fixed">
    <parent link="mcp_joint_2" />
    <child link="mcp_joint_2_sphere2" />
    <origin rpy="0 0 0" xyz="-0.026999 0.052001 0.015" />
    <axis xyz="0 0 1" />
    </joint>
  <link name="mcp_joint_2_sphere3" />
  <joint name="mcp_joint_2_joint_sphere3" type="fixed">
    <parent link="mcp_joint_2" />
    <child link="mcp_joint_2_sphere3" />
    <origin rpy="0 0 0" xyz="-0.0295 0.042919 0.029" />
    <axis xyz="0 0 1" />
    </joint>
  <link name="mcp_joint_2_sphere4" />
  <joint name="mcp_joint_2_joint_sphere4" type="fixed">
    <parent link="mcp_joint_2" />
    <child link="mcp_joint_2_sphere4" />
    <origin rpy="0 0 0" xyz="-0.025257 0.030674 0.029" />
    <axis xyz="0 0 1" />
    </joint>
  <link name="mcp_joint_2_sphere5" />
  <joint name="mcp_joint_2_joint_sphere5" type="fixed">
    <parent link="mcp_joint_2" />
    <child link="mcp_joint_2_sphere5" />
    <origin rpy="0 0 0" xyz="-0.018096 0.02 0.007599" />
    <axis xyz="0 0 1" />
    </joint>
  <link name="mcp_joint_2_sphere6" />
  <joint name="mcp_joint_2_joint_sphere6" type="fixed">
    <parent link="mcp_joint_2" />
    <child link="mcp_joint_2_sphere6" />
    <origin rpy="0 0 0" xyz="-0.03524 0.02 0.009029" />
    <axis xyz="0 0 1" />
    </joint>
  <link name="mcp_joint_2_sphere7" />
  <joint name="mcp_joint_2_joint_sphere7" type="fixed">
    <parent link="mcp_joint_2" />
    <child link="mcp_joint_2_sphere7" />
    <origin rpy="0 0 0" xyz="0.006998 0.018 0.006286" />
    <axis xyz="0 0 1" />
    </joint>
  <link name="mcp_joint_2_sphere8" />
  <joint name="mcp_joint_2_joint_sphere8" type="fixed">
    <parent link="mcp_joint_2" />
    <child link="mcp_joint_2_sphere8" />
    <origin rpy="0 0 0" xyz="-0.035439 0.03067 0.029" />
    <axis xyz="0 0 1" />
    </joint>
  <link name="mcp_joint_2_sphere9" />
  <joint name="mcp_joint_2_joint_sphere9" type="fixed">
    <parent link="mcp_joint_2" />
    <child link="mcp_joint_2_sphere9" />
    <origin rpy="0 0 0" xyz="0.006494 0.018 0.023403" />
    <axis xyz="0 0 1" />
    </joint>
  <link name="mcp_joint_2_sphere10" />
  <joint name="mcp_joint_2_joint_sphere10" type="fixed">
    <parent link="mcp_joint_2" />
    <child link="mcp_joint_2_sphere10" />
    <origin rpy="0 0 0" xyz="-0.036193 0.02 0.019267" />
    <axis xyz="0 0 1" />
    </joint>
  <link name="mcp_joint_2_sphere11" />
  <joint name="mcp_joint_2_joint_sphere11" type="fixed">
    <parent link="mcp_joint_2" />
    <child link="mcp_joint_2_sphere11" />
    <origin rpy="0 0 0" xyz="-0.013073 0.02 0.016885" />
    <axis xyz="0 0 1" />
    </joint>
  <link name="mcp_joint_2_sphere12" />
  <joint name="mcp_joint_2_joint_sphere12" type="fixed">
    <parent link="mcp_joint_2" />
    <child link="mcp_joint_2_sphere12" />
    <origin rpy="0 0 0" xyz="-0.003105 0.018 0.002528" />
    <axis xyz="0 0 1" />
    </joint>
  <link name="mcp_joint_2_sphere13" />
  <joint name="mcp_joint_2_joint_sphere13" type="fixed">
    <parent link="mcp_joint_2" />
    <child link="mcp_joint_2_sphere13" />
    <origin rpy="0 0 0" xyz="-0.005154 0.017999 0.014529" />
    <axis xyz="0 0 1" />
    </joint>
  <link name="mcp_joint_2_sphere14" />
  <joint name="mcp_joint_2_joint_sphere14" type="fixed">
    <parent link="mcp_joint_2" />
    <child link="mcp_joint_2_sphere14" />
    <origin rpy="0 0 0" xyz="-0.02314 0.02 0.018738" />
    <axis xyz="0 0 1" />
    </joint>
  <link name="mcp_joint_2_sphere15" />
  <joint name="mcp_joint_2_joint_sphere15" type="fixed">
    <parent link="mcp_joint_2" />
    <child link="mcp_joint_2_sphere15" />
    <origin rpy="0 0 0" xyz="-0.003739 0.018 0.026747" />
    <axis xyz="0 0 1" />
    </joint>
  <link name="mcp_joint_2_sphere16" />
  <joint name="mcp_joint_2_joint_sphere16" type="fixed">
    <parent link="mcp_joint_2" />
    <child link="mcp_joint_2_sphere16" />
    <origin rpy="0 0 0" xyz="0.003682 0.009655 0.03" />
    <axis xyz="0 0 1" />
    </joint>
  <link name="mcp_joint_2_sphere17" />
  <joint name="mcp_joint_2_joint_sphere17" type="fixed">
    <parent link="mcp_joint_2" />
    <child link="mcp_joint_2_sphere17" />
    <origin rpy="0 0 0" xyz="0.003682 0.009655 -0.001" />
    <axis xyz="0 0 1" />
    </joint>
  <link name="mcp_joint_2_sphere18" />
  <joint name="mcp_joint_2_joint_sphere18" type="fixed">
    <parent link="mcp_joint_2" />
    <child link="mcp_joint_2_sphere18" />
    <origin rpy="0 0 0" xyz="-0.003949 0.000145 0.03" />
    <axis xyz="0 0 1" />
    </joint>
  <link name="mcp_joint_2_sphere19" />
  <joint name="mcp_joint_2_joint_sphere19" type="fixed">
    <parent link="mcp_joint_2" />
    <child link="mcp_joint_2_sphere19" />
    <origin rpy="0 0 0" xyz="-0.003949 0.000145 -0.001" />
    <axis xyz="0 0 1" />
    </joint>
  <link name="mcp_joint_2_sphere20" />
  <joint name="mcp_joint_2_joint_sphere20" type="fixed">
    <parent link="mcp_joint_2" />
    <child link="mcp_joint_2_sphere20" />
    <origin rpy="0 0 0" xyz="0.003189 -0.000464 0.03" />
    <axis xyz="0 0 1" />
    </joint>
  <link name="mcp_joint_2_sphere21" />
  <joint name="mcp_joint_2_joint_sphere21" type="fixed">
    <parent link="mcp_joint_2" />
    <child link="mcp_joint_2_sphere21" />
    <origin rpy="0 0 0" xyz="0.003189 -0.000464 -0.001" />
    <axis xyz="0 0 1" />
    </joint>
  <link name="mcp_joint_2_sphere22" />
  <joint name="mcp_joint_2_joint_sphere22" type="fixed">
    <parent link="mcp_joint_2" />
    <child link="mcp_joint_2_sphere22" />
    <origin rpy="0 0 0" xyz="-0.003375 0.010346 0.03" />
    <axis xyz="0 0 1" />
    </joint>
  <link name="mcp_joint_2_sphere23" />
  <joint name="mcp_joint_2_joint_sphere23" type="fixed">
    <parent link="mcp_joint_2" />
    <child link="mcp_joint_2_sphere23" />
    <origin rpy="0 0 0" xyz="-0.003375 0.010346 -0.001" />
    <axis xyz="0 0 1" />
    </joint>
  <link name="pip_2_sphere1" />
  <joint name="pip_2_joint_sphere1" type="fixed">
    <parent link="pip_2" />
    <child link="pip_2_sphere1" />
    <origin rpy="0 0 0" xyz="0.001501 -0.0002 -0.011" />
    <axis xyz="0 0 1" />
    </joint>
  <link name="pip_2_sphere2" />
  <joint name="pip_2_joint_sphere2" type="fixed">
    <parent link="pip_2" />
    <child link="pip_2_sphere2" />
    <origin rpy="0 0 0" xyz="0.013501 -0.0002 -0.010999" />
    <axis xyz="0 0 1" />
    </joint>
  <link name="dip_2_sphere1" />
  <joint name="dip_2_joint_sphere1" type="fixed">
    <parent link="dip_2" />
    <child link="dip_2_sphere1" />
    <origin rpy="0 0 0" xyz="0.0015 -0.035001 0.015" />
    <axis xyz="0 0 1" />
    </joint>
  <link name="dip_2_sphere2" />
  <joint name="dip_2_joint_sphere2" type="fixed">
    <parent link="dip_2" />
    <child link="dip_2_sphere2" />
    <origin rpy="0 0 0" xyz="0.0135 -0.035 0.014999" />
    <axis xyz="0 0 1" />
    </joint>
  <link name="dip_2_sphere3" />
  <joint name="dip_2_joint_sphere3" type="fixed">
    <parent link="dip_2" />
    <child link="dip_2_sphere3" />
    <origin rpy="0 0 0" xyz="-0.004874 -0.02 0.009187" />
    <axis xyz="0 0 1" />
    </joint>
  <link name="dip_2_sphere4" />
  <joint name="dip_2_joint_sphere4" type="fixed">
    <parent link="dip_2" />
    <child link="dip_2_sphere4" />
    <origin rpy="0 0 0" xyz="0.004477 -0.02 0.021215" />
    <axis xyz="0 0 1" />
    </joint>
  <link name="dip_2_sphere5" />
  <joint name="dip_2_joint_sphere5" type="fixed">
    <parent link="dip_2" />
    <child link="dip_2_sphere5" />
    <origin rpy="0 0 0" xyz="0.003347 -0.02 0.007914" />
    <axis xyz="0 0 1" />
    </joint>
  <link name="dip_2_sphere6" />
  <joint name="dip_2_joint_sphere6" type="fixed">
    <parent link="dip_2" />
    <child link="dip_2_sphere6" />
    <origin rpy="0 0 0" xyz="-0.003656 -0.02 0.022271" />
    <axis xyz="0 0 1" />
    </joint>
  <link name="dip_2_sphere7" />
  <joint name="dip_2_joint_sphere7" type="fixed">
    <parent link="dip_2" />
    <child link="dip_2_sphere7" />
    <origin rpy="0 0 0" xyz="0.006365 -0.016 0.017072" />
    <axis xyz="0 0 1" />
    </joint>
  <link name="dip_2_sphere8" />
  <joint name="dip_2_joint_sphere8" type="fixed">
    <parent link="dip_2" />
    <child link="dip_2_sphere8" />
    <origin rpy="0 0 0" xyz="-0.005092 -0.016 0.020145" />
    <axis xyz="0 0 1" />
    </joint>
  <link name="dip_2_sphere9" />
  <joint name="dip_2_joint_sphere9" type="fixed">
    <parent link="dip_2" />
    <child link="dip_2_sphere9" />
    <origin rpy="0 0 0" xyz="-0.005261 -0.016 0.010867" />
    <axis xyz="0 0 1" />
    </joint>
  <link name="dip_2_sphere10" />
  <joint name="dip_2_joint_sphere10" type="fixed">
    <parent link="dip_2" />
    <child link="dip_2_sphere10" />
    <origin rpy="0 0 0" xyz="0.00553 -0.016 0.027371" />
    <axis xyz="0 0 1" />
    </joint>
  <link name="dip_2_sphere11" />
  <joint name="dip_2_joint_sphere11" type="fixed">
    <parent link="dip_2" />
    <child link="dip_2_sphere11" />
    <origin rpy="0 0 0" xyz="-0.004669 -0.016 0.028472" />
    <axis xyz="0 0 1" />
    </joint>
  <link name="dip_2_sphere12" />
  <joint name="dip_2_joint_sphere12" type="fixed">
    <parent link="dip_2" />
    <child link="dip_2_sphere12" />
    <origin rpy="0 0 0" xyz="0.003682 0.000155 0.03" />
    <axis xyz="0 0 1" />
    </joint>
  <link name="dip_2_sphere13" />
  <joint name="dip_2_joint_sphere13" type="fixed">
    <parent link="dip_2" />
    <child link="dip_2_sphere13" />
    <origin rpy="0 0 0" xyz="0.003682 0.000155 0.0" />
    <axis xyz="0 0 1" />
    </joint>
  <link name="dip_2_sphere14" />
  <joint name="dip_2_joint_sphere14" type="fixed">
    <parent link="dip_2" />
    <child link="dip_2_sphere14" />
    <origin rpy="0 0 0" xyz="0.00448 -0.016 0.000804" />
    <axis xyz="0 0 1" />
    </joint>
  <link name="dip_2_sphere15" />
  <joint name="dip_2_joint_sphere15" type="fixed">
    <parent link="dip_2" />
    <child link="dip_2_sphere15" />
    <origin rpy="0 0 0" xyz="0.004918 -0.016 0.007209" />
    <axis xyz="0 0 1" />
    </joint>
  <link name="dip_2_sphere16" />
  <joint name="dip_2_joint_sphere16" type="fixed">
    <parent link="dip_2" />
    <child link="dip_2_sphere16" />
    <origin rpy="0 0 0" xyz="-0.005632 -0.016 0.00212" />
    <axis xyz="0 0 1" />
    </joint>
  <link name="dip_2_sphere17" />
  <joint name="dip_2_joint_sphere17" type="fixed">
    <parent link="dip_2" />
    <child link="dip_2_sphere17" />
    <origin rpy="0 0 0" xyz="-0.003949 -0.009355 0.03" />
    <axis xyz="0 0 1" />
    </joint>
  <link name="dip_2_sphere18" />
  <joint name="dip_2_joint_sphere18" type="fixed">
    <parent link="dip_2" />
    <child link="dip_2_sphere18" />
    <origin rpy="0 0 0" xyz="-0.003949 -0.009355 0.0" />
    <axis xyz="0 0 1" />
    </joint>
  <link name="dip_2_sphere19" />
  <joint name="dip_2_joint_sphere19" type="fixed">
    <parent link="dip_2" />
    <child link="dip_2_sphere19" />
    <origin rpy="0 0 0" xyz="0.003189 -0.009964 0.03" />
    <axis xyz="0 0 1" />
    </joint>
  <link name="dip_2_sphere20" />
  <joint name="dip_2_joint_sphere20" type="fixed">
    <parent link="dip_2" />
    <child link="dip_2_sphere20" />
    <origin rpy="0 0 0" xyz="0.003189 -0.009964 0.0" />
    <axis xyz="0 0 1" />
    </joint>
  <link name="dip_2_sphere21" />
  <joint name="dip_2_joint_sphere21" type="fixed">
    <parent link="dip_2" />
    <child link="dip_2_sphere21" />
    <origin rpy="0 0 0" xyz="-0.003375 0.000846 0.03" />
    <axis xyz="0 0 1" />
    </joint>
  <link name="dip_2_sphere22" />
  <joint name="dip_2_joint_sphere22" type="fixed">
    <parent link="dip_2" />
    <child link="dip_2_sphere22" />
    <origin rpy="0 0 0" xyz="-0.003375 0.000846 0.0" />
    <axis xyz="0 0 1" />
    </joint>
  <link name="fingertip_2_sphere1" />
  <joint name="fingertip_2_joint_sphere1" type="fixed">
    <parent link="fingertip_2" />
    <child link="fingertip_2_sphere1" />
    <origin rpy="0 0 0" xyz="-0.000784 -0.032989 0.014514" />
    <axis xyz="0 0 1" />
    </joint>
  <link name="fingertip_2_sphere2" />
  <joint name="fingertip_2_joint_sphere2" type="fixed">
    <parent link="fingertip_2" />
    <child link="fingertip_2_sphere2" />
    <origin rpy="0 0 0" xyz="-0.006462 -0.017 0.008712" />
    <axis xyz="0 0 1" />
    </joint>
  <link name="fingertip_2_sphere3" />
  <joint name="fingertip_2_joint_sphere3" type="fixed">
    <parent link="fingertip_2" />
    <child link="fingertip_2_sphere3" />
    <origin rpy="0 0 0" xyz="0.006409 -0.017 0.021671" />
    <axis xyz="0 0 1" />
    </joint>
  <link name="fingertip_2_sphere4" />
  <joint name="fingertip_2_joint_sphere4" type="fixed">
    <parent link="fingertip_2" />
    <child link="fingertip_2_sphere4" />
    <origin rpy="0 0 0" xyz="0.003799 -0.017 0.006543" />
    <axis xyz="0 0 1" />
    </joint>
  <link name="fingertip_2_sphere5" />
  <joint name="fingertip_2_joint_sphere5" type="fixed">
    <parent link="fingertip_2" />
    <child link="fingertip_2_sphere5" />
    <origin rpy="0 0 0" xyz="-0.003787 -0.017 0.023887" />
    <axis xyz="0 0 1" />
    </joint>
  <link name="fingertip_2_sphere6" />
  <joint name="fingertip_2_joint_sphere6" type="fixed">
    <parent link="fingertip_2" />
    <child link="fingertip_2_sphere6" />
    <origin rpy="0 0 0" xyz="0.00382 -0.011789 0.03" />
    <axis xyz="0 0 1" />
    </joint>
  <link name="fingertip_2_sphere7" />
  <joint name="fingertip_2_joint_sphere7" type="fixed">
    <parent link="fingertip_2" />
    <child link="fingertip_2_sphere7" />
    <origin rpy="0 0 0" xyz="0.00382 -0.011789 -0.001" />
    <axis xyz="0 0 1" />
    </joint>
  <link name="fingertip_2_sphere8" />
  <joint name="fingertip_2_joint_sphere8" type="fixed">
    <parent link="fingertip_2" />
    <child link="fingertip_2_sphere8" />
    <origin rpy="0 0 0" xyz="0.004645 -0.000566 0.03" />
    <axis xyz="0 0 1" />
    </joint>
  <link name="fingertip_2_sphere9" />
  <joint name="fingertip_2_joint_sphere9" type="fixed">
    <parent link="fingertip_2" />
    <child link="fingertip_2_sphere9" />
    <origin rpy="0 0 0" xyz="0.004645 -0.000566 -0.001" />
    <axis xyz="0 0 1" />
    </joint>
  <link name="fingertip_2_sphere10" />
  <joint name="fingertip_2_joint_sphere10" type="fixed">
    <parent link="fingertip_2" />
    <child link="fingertip_2_sphere10" />
    <origin rpy="0 0 0" xyz="-0.001974 0.002389 0.03" />
    <axis xyz="0 0 1" />
    </joint>
  <link name="fingertip_2_sphere11" />
  <joint name="fingertip_2_joint_sphere11" type="fixed">
    <parent link="fingertip_2" />
    <child link="fingertip_2_sphere11" />
    <origin rpy="0 0 0" xyz="-0.001974 0.002389 -0.001" />
    <axis xyz="0 0 1" />
    </joint>
  <link name="fingertip_2_sphere12" />
  <joint name="fingertip_2_joint_sphere12" type="fixed">
    <parent link="fingertip_2" />
    <child link="fingertip_2_sphere12" />
    <origin rpy="0 0 0" xyz="-0.003256 -0.013027 0.03" />
    <axis xyz="0 0 1" />
    </joint>
  <link name="fingertip_2_sphere13" />
  <joint name="fingertip_2_joint_sphere13" type="fixed">
    <parent link="fingertip_2" />
    <child link="fingertip_2_sphere13" />
    <origin rpy="0 0 0" xyz="-0.003256 -0.013027 -0.001" />
    <axis xyz="0 0 1" />
    </joint>
  <link name="fingertip_2_sphere14" />
  <joint name="fingertip_2_joint_sphere14" type="fixed">
    <parent link="fingertip_2" />
    <child link="fingertip_2_sphere14" />
    <origin rpy="0 0 0" xyz="-0.003284 -0.004644 0.03" />
    <axis xyz="0 0 1" />
    </joint>
  <link name="fingertip_2_sphere15" />
  <joint name="fingertip_2_joint_sphere15" type="fixed">
    <parent link="fingertip_2" />
    <child link="fingertip_2_sphere15" />
    <origin rpy="0 0 0" xyz="-0.003284 -0.004644 -0.001" />
    <axis xyz="0 0 1" />
    </joint>
  <link name="mcp_joint_3_sphere1" />
  <joint name="mcp_joint_3_joint_sphere1" type="fixed">
    <parent link="mcp_joint_3" />
    <child link="mcp_joint_3_sphere1" />
    <origin rpy="0 0 0" xyz="-0.027001 0.031999 0.015" />
    <axis xyz="0 0 1" />
    </joint>
  <link name="mcp_joint_3_sphere2" />
  <joint name="mcp_joint_3_joint_sphere2" type="fixed">
    <parent link="mcp_joint_3" />
    <child link="mcp_joint_3_sphere2" />
    <origin rpy="0 0 0" xyz="-0.026999 0.052001 0.015" />
    <axis xyz="0 0 1" />
    </joint>
  <link name="mcp_joint_3_sphere3" />
  <joint name="mcp_joint_3_joint_sphere3" type="fixed">
    <parent link="mcp_joint_3" />
    <child link="mcp_joint_3_sphere3" />
    <origin rpy="0 0 0" xyz="-0.0295 0.042919 0.029" />
    <axis xyz="0 0 1" />
    </joint>
  <link name="mcp_joint_3_sphere4" />
  <joint name="mcp_joint_3_joint_sphere4" type="fixed">
    <parent link="mcp_joint_3" />
    <child link="mcp_joint_3_sphere4" />
    <origin rpy="0 0 0" xyz="-0.025257 0.030674 0.029" />
    <axis xyz="0 0 1" />
    </joint>
  <link name="mcp_joint_3_sphere5" />
  <joint name="mcp_joint_3_joint_sphere5" type="fixed">
    <parent link="mcp_joint_3" />
    <child link="mcp_joint_3_sphere5" />
    <origin rpy="0 0 0" xyz="-0.018096 0.02 0.007599" />
    <axis xyz="0 0 1" />
    </joint>
  <link name="mcp_joint_3_sphere6" />
  <joint name="mcp_joint_3_joint_sphere6" type="fixed">
    <parent link="mcp_joint_3" />
    <child link="mcp_joint_3_sphere6" />
    <origin rpy="0 0 0" xyz="-0.03524 0.02 0.009029" />
    <axis xyz="0 0 1" />
    </joint>
  <link name="mcp_joint_3_sphere7" />
  <joint name="mcp_joint_3_joint_sphere7" type="fixed">
    <parent link="mcp_joint_3" />
    <child link="mcp_joint_3_sphere7" />
    <origin rpy="0 0 0" xyz="0.006998 0.018 0.006286" />
    <axis xyz="0 0 1" />
    </joint>
  <link name="mcp_joint_3_sphere8" />
  <joint name="mcp_joint_3_joint_sphere8" type="fixed">
    <parent link="mcp_joint_3" />
    <child link="mcp_joint_3_sphere8" />
    <origin rpy="0 0 0" xyz="-0.035439 0.03067 0.029" />
    <axis xyz="0 0 1" />
    </joint>
  <link name="mcp_joint_3_sphere9" />
  <joint name="mcp_joint_3_joint_sphere9" type="fixed">
    <parent link="mcp_joint_3" />
    <child link="mcp_joint_3_sphere9" />
    <origin rpy="0 0 0" xyz="0.006494 0.018 0.023403" />
    <axis xyz="0 0 1" />
    </joint>
  <link name="mcp_joint_3_sphere10" />
  <joint name="mcp_joint_3_joint_sphere10" type="fixed">
    <parent link="mcp_joint_3" />
    <child link="mcp_joint_3_sphere10" />
    <origin rpy="0 0 0" xyz="-0.036193 0.02 0.019267" />
    <axis xyz="0 0 1" />
    </joint>
  <link name="mcp_joint_3_sphere11" />
  <joint name="mcp_joint_3_joint_sphere11" type="fixed">
    <parent link="mcp_joint_3" />
    <child link="mcp_joint_3_sphere11" />
    <origin rpy="0 0 0" xyz="-0.013073 0.02 0.016885" />
    <axis xyz="0 0 1" />
    </joint>
  <link name="mcp_joint_3_sphere12" />
  <joint name="mcp_joint_3_joint_sphere12" type="fixed">
    <parent link="mcp_joint_3" />
    <child link="mcp_joint_3_sphere12" />
    <origin rpy="0 0 0" xyz="-0.003105 0.018 0.002528" />
    <axis xyz="0 0 1" />
    </joint>
  <link name="mcp_joint_3_sphere13" />
  <joint name="mcp_joint_3_joint_sphere13" type="fixed">
    <parent link="mcp_joint_3" />
    <child link="mcp_joint_3_sphere13" />
    <origin rpy="0 0 0" xyz="-0.005154 0.017999 0.014529" />
    <axis xyz="0 0 1" />
    </joint>
  <link name="mcp_joint_3_sphere14" />
  <joint name="mcp_joint_3_joint_sphere14" type="fixed">
    <parent link="mcp_joint_3" />
    <child link="mcp_joint_3_sphere14" />
    <origin rpy="0 0 0" xyz="-0.02314 0.02 0.018738" />
    <axis xyz="0 0 1" />
    </joint>
  <link name="mcp_joint_3_sphere15" />
  <joint name="mcp_joint_3_joint_sphere15" type="fixed">
    <parent link="mcp_joint_3" />
    <child link="mcp_joint_3_sphere15" />
    <origin rpy="0 0 0" xyz="-0.003739 0.018 0.026747" />
    <axis xyz="0 0 1" />
    </joint>
  <link name="mcp_joint_3_sphere16" />
  <joint name="mcp_joint_3_joint_sphere16" type="fixed">
    <parent link="mcp_joint_3" />
    <child link="mcp_joint_3_sphere16" />
    <origin rpy="0 0 0" xyz="0.003682 0.009655 0.03" />
    <axis xyz="0 0 1" />
    </joint>
  <link name="mcp_joint_3_sphere17" />
  <joint name="mcp_joint_3_joint_sphere17" type="fixed">
    <parent link="mcp_joint_3" />
    <child link="mcp_joint_3_sphere17" />
    <origin rpy="0 0 0" xyz="0.003682 0.009655 -0.001" />
    <axis xyz="0 0 1" />
    </joint>
  <link name="mcp_joint_3_sphere18" />
  <joint name="mcp_joint_3_joint_sphere18" type="fixed">
    <parent link="mcp_joint_3" />
    <child link="mcp_joint_3_sphere18" />
    <origin rpy="0 0 0" xyz="-0.003949 0.000145 0.03" />
    <axis xyz="0 0 1" />
    </joint>
  <link name="mcp_joint_3_sphere19" />
  <joint name="mcp_joint_3_joint_sphere19" type="fixed">
    <parent link="mcp_joint_3" />
    <child link="mcp_joint_3_sphere19" />
    <origin rpy="0 0 0" xyz="-0.003949 0.000145 -0.001" />
    <axis xyz="0 0 1" />
    </joint>
  <link name="mcp_joint_3_sphere20" />
  <joint name="mcp_joint_3_joint_sphere20" type="fixed">
    <parent link="mcp_joint_3" />
    <child link="mcp_joint_3_sphere20" />
    <origin rpy="0 0 0" xyz="0.003189 -0.000464 0.03" />
    <axis xyz="0 0 1" />
    </joint>
  <link name="mcp_joint_3_sphere21" />
  <joint name="mcp_joint_3_joint_sphere21" type="fixed">
    <parent link="mcp_joint_3" />
    <child link="mcp_joint_3_sphere21" />
    <origin rpy="0 0 0" xyz="0.003189 -0.000464 -0.001" />
    <axis xyz="0 0 1" />
    </joint>
  <link name="mcp_joint_3_sphere22" />
  <joint name="mcp_joint_3_joint_sphere22" type="fixed">
    <parent link="mcp_joint_3" />
    <child link="mcp_joint_3_sphere22" />
    <origin rpy="0 0 0" xyz="-0.003375 0.010346 0.03" />
    <axis xyz="0 0 1" />
    </joint>
  <link name="mcp_joint_3_sphere23" />
  <joint name="mcp_joint_3_joint_sphere23" type="fixed">
    <parent link="mcp_joint_3" />
    <child link="mcp_joint_3_sphere23" />
    <origin rpy="0 0 0" xyz="-0.003375 0.010346 -0.001" />
    <axis xyz="0 0 1" />
    </joint>
  <link name="pip_3_sphere1" />
  <joint name="pip_3_joint_sphere1" type="fixed">
    <parent link="pip_3" />
    <child link="pip_3_sphere1" />
    <origin rpy="0 0 0" xyz="0.001501 -0.0002 -0.011" />
    <axis xyz="0 0 1" />
    </joint>
  <link name="pip_3_sphere2" />
  <joint name="pip_3_joint_sphere2" type="fixed">
    <parent link="pip_3" />
    <child link="pip_3_sphere2" />
    <origin rpy="0 0 0" xyz="0.013501 -0.0002 -0.010999" />
    <axis xyz="0 0 1" />
    </joint>
  <link name="dip_3_sphere1" />
  <joint name="dip_3_joint_sphere1" type="fixed">
    <parent link="dip_3" />
    <child link="dip_3_sphere1" />
    <origin rpy="0 0 0" xyz="0.0015 -0.035001 0.015" />
    <axis xyz="0 0 1" />
    </joint>
  <link name="dip_3_sphere2" />
  <joint name="dip_3_joint_sphere2" type="fixed">
    <parent link="dip_3" />
    <child link="dip_3_sphere2" />
    <origin rpy="0 0 0" xyz="0.0135 -0.035 0.014999" />
    <axis xyz="0 0 1" />
    </joint>
  <link name="dip_3_sphere3" />
  <joint name="dip_3_joint_sphere3" type="fixed">
    <parent link="dip_3" />
    <child link="dip_3_sphere3" />
    <origin rpy="0 0 0" xyz="-0.004874 -0.02 0.009187" />
    <axis xyz="0 0 1" />
    </joint>
  <link name="dip_3_sphere4" />
  <joint name="dip_3_joint_sphere4" type="fixed">
    <parent link="dip_3" />
    <child link="dip_3_sphere4" />
    <origin rpy="0 0 0" xyz="0.004477 -0.02 0.021215" />
    <axis xyz="0 0 1" />
    </joint>
  <link name="dip_3_sphere5" />
  <joint name="dip_3_joint_sphere5" type="fixed">
    <parent link="dip_3" />
    <child link="dip_3_sphere5" />
    <origin rpy="0 0 0" xyz="0.003347 -0.02 0.007914" />
    <axis xyz="0 0 1" />
    </joint>
  <link name="dip_3_sphere6" />
  <joint name="dip_3_joint_sphere6" type="fixed">
    <parent link="dip_3" />
    <child link="dip_3_sphere6" />
    <origin rpy="0 0 0" xyz="-0.003656 -0.02 0.022271" />
    <axis xyz="0 0 1" />
    </joint>
  <link name="dip_3_sphere7" />
  <joint name="dip_3_joint_sphere7" type="fixed">
    <parent link="dip_3" />
    <child link="dip_3_sphere7" />
    <origin rpy="0 0 0" xyz="0.006365 -0.016 0.017072" />
    <axis xyz="0 0 1" />
    </joint>
  <link name="dip_3_sphere8" />
  <joint name="dip_3_joint_sphere8" type="fixed">
    <parent link="dip_3" />
    <child link="dip_3_sphere8" />
    <origin rpy="0 0 0" xyz="-0.005092 -0.016 0.020145" />
    <axis xyz="0 0 1" />
    </joint>
  <link name="dip_3_sphere9" />
  <joint name="dip_3_joint_sphere9" type="fixed">
    <parent link="dip_3" />
    <child link="dip_3_sphere9" />
    <origin rpy="0 0 0" xyz="-0.005261 -0.016 0.010867" />
    <axis xyz="0 0 1" />
    </joint>
  <link name="dip_3_sphere10" />
  <joint name="dip_3_joint_sphere10" type="fixed">
    <parent link="dip_3" />
    <child link="dip_3_sphere10" />
    <origin rpy="0 0 0" xyz="0.00553 -0.016 0.027371" />
    <axis xyz="0 0 1" />
    </joint>
  <link name="dip_3_sphere11" />
  <joint name="dip_3_joint_sphere11" type="fixed">
    <parent link="dip_3" />
    <child link="dip_3_sphere11" />
    <origin rpy="0 0 0" xyz="-0.004669 -0.016 0.028472" />
    <axis xyz="0 0 1" />
    </joint>
  <link name="dip_3_sphere12" />
  <joint name="dip_3_joint_sphere12" type="fixed">
    <parent link="dip_3" />
    <child link="dip_3_sphere12" />
    <origin rpy="0 0 0" xyz="0.003682 0.000155 0.03" />
    <axis xyz="0 0 1" />
    </joint>
  <link name="dip_3_sphere13" />
  <joint name="dip_3_joint_sphere13" type="fixed">
    <parent link="dip_3" />
    <child link="dip_3_sphere13" />
    <origin rpy="0 0 0" xyz="0.003682 0.000155 0.0" />
    <axis xyz="0 0 1" />
    </joint>
  <link name="dip_3_sphere14" />
  <joint name="dip_3_joint_sphere14" type="fixed">
    <parent link="dip_3" />
    <child link="dip_3_sphere14" />
    <origin rpy="0 0 0" xyz="0.00448 -0.016 0.000804" />
    <axis xyz="0 0 1" />
    </joint>
  <link name="dip_3_sphere15" />
  <joint name="dip_3_joint_sphere15" type="fixed">
    <parent link="dip_3" />
    <child link="dip_3_sphere15" />
    <origin rpy="0 0 0" xyz="0.004918 -0.016 0.007209" />
    <axis xyz="0 0 1" />
    </joint>
  <link name="dip_3_sphere16" />
  <joint name="dip_3_joint_sphere16" type="fixed">
    <parent link="dip_3" />
    <child link="dip_3_sphere16" />
    <origin rpy="0 0 0" xyz="-0.005632 -0.016 0.00212" />
    <axis xyz="0 0 1" />
    </joint>
  <link name="dip_3_sphere17" />
  <joint name="dip_3_joint_sphere17" type="fixed">
    <parent link="dip_3" />
    <child link="dip_3_sphere17" />
    <origin rpy="0 0 0" xyz="-0.003949 -0.009355 0.03" />
    <axis xyz="0 0 1" />
    </joint>
  <link name="dip_3_sphere18" />
  <joint name="dip_3_joint_sphere18" type="fixed">
    <parent link="dip_3" />
    <child link="dip_3_sphere18" />
    <origin rpy="0 0 0" xyz="-0.003949 -0.009355 0.0" />
    <axis xyz="0 0 1" />
    </joint>
  <link name="dip_3_sphere19" />
  <joint name="dip_3_joint_sphere19" type="fixed">
    <parent link="dip_3" />
    <child link="dip_3_sphere19" />
    <origin rpy="0 0 0" xyz="0.003189 -0.009964 0.03" />
    <axis xyz="0 0 1" />
    </joint>
  <link name="dip_3_sphere20" />
  <joint name="dip_3_joint_sphere20" type="fixed">
    <parent link="dip_3" />
    <child link="dip_3_sphere20" />
    <origin rpy="0 0 0" xyz="0.003189 -0.009964 0.0" />
    <axis xyz="0 0 1" />
    </joint>
  <link name="dip_3_sphere21" />
  <joint name="dip_3_joint_sphere21" type="fixed">
    <parent link="dip_3" />
    <child link="dip_3_sphere21" />
    <origin rpy="0 0 0" xyz="-0.003375 0.000846 0.03" />
    <axis xyz="0 0 1" />
    </joint>
  <link name="dip_3_sphere22" />
  <joint name="dip_3_joint_sphere22" type="fixed">
    <parent link="dip_3" />
    <child link="dip_3_sphere22" />
    <origin rpy="0 0 0" xyz="-0.003375 0.000846 0.0" />
    <axis xyz="0 0 1" />
    </joint>
  <link name="fingertip_3_sphere1" />
  <joint name="fingertip_3_joint_sphere1" type="fixed">
    <parent link="fingertip_3" />
    <child link="fingertip_3_sphere1" />
    <origin rpy="0 0 0" xyz="-0.000784 -0.032989 0.014514" />
    <axis xyz="0 0 1" />
    </joint>
  <link name="fingertip_3_sphere2" />
  <joint name="fingertip_3_joint_sphere2" type="fixed">
    <parent link="fingertip_3" />
    <child link="fingertip_3_sphere2" />
    <origin rpy="0 0 0" xyz="-0.006462 -0.017 0.008712" />
    <axis xyz="0 0 1" />
    </joint>
  <link name="fingertip_3_sphere3" />
  <joint name="fingertip_3_joint_sphere3" type="fixed">
    <parent link="fingertip_3" />
    <child link="fingertip_3_sphere3" />
    <origin rpy="0 0 0" xyz="0.006409 -0.017 0.021671" />
    <axis xyz="0 0 1" />
    </joint>
  <link name="fingertip_3_sphere4" />
  <joint name="fingertip_3_joint_sphere4" type="fixed">
    <parent link="fingertip_3" />
    <child link="fingertip_3_sphere4" />
    <origin rpy="0 0 0" xyz="0.003799 -0.017 0.006543" />
    <axis xyz="0 0 1" />
    </joint>
  <link name="fingertip_3_sphere5" />
  <joint name="fingertip_3_joint_sphere5" type="fixed">
    <parent link="fingertip_3" />
    <child link="fingertip_3_sphere5" />
    <origin rpy="0 0 0" xyz="-0.003787 -0.017 0.023887" />
    <axis xyz="0 0 1" />
    </joint>
  <link name="fingertip_3_sphere6" />
  <joint name="fingertip_3_joint_sphere6" type="fixed">
    <parent link="fingertip_3" />
    <child link="fingertip_3_sphere6" />
    <origin rpy="0 0 0" xyz="0.00382 -0.011789 0.03" />
    <axis xyz="0 0 1" />
    </joint>
  <link name="fingertip_3_sphere7" />
  <joint name="fingertip_3_joint_sphere7" type="fixed">
    <parent link="fingertip_3" />
    <child link="fingertip_3_sphere7" />
    <origin rpy="0 0 0" xyz="0.00382 -0.011789 -0.001" />
    <axis xyz="0 0 1" />
    </joint>
  <link name="fingertip_3_sphere8" />
  <joint name="fingertip_3_joint_sphere8" type="fixed">
    <parent link="fingertip_3" />
    <child link="fingertip_3_sphere8" />
    <origin rpy="0 0 0" xyz="0.004645 -0.000566 0.03" />
    <axis xyz="0 0 1" />
    </joint>
  <link name="fingertip_3_sphere9" />
  <joint name="fingertip_3_joint_sphere9" type="fixed">
    <parent link="fingertip_3" />
    <child link="fingertip_3_sphere9" />
    <origin rpy="0 0 0" xyz="0.004645 -0.000566 -0.001" />
    <axis xyz="0 0 1" />
    </joint>
  <link name="fingertip_3_sphere10" />
  <joint name="fingertip_3_joint_sphere10" type="fixed">
    <parent link="fingertip_3" />
    <child link="fingertip_3_sphere10" />
    <origin rpy="0 0 0" xyz="-0.001974 0.002389 0.03" />
    <axis xyz="0 0 1" />
    </joint>
  <link name="fingertip_3_sphere11" />
  <joint name="fingertip_3_joint_sphere11" type="fixed">
    <parent link="fingertip_3" />
    <child link="fingertip_3_sphere11" />
    <origin rpy="0 0 0" xyz="-0.001974 0.002389 -0.001" />
    <axis xyz="0 0 1" />
    </joint>
  <link name="fingertip_3_sphere12" />
  <joint name="fingertip_3_joint_sphere12" type="fixed">
    <parent link="fingertip_3" />
    <child link="fingertip_3_sphere12" />
    <origin rpy="0 0 0" xyz="-0.003256 -0.013027 0.03" />
    <axis xyz="0 0 1" />
    </joint>
  <link name="fingertip_3_sphere13" />
  <joint name="fingertip_3_joint_sphere13" type="fixed">
    <parent link="fingertip_3" />
    <child link="fingertip_3_sphere13" />
    <origin rpy="0 0 0" xyz="-0.003256 -0.013027 -0.001" />
    <axis xyz="0 0 1" />
    </joint>
  <link name="fingertip_3_sphere14" />
  <joint name="fingertip_3_joint_sphere14" type="fixed">
    <parent link="fingertip_3" />
    <child link="fingertip_3_sphere14" />
    <origin rpy="0 0 0" xyz="-0.003284 -0.004644 0.03" />
    <axis xyz="0 0 1" />
    </joint>
  <link name="fingertip_3_sphere15" />
  <joint name="fingertip_3_joint_sphere15" type="fixed">
    <parent link="fingertip_3" />
    <child link="fingertip_3_sphere15" />
    <origin rpy="0 0 0" xyz="-0.003284 -0.004644 -0.001" />
    <axis xyz="0 0 1" />
    </joint>
  <link name="pip_4_sphere1" />
  <joint name="pip_4_joint_sphere1" type="fixed">
    <parent link="pip_4" />
    <child link="pip_4_sphere1" />
    <origin rpy="0 0 0" xyz="0.001501 -0.0002 -0.011" />
    <axis xyz="0 0 1" />
    </joint>
  <link name="pip_4_sphere2" />
  <joint name="pip_4_joint_sphere2" type="fixed">
    <parent link="pip_4" />
    <child link="pip_4_sphere2" />
    <origin rpy="0 0 0" xyz="0.013501 -0.0002 -0.010999" />
    <axis xyz="0 0 1" />
    </joint>
  <link name="thumb_pip_sphere1" />
  <joint name="thumb_pip_joint_sphere1" type="fixed">
    <parent link="thumb_pip" />
    <child link="thumb_pip_sphere1" />
    <origin rpy="0 0 0" xyz="0.002056 -0.015 -0.007151" />
    <axis xyz="0 0 1" />
    </joint>
  <link name="thumb_pip_sphere2" />
  <joint name="thumb_pip_joint_sphere2" type="fixed">
    <parent link="thumb_pip" />
    <child link="thumb_pip_sphere2" />
    <origin rpy="0 0 0" xyz="0.002056 0.015 -0.007151" />
    <axis xyz="0 0 1" />
    </joint>
  <link name="thumb_pip_sphere3" />
  <joint name="thumb_pip_joint_sphere3" type="fixed">
    <parent link="thumb_pip" />
    <child link="thumb_pip_sphere3" />
    <origin rpy="0 0 0" xyz="-0.004976 -0.015 -0.00904" />
    <axis xyz="0 0 1" />
    </joint>
  <link name="thumb_pip_sphere4" />
  <joint name="thumb_pip_joint_sphere4" type="fixed">
    <parent link="thumb_pip" />
    <child link="thumb_pip_sphere4" />
    <origin rpy="0 0 0" xyz="-0.004976 0.015 -0.00904" />
    <axis xyz="0 0 1" />
    </joint>
  <link name="thumb_pip_sphere5" />
  <joint name="thumb_pip_joint_sphere5" type="fixed">
    <parent link="thumb_pip" />
    <child link="thumb_pip_sphere5" />
    <origin rpy="0 0 0" xyz="0.004444 -0.015 -0.017227" />
    <axis xyz="0 0 1" />
    </joint>
  <link name="thumb_pip_sphere6" />
  <joint name="thumb_pip_joint_sphere6" type="fixed">
    <parent link="thumb_pip" />
    <child link="thumb_pip_sphere6" />
    <origin rpy="0 0 0" xyz="0.004444 0.015 -0.017227" />
    <axis xyz="0 0 1" />
    </joint>
  <link name="thumb_pip_sphere7" />
  <joint name="thumb_pip_joint_sphere7" type="fixed">
    <parent link="thumb_pip" />
    <child link="thumb_pip_sphere7" />
    <origin rpy="0 0 0" xyz="0.004401 0.004301 -0.0015" />
    <axis xyz="0 0 1" />
    </joint>
  <link name="thumb_pip_sphere8" />
  <joint name="thumb_pip_joint_sphere8" type="fixed">
    <parent link="thumb_pip" />
    <child link="thumb_pip_sphere8" />
    <origin rpy="0 0 0" xyz="0.004003 -0.004061 -0.0015" />
    <axis xyz="0 0 1" />
    </joint>
  <link name="thumb_pip_sphere9" />
  <joint name="thumb_pip_joint_sphere9" type="fixed">
    <parent link="thumb_pip" />
    <child link="thumb_pip_sphere9" />
    <origin rpy="0 0 0" xyz="-0.003716 0.013577 -0.0015" />
    <axis xyz="0 0 1" />
    </joint>
  <link name="thumb_pip_sphere10" />
  <joint name="thumb_pip_joint_sphere10" type="fixed">
    <parent link="thumb_pip" />
    <child link="thumb_pip_sphere10" />
    <origin rpy="0 0 0" xyz="-0.005628 -0.003209 -0.0015" />
    <axis xyz="0 0 1" />
    </joint>
  <link name="thumb_pip_sphere11" />
  <joint name="thumb_pip_joint_sphere11" type="fixed">
    <parent link="thumb_pip" />
    <child link="thumb_pip_sphere11" />
    <origin rpy="0 0 0" xyz="-0.004508 0.006102 -0.0015" />
    <axis xyz="0 0 1" />
    </joint>
  <link name="thumb_pip_sphere12" />
  <joint name="thumb_pip_joint_sphere12" type="fixed">
    <parent link="thumb_pip" />
    <child link="thumb_pip_sphere12" />
    <origin rpy="0 0 0" xyz="-0.004461 -0.012631 -0.0015" />
    <axis xyz="0 0 1" />
    </joint>
  <link name="thumb_pip_sphere13" />
  <joint name="thumb_pip_joint_sphere13" type="fixed">
    <parent link="thumb_pip" />
    <child link="thumb_pip_sphere13" />
    <origin rpy="0 0 0" xyz="0.004752 -0.012366 -0.0015" />
    <axis xyz="0 0 1" />
    </joint>
  <link name="thumb_pip_sphere14" />
  <joint name="thumb_pip_joint_sphere14" type="fixed">
    <parent link="thumb_pip" />
    <child link="thumb_pip_sphere14" />
    <origin rpy="0 0 0" xyz="-0.002656 -0.015 -0.019151" />
    <axis xyz="0 0 1" />
    </joint>
  <link name="thumb_pip_sphere15" />
  <joint name="thumb_pip_joint_sphere15" type="fixed">
    <parent link="thumb_pip" />
    <child link="thumb_pip_sphere15" />
    <origin rpy="0 0 0" xyz="-0.002656 0.015 -0.019151" />
    <axis xyz="0 0 1" />
    </joint>
  <link name="thumb_pip_sphere16" />
  <joint name="thumb_pip_joint_sphere16" type="fixed">
    <parent link="thumb_pip" />
    <child link="thumb_pip_sphere16" />
    <origin rpy="0 0 0" xyz="0.005552 0.012547 -0.0015" />
    <axis xyz="0 0 1" />
    </joint>
  <link name="thumb_dip_sphere1" />
  <joint name="thumb_dip_joint_sphere1" type="fixed">
    <parent link="thumb_dip" />
    <child link="thumb_dip_sphere1" />
    <origin rpy="0 0 0" xyz="1e-06 0.000499 -0.014" />
    <axis xyz="0 0 1" />
    </joint>
  <link name="thumb_dip_sphere2" />
  <joint name="thumb_dip_joint_sphere2" type="fixed">
    <parent link="thumb_dip" />
    <child link="thumb_dip_sphere2" />
    <origin rpy="0 0 0" xyz="1e-06 0.020501 -0.014001" />
    <axis xyz="0 0 1" />
    </joint>
  <link name="thumb_dip_sphere3" />
  <joint name="thumb_dip_joint_sphere3" type="fixed">
    <parent link="thumb_dip" />
    <child link="thumb_dip_sphere3" />
    <origin rpy="0 0 0" xyz="-0.0135 0.023452 -0.011648" />
    <axis xyz="0 0 1" />
    </joint>
  <link name="thumb_dip_sphere4" />
  <joint name="thumb_dip_joint_sphere4" type="fixed">
    <parent link="thumb_dip" />
    <child link="thumb_dip_sphere4" />
    <origin rpy="0 0 0" xyz="-0.0135 0.011412 -0.011674" />
    <axis xyz="0 0 1" />
    </joint>
  <link name="thumb_dip_sphere5" />
  <joint name="thumb_dip_joint_sphere5" type="fixed">
    <parent link="thumb_dip" />
    <child link="thumb_dip_sphere5" />
    <origin rpy="0 0 0" xyz="-0.006144 0.031 -0.025077" />
    <axis xyz="0 0 1" />
    </joint>
  <link name="thumb_dip_sphere6" />
  <joint name="thumb_dip_joint_sphere6" type="fixed">
    <parent link="thumb_dip" />
    <child link="thumb_dip_sphere6" />
    <origin rpy="0 0 0" xyz="-0.005324 0.031 -0.01372" />
    <axis xyz="0 0 1" />
    </joint>
  <link name="thumb_dip_sphere7" />
  <joint name="thumb_dip_joint_sphere7" type="fixed">
    <parent link="thumb_dip" />
    <child link="thumb_dip_sphere7" />
    <origin rpy="0 0 0" xyz="0.005379 0.031 -0.012823" />
    <axis xyz="0 0 1" />
    </joint>
  <link name="thumb_dip_sphere8" />
  <joint name="thumb_dip_joint_sphere8" type="fixed">
    <parent link="thumb_dip" />
    <child link="thumb_dip_sphere8" />
    <origin rpy="0 0 0" xyz="0.0035 0.031 -0.028824" />
    <axis xyz="0 0 1" />
    </joint>
  <link name="thumb_dip_sphere9" />
  <joint name="thumb_dip_joint_sphere9" type="fixed">
    <parent link="thumb_dip" />
    <child link="thumb_dip_sphere9" />
    <origin rpy="0 0 0" xyz="-0.005091 0.031 -0.003608" />
    <axis xyz="0 0 1" />
    </joint>
  <link name="thumb_dip_sphere10" />
  <joint name="thumb_dip_joint_sphere10" type="fixed">
    <parent link="thumb_dip" />
    <child link="thumb_dip_sphere10" />
    <origin rpy="0 0 0" xyz="0.004964 0.031 -0.003176" />
    <axis xyz="0 0 1" />
    </joint>
  <link name="thumb_dip_sphere11" />
  <joint name="thumb_dip_joint_sphere11" type="fixed">
    <parent link="thumb_dip" />
    <child link="thumb_dip_sphere11" />
    <origin rpy="0 0 0" xyz="0.004766 0.031 -0.022304" />
    <axis xyz="0 0 1" />
    </joint>
  <link name="thumb_dip_sphere12" />
  <joint name="thumb_dip_joint_sphere12" type="fixed">
    <parent link="thumb_dip" />
    <child link="thumb_dip_sphere12" />
    <origin rpy="0 0 0" xyz="0.003682 0.046655 0.001" />
    <axis xyz="0 0 1" />
    </joint>
  <link name="thumb_dip_sphere13" />
  <joint name="thumb_dip_joint_sphere13" type="fixed">
    <parent link="thumb_dip" />
    <child link="thumb_dip_sphere13" />
    <origin rpy="0 0 0" xyz="0.003682 0.046655 -0.029" />
    <axis xyz="0 0 1" />
    </joint>
  <link name="thumb_dip_sphere14" />
  <joint name="thumb_dip_joint_sphere14" type="fixed">
    <parent link="thumb_dip" />
    <child link="thumb_dip_sphere14" />
    <origin rpy="0 0 0" xyz="-0.003949 0.037145 0.001" />
    <axis xyz="0 0 1" />
    </joint>
  <link name="thumb_dip_sphere15" />
  <joint name="thumb_dip_joint_sphere15" type="fixed">
    <parent link="thumb_dip" />
    <child link="thumb_dip_sphere15" />
    <origin rpy="0 0 0" xyz="-0.003949 0.037145 -0.029" />
    <axis xyz="0 0 1" />
    </joint>
  <link name="thumb_dip_sphere16" />
  <joint name="thumb_dip_joint_sphere16" type="fixed">
    <parent link="thumb_dip" />
    <child link="thumb_dip_sphere16" />
    <origin rpy="0 0 0" xyz="0.003189 0.036536 0.001" />
    <axis xyz="0 0 1" />
    </joint>
  <link name="thumb_dip_sphere17" />
  <joint name="thumb_dip_joint_sphere17" type="fixed">
    <parent link="thumb_dip" />
    <child link="thumb_dip_sphere17" />
    <origin rpy="0 0 0" xyz="0.003189 0.036536 -0.029" />
    <axis xyz="0 0 1" />
    </joint>
  <link name="thumb_dip_sphere18" />
  <joint name="thumb_dip_joint_sphere18" type="fixed">
    <parent link="thumb_dip" />
    <child link="thumb_dip_sphere18" />
    <origin rpy="0 0 0" xyz="-0.003375 0.047346 0.001" />
    <axis xyz="0 0 1" />
    </joint>
  <link name="thumb_dip_sphere19" />
  <joint name="thumb_dip_joint_sphere19" type="fixed">
    <parent link="thumb_dip" />
    <child link="thumb_dip_sphere19" />
    <origin rpy="0 0 0" xyz="-0.003375 0.047346 -0.029" />
    <axis xyz="0 0 1" />
    </joint>
  <link name="thumb_fingertip_sphere1" />
  <joint name="thumb_fingertip_joint_sphere1" type="fixed">
    <parent link="thumb_fingertip" />
    <child link="thumb_fingertip_sphere1" />
    <origin rpy="0 0 0" xyz="-0.000828 -0.04498 -0.014353" />
    <axis xyz="0 0 1" />
    </joint>
  <link name="thumb_fingertip_sphere2" />
  <joint name="thumb_fingertip_joint_sphere2" type="fixed">
    <parent link="thumb_fingertip" />
    <child link="thumb_fingertip_sphere2" />
    <origin rpy="0 0 0" xyz="0.0 -0.0165 -0.015" />
    <axis xyz="0 0 1" />
    </joint>
  <link name="thumb_fingertip_sphere3" />
  <joint name="thumb_fingertip_joint_sphere3" type="fixed">
    <parent link="thumb_fingertip" />
    <child link="thumb_fingertip_sphere3" />
    <origin rpy="0 0 0" xyz="0.0 -0.0005 -0.015" />
    <axis xyz="0 0 1" />
    </joint>
  <link name="thumb_fingertip_sphere4" />
  <joint name="thumb_fingertip_joint_sphere4" type="fixed">
    <parent link="thumb_fingertip" />
    <child link="thumb_fingertip_sphere4" />
    <origin rpy="0 0 0" xyz="0.015 -0.023846 -0.01151" />
    <axis xyz="0 0 1" />
    </joint>
  <link name="thumb_fingertip_sphere5" />
  <joint name="thumb_fingertip_joint_sphere5" type="fixed">
    <parent link="thumb_fingertip" />
    <child link="thumb_fingertip_sphere5" />
    <origin rpy="0 0 0" xyz="0.015 -0.014047 -0.006501" />
    <axis xyz="0 0 1" />
    </joint>
  <link name="thumb_fingertip_sphere6" />
  <joint name="thumb_fingertip_joint_sphere6" type="fixed">
    <parent link="thumb_fingertip" />
    <child link="thumb_fingertip_sphere6" />
    <origin rpy="0 0 0" xyz="0.015 -0.011575 -0.014589" />
    <axis xyz="0 0 1" />
    </joint>
  <link name="thumb_fingertip_sphere7" />
  <joint name="thumb_fingertip_joint_sphere7" type="fixed">
    <parent link="thumb_fingertip" />
    <child link="thumb_fingertip_sphere7" />
    <origin rpy="0 0 0" xyz="-0.004963 -0.029 -0.003661" />
    <axis xyz="0 0 1" />
    </joint>
  <link name="thumb_fingertip_sphere8" />
  <joint name="thumb_fingertip_joint_sphere8" type="fixed">
    <parent link="thumb_fingertip" />
    <child link="thumb_fingertip_sphere8" />
    <origin rpy="0 0 0" xyz="-0.007195 -0.029 -0.014759" />
    <axis xyz="0 0 1" />
    </joint>
  <link name="thumb_fingertip_sphere9" />
  <joint name="thumb_fingertip_joint_sphere9" type="fixed">
    <parent link="thumb_fingertip" />
    <child link="thumb_fingertip_sphere9" />
    <origin rpy="0 0 0" xyz="0.003843 -0.029 -0.010822" />
    <axis xyz="0 0 1" />
    </joint>
  <link name="thumb_fingertip_sphere10" />
  <joint name="thumb_fingertip_joint_sphere10" type="fixed">
    <parent link="thumb_fingertip" />
    <child link="thumb_fingertip_sphere10" />
    <origin rpy="0 0 0" xyz="0.00523 -0.029 -0.003395" />
    <axis xyz="0 0 1" />
    </joint>
  <link name="thumb_fingertip_sphere11" />
  <joint name="thumb_fingertip_joint_sphere11" type="fixed">
    <parent link="thumb_fingertip" />
    <child link="thumb_fingertip_sphere11" />
    <origin rpy="0 0 0" xyz="0.004415 -0.029 -0.017151" />
    <axis xyz="0 0 1" />
    </joint>
  <link name="thumb_fingertip_sphere12" />
  <joint name="thumb_fingertip_joint_sphere12" type="fixed">
    <parent link="thumb_fingertip" />
    <child link="thumb_fingertip_sphere12" />
    <origin rpy="0 0 0" xyz="-0.004973 -0.029 -0.025106" />
    <axis xyz="0 0 1" />
    </joint>
  <link name="thumb_fingertip_sphere13" />
  <joint name="thumb_fingertip_joint_sphere13" type="fixed">
    <parent link="thumb_fingertip" />
    <child link="thumb_fingertip_sphere13" />
    <origin rpy="0 0 0" xyz="0.005241 -0.029 -0.025019" />
    <axis xyz="0 0 1" />
    </joint>
  </robot>
