<?xml version="1.0" encoding="utf-8"?>
<robot name="xarm7" path="assets/xarm7_leaphand/xarm7_leap_right_simplified.urdf">
	<link name="link_base">
		<inertial>
			<origin rpy="0 0 0" xyz="-0.021131 -0.0016302 0.056488"></origin>
			<mass value="0.88556"></mass>
			<inertia ixx="0.0030595" ixy="0.00012259" ixz="-0.00062705" iyy="0.0037783" iyz="0.00027023" izz="0.0020125"></inertia>
		</inertial>
		<visual>
			<geometry>
				<mesh filename="meshes/visual/link_base.glb"></mesh>
			</geometry>
			<origin rpy="0 0 0" xyz="0 0 0"></origin>
		</visual>
		<collision>
			<geometry>
				<sphere radius="0.090543"></sphere>
			</geometry>
			<origin xyz="-0.009822685557497348 -0.0004200115631789337 0.045932544027745804" rpy="0 0 0"></origin>
		</collision>
		<collision>
			<geometry>
				<sphere radius="0.08327"></sphere>
			</geometry>
			<origin xyz="0.001143314442502652 0.0010229884368210664 0.09642654402774581" rpy="0 0 0"></origin>
		</collision>
	</link>
	<link name="link1">
		<inertial>
			<origin rpy="0 0 0" xyz="-0.0002 0.02905 -0.01233"></origin>
			<mass value="2.382"></mass>
			<inertia ixx="0.0056905" ixy="-1.579e-05" ixz="5.125e-06" iyy="0.0049566" iyz="-0.000873378" izz="0.003316654"></inertia>
		</inertial>
		<visual>
			<geometry>
				<mesh filename="meshes/visual/link1.glb"></mesh>
			</geometry>
			<origin rpy="0 0 0" xyz="0 0 0"></origin>
		</visual>
		<collision>
			<geometry>
				<sphere radius="0.082036"></sphere>
			</geometry>
			<origin xyz="0.00011850103334569171 0.016853344212451223 -0.00018040880377904328" rpy="0 0 0"></origin>
		</collision>
		<collision>
			<geometry>
				<sphere radius="0.076086"></sphere>
			</geometry>
			<origin xyz="-0.0002344989666543083 -0.0047386557875487775 -0.06557640880377905" rpy="0 0 0"></origin>
		</collision>
	</link>
	<link name="link2">
		<inertial>
			<origin rpy="0 0 0" xyz="0.00022 -0.12856 0.01735"></origin>
			<mass value="1.869"></mass>
			<inertia ixx="0.0095989" ixy="1.541e-06" ixz="5.56e-06" iyy="0.00382472" iyz="-0.00317156" izz="0.007565669"></inertia>
		</inertial>
		<visual>
			<geometry>
				<mesh filename="meshes/visual/link2.glb"></mesh>
			</geometry>
			<origin rpy="0 0 0" xyz="0 0 0"></origin>
		</visual>
		<collision>
			<geometry>
				<sphere radius="0.081135"></sphere>
			</geometry>
			<origin xyz="-0.0003014605783935966 -0.1333216654906158 0.0016707879268057085" rpy="0 0 0"></origin>
		</collision>
		<collision>
			<geometry>
				<sphere radius="0.081483"></sphere>
			</geometry>
			<origin xyz="-0.0017104605783935967 -0.09539866549061579 0.07280178792680571" rpy="0 0 0"></origin>
		</collision>
		<collision>
			<geometry>
				<sphere radius="0.059776"></sphere>
			</geometry>
			<origin xyz="-0.015401460578393597 0.005834334509384212 0.09610278792680571" rpy="0 0 0"></origin>
		</collision>
		<collision>
			<geometry>
				<sphere radius="0.057029"></sphere>
			</geometry>
			<origin xyz="0.022086539421606405 0.0002483345093842182 0.09450478792680571" rpy="0 0 0"></origin>
		</collision>
	</link>
	<link name="link3">
		<inertial>
			<origin rpy="0 0 0" xyz="0.0466 -0.02463 -0.00768"></origin>
			<mass value="1.6383"></mass>
			<inertia ixx="0.00310955" ixy="0.00030837" ixz="-0.00058453" iyy="0.00264483" iyz="0.000338893" izz="0.0026624"></inertia>
		</inertial>
		<visual>
			<geometry>
				<mesh filename="meshes/visual/link3.glb"></mesh>
			</geometry>
			<origin rpy="0 0 0" xyz="0 0 0"></origin>
		</visual>
		<collision>
			<geometry>
				<sphere radius="0.085349"></sphere>
			</geometry>
			<origin xyz="0.013209131899725777 0.01003219089153077 -0.04565185660528091" rpy="0 0 0"></origin>
		</collision>
		<collision>
			<geometry>
				<sphere radius="0.083065"></sphere>
			</geometry>
			<origin xyz="0.05079413189972577 -0.003523809108469231 -0.0004138566052809163" rpy="0 0 0"></origin>
		</collision>
	</link>
	<link name="link4">
		<inertial>
			<origin rpy="0 0 0" xyz="0.07047 -0.11575 0.012"></origin>
			<mass value="1.7269"></mass>
			<inertia ixx="0.005889" ixy="0.00137112" ixz="0.00088143" iyy="0.00359703" iyz="-0.001762155" izz="0.00543244"></inertia>
		</inertial>
		<visual>
			<geometry>
				<mesh filename="meshes/visual/link4.glb"></mesh>
			</geometry>
			<origin rpy="0 0 0" xyz="0 0 0"></origin>
		</visual>
		<collision>
			<geometry>
				<sphere radius="0.066979"></sphere>
			</geometry>
			<origin xyz="0.07793559973734299 -0.13077204715368318 0.007634861635274347" rpy="0 0 0"></origin>
		</collision>
		<collision>
			<geometry>
				<sphere radius="0.070637"></sphere>
			</geometry>
			<origin xyz="0.077846599737343 -0.09137604715368317 0.014254861635274348" rpy="0 0 0"></origin>
		</collision>
		<collision>
			<geometry>
				<sphere radius="0.071681"></sphere>
			</geometry>
			<origin xyz="0.069955599737343 -0.08038304715368318 0.06174686163527435" rpy="0 0 0"></origin>
		</collision>
		<collision>
			<geometry>
				<sphere radius="0.059201"></sphere>
			</geometry>
			<origin xyz="0.026581599737342993 -0.023333047153683173 0.08347086163527434" rpy="0 0 0"></origin>
		</collision>
		<collision>
			<geometry>
				<sphere radius="0.05454"></sphere>
			</geometry>
			<origin xyz="-0.0011094002626570038 -0.0011250471536831744 0.08654786163527434" rpy="0 0 0"></origin>
		</collision>
	</link>
	<link name="link5">
		<inertial>
			<origin rpy="0 0 0" xyz="-0.00032 0.01604 -0.026"></origin>
			<mass value="1.3203"></mass>
			<inertia ixx="0.00534665" ixy="1.5117e-05" ixz="-3.69e-07" iyy="0.0049779" iyz="-0.00022132" izz="0.0013624"></inertia>
		</inertial>
		<visual>
			<geometry>
				<mesh filename="meshes/visual/link5.glb"></mesh>
			</geometry>
			<origin rpy="0 0 0" xyz="0 0 0"></origin>
		</visual>
		<collision>
			<geometry>
				<sphere radius="0.044377"></sphere>
			</geometry>
			<origin xyz="0.00011264382708814141 0.06108914765800623 -0.08047913520490677" rpy="0 0 0"></origin>
		</collision>
		<collision>
			<geometry>
				<sphere radius="0.058074"></sphere>
			</geometry>
			<origin xyz="0.0020476438270881415 0.00350914765800623 -0.14488713520490676" rpy="0 0 0"></origin>
		</collision>
		<collision>
			<geometry>
				<sphere radius="0.056247"></sphere>
			</geometry>
			<origin xyz="-7.53561729118586e-05 0.053318147658006236 -0.03188613520490676" rpy="0 0 0"></origin>
		</collision>
		<collision>
			<geometry>
				<sphere radius="0.055407"></sphere>
			</geometry>
			<origin xyz="-0.0006303561729118585 0.04021514765800623 -0.0001451352049067628" rpy="0 0 0"></origin>
		</collision>
		<collision>
			<geometry>
				<sphere radius="0.049012"></sphere>
			</geometry>
			<origin xyz="-0.0027083561729118587 0.04267714765800623 -0.10967313520490676" rpy="0 0 0"></origin>
		</collision>
	</link>
	<link name="link6">
		<inertial>
			<origin rpy="0 0 0" xyz="0.06469 0.03278 0.02141"></origin>
			<mass value="1.325"></mass>
			<inertia ixx="0.0014745" ixy="-0.000488" ixz="0.0002953" iyy="0.0019037" iyz="0.00014749" izz="0.0023652"></inertia>
		</inertial>
		<visual>
			<geometry>
				<mesh filename="meshes/visual/link6.glb"></mesh>
			</geometry>
			<origin rpy="0 0 0" xyz="0 0 0"></origin>
		</visual>
		<collision>
			<geometry>
				<sphere radius="0.060912"></sphere>
			</geometry>
			<origin xyz="0.07598182 0.020571005 6.90150000000004e-05" rpy="0 0 0"></origin>
		</collision>
		<collision>
			<geometry>
				<sphere radius="0.063307"></sphere>
			</geometry>
			<origin xyz="0.02012482 0.0001880050000000015 0.021902015" rpy="0 0 0"></origin>
		</collision>
	</link>
	<link name="link7">
		<inertial>
			<origin rpy="0 0 0" xyz="0 -0.00677 -0.01098"></origin>
			<mass value="0.17"></mass>
			<inertia ixx="9.3e-05" ixy="-0.0" ixz="-0.0" iyy="5.87e-05" iyz="-3.6e-06" izz="0.000132"></inertia>
		</inertial>
		<visual>
			<geometry>
				<mesh filename="meshes/visual/link7.glb"></mesh>
			</geometry>
			<origin rpy="0 0 0" xyz="0 0 0"></origin>
		</visual>
		<collision>
			<geometry>
				<sphere radius="0.044033"></sphere>
			</geometry>
			<origin xyz="0.00015747225003949966 0.0013680348926104636 -0.013522055370485246" rpy="0 0 0"></origin>
		</collision>
		<collision>
			<geometry>
				<sphere radius="0.043479"></sphere>
			</geometry>
			<origin xyz="-0.0098065277499605 -0.014765965107389535 -0.013716055370485246" rpy="0 0 0"></origin>
		</collision>
	</link>
	<link name="palm_link">
		<visual>
			<origin xyz="-0.020095249652862544332 0.025757756134899473244 -0.034722403578460216134" rpy="0 -0 0"></origin>
			<geometry>
				<mesh filename="leap_hand/palm_lower.stl"></mesh>
			</geometry>
			<material name="palm_link_material">
				<color rgba="0.60392156862745094426 0.14901960784313725283 0.14901960784313725283 1.0"></color>
			</material>
		</visual>
		<collision>
			<geometry>
				<sphere radius="0.020273"></sphere>
			</geometry>
			<origin xyz="-0.008999999999999998 0.008 -0.017" rpy="0 0 0"></origin>
		</collision>
		<collision>
			<geometry>
				<sphere radius="0.020273"></sphere>
			</geometry>
			<origin xyz="-0.009000999999999997 0.008 -0.004999999999999999" rpy="0 0 0"></origin>
		</collision>
		<collision>
			<geometry>
				<sphere radius="0.020273"></sphere>
			</geometry>
			<origin xyz="-0.008999999999999998 -0.037 -0.017" rpy="0 0 0"></origin>
		</collision>
		<collision>
			<geometry>
				<sphere radius="0.020273"></sphere>
			</geometry>
			<origin xyz="-0.009000999999999997 -0.037 -0.004999999999999999" rpy="0 0 0"></origin>
		</collision>
		<collision>
			<geometry>
				<sphere radius="0.020273"></sphere>
			</geometry>
			<origin xyz="-0.008999999999999998 -0.082 -0.017" rpy="0 0 0"></origin>
		</collision>
		<collision>
			<geometry>
				<sphere radius="0.020273"></sphere>
			</geometry>
			<origin xyz="-0.009000999999999997 -0.082 -0.004999999999999999" rpy="0 0 0"></origin>
		</collision>
		<collision>
			<geometry>
				<sphere radius="0.02711"></sphere>
			</geometry>
			<origin xyz="-0.048111 -0.083471 -0.011500000000000002" rpy="0 0 0"></origin>
		</collision>
		<collision>
			<geometry>
				<sphere radius="0.025484"></sphere>
			</geometry>
			<origin xyz="-0.075006 -0.075247 -0.0013750000000000012" rpy="0 0 0"></origin>
		</collision>
		<collision>
			<geometry>
				<sphere radius="0.02658"></sphere>
			</geometry>
			<origin xyz="-0.072741 -0.075939 -0.023339000000000002" rpy="0 0 0"></origin>
		</collision>
		<collision>
			<geometry>
				<sphere radius="0.018064"></sphere>
			</geometry>
			<origin xyz="-0.03 -0.083762 0.002000000000000001" rpy="0 0 0"></origin>
		</collision>
		<collision>
			<geometry>
				<sphere radius="0.019652"></sphere>
			</geometry>
			<origin xyz="-0.030001 -0.08135400000000001 -0.008001" rpy="0 0 0"></origin>
		</collision>
		<collision>
			<geometry>
				<sphere radius="0.019924"></sphere>
			</geometry>
			<origin xyz="-0.029998999999999998 -0.060492000000000004 -0.001706999999999999" rpy="0 0 0"></origin>
		</collision>
		<collision>
			<geometry>
				<sphere radius="0.020306"></sphere>
			</geometry>
			<origin xyz="-0.030001 -0.040293 -0.008" rpy="0 0 0"></origin>
		</collision>
		<collision>
			<geometry>
				<sphere radius="0.020074"></sphere>
			</geometry>
			<origin xyz="-0.03 0.010754999999999994 0.002000000000000001" rpy="0 0 0"></origin>
		</collision>
		<collision>
			<geometry>
				<sphere radius="0.020463"></sphere>
			</geometry>
			<origin xyz="-0.03 -0.013925000000000003 -0.0035179999999999994" rpy="0 0 0"></origin>
		</collision>
		<collision>
			<geometry>
				<sphere radius="0.019999"></sphere>
			</geometry>
			<origin xyz="-0.029998999999999998 0.010858 -0.008003" rpy="0 0 0"></origin>
		</collision>
		<collision>
			<geometry>
				<sphere radius="0.020058"></sphere>
			</geometry>
			<origin xyz="-0.029997 -0.034841000000000004 0.0020030000000000004" rpy="0 0 0"></origin>
		</collision>
		<collision>
			<geometry>
				<sphere radius="0.013339"></sphere>
			</geometry>
			<origin xyz="-0.032 -0.087726 -0.023999" rpy="0 0 0"></origin>
		</collision>
		<collision>
			<geometry>
				<sphere radius="0.013678"></sphere>
			</geometry>
			<origin xyz="-0.031989000000000004 -0.071381 -0.023989" rpy="0 0 0"></origin>
		</collision>
		<collision>
			<geometry>
				<sphere radius="0.013359"></sphere>
			</geometry>
			<origin xyz="-0.032313 -0.055604 -0.024313" rpy="0 0 0"></origin>
		</collision>
		<collision>
			<geometry>
				<sphere radius="0.013099"></sphere>
			</geometry>
			<origin xyz="-0.031428 -0.041055 -0.023428" rpy="0 0 0"></origin>
		</collision>
		<collision>
			<geometry>
				<sphere radius="0.013038"></sphere>
			</geometry>
			<origin xyz="-0.032287 -0.027111000000000003 -0.024288" rpy="0 0 0"></origin>
		</collision>
		<collision>
			<geometry>
				<sphere radius="0.013036"></sphere>
			</geometry>
			<origin xyz="-0.03173 -0.012600000000000004 -0.02373" rpy="0 0 0"></origin>
		</collision>
		<collision>
			<geometry>
				<sphere radius="0.013339"></sphere>
			</geometry>
			<origin xyz="-0.032 0.0019809999999999967 -0.024" rpy="0 0 0"></origin>
		</collision>
		<collision>
			<geometry>
				<sphere radius="0.013335"></sphere>
			</geometry>
			<origin xyz="-0.032 0.017733 -0.024" rpy="0 0 0"></origin>
		</collision>
		<collision>
			<geometry>
				<sphere radius="0.028585"></sphere>
			</geometry>
			<origin xyz="-0.048 -0.079001 -0.011502000000000002" rpy="0 0 0"></origin>
		</collision>
		<collision>
			<geometry>
				<sphere radius="0.028704"></sphere>
			</geometry>
			<origin xyz="-0.047999 -0.055233000000000004 -0.012001000000000001" rpy="0 0 0"></origin>
		</collision>
		<collision>
			<geometry>
				<sphere radius="0.029179"></sphere>
			</geometry>
			<origin xyz="-0.048 -0.028875 -0.010420000000000002" rpy="0 0 0"></origin>
		</collision>
		<collision>
			<geometry>
				<sphere radius="0.026875"></sphere>
			</geometry>
			<origin xyz="-0.048 0.0063519999999999965 -0.0036780000000000007" rpy="0 0 0"></origin>
		</collision>
		<collision>
			<geometry>
				<sphere radius="0.029143"></sphere>
			</geometry>
			<origin xyz="-0.048 0.0013069999999999957 -0.022502" rpy="0 0 0"></origin>
		</collision>
		<collision>
			<geometry>
				<sphere radius="0.041097"></sphere>
			</geometry>
			<origin xyz="-0.078 -0.053 -0.011500000000000002" rpy="0 0 0"></origin>
		</collision>
		<collision>
			<geometry>
				<sphere radius="0.009194"></sphere>
			</geometry>
			<origin xyz="-0.098 0.0020000000000000018 0.005396000000000001" rpy="0 0 0"></origin>
		</collision>
		<collision>
			<geometry>
				<sphere radius="0.009136"></sphere>
			</geometry>
			<origin xyz="-0.098 0.003618000000000003 -0.008074" rpy="0 0 0"></origin>
		</collision>
		<collision>
			<geometry>
				<sphere radius="0.008762"></sphere>
			</geometry>
			<origin xyz="-0.098 0.0012510000000000021 -0.019496" rpy="0 0 0"></origin>
		</collision>
		<collision>
			<geometry>
				<sphere radius="0.009444"></sphere>
			</geometry>
			<origin xyz="-0.098 -0.009536999999999997 0.002595000000000001" rpy="0 0 0"></origin>
		</collision>
		<collision>
			<geometry>
				<sphere radius="0.009226"></sphere>
			</geometry>
			<origin xyz="-0.098 -0.020571 0.004727000000000001" rpy="0 0 0"></origin>
		</collision>
		<collision>
			<geometry>
				<sphere radius="0.009031"></sphere>
			</geometry>
			<origin xyz="-0.098 -0.019777999999999997 -0.006755999999999999" rpy="0 0 0"></origin>
		</collision>
		<collision>
			<geometry>
				<sphere radius="0.009166"></sphere>
			</geometry>
			<origin xyz="-0.098 -0.008834999999999997 -0.014573" rpy="0 0 0"></origin>
		</collision>
		<collision>
			<geometry>
				<sphere radius="0.009296"></sphere>
			</geometry>
			<origin xyz="-0.098 -0.019811999999999996 -0.017495999999999998" rpy="0 0 0"></origin>
		</collision>
		<collision>
			<geometry>
				<sphere radius="0.013006"></sphere>
			</geometry>
			<origin xyz="-0.082469 0.013555000000000001 0.01" rpy="0 0 0"></origin>
		</collision>
		<collision>
			<geometry>
				<sphere radius="0.012859"></sphere>
			</geometry>
			<origin xyz="-0.074894 -0.019507999999999998 0.01" rpy="0 0 0"></origin>
		</collision>
		<collision>
			<geometry>
				<sphere radius="0.012861"></sphere>
			</geometry>
			<origin xyz="-0.065559 -0.0006649999999999994 0.01" rpy="0 0 0"></origin>
		</collision>
		<collision>
			<geometry>
				<sphere radius="0.012852"></sphere>
			</geometry>
			<origin xyz="-0.089653 -0.005859999999999999 0.01" rpy="0 0 0"></origin>
		</collision>
		<collision>
			<geometry>
				<sphere radius="0.012873"></sphere>
			</geometry>
			<origin xyz="-0.065778 0.01688 0.01" rpy="0 0 0"></origin>
		</collision>
		<collision>
			<geometry>
				<sphere radius="0.012857"></sphere>
			</geometry>
			<origin xyz="-0.09046799999999999 -0.022657999999999998 0.01" rpy="0 0 0"></origin>
		</collision>
		<collision>
			<geometry>
				<sphere radius="0.012565"></sphere>
			</geometry>
			<origin xyz="-0.062443 -0.020399999999999998 0.010001" rpy="0 0 0"></origin>
		</collision>
		<collision>
			<geometry>
				<sphere radius="0.012723"></sphere>
			</geometry>
			<origin xyz="-0.0946 0.013656000000000001 0.01" rpy="0 0 0"></origin>
		</collision>
		<inertial>
			<origin xyz="0 0 0" rpy="0 0 0"></origin>
			<mass value="0.237"></mass>
			<inertia ixx="0.000354094" ixy="-0.000001193" ixz="-0.000002445" iyy="0.000260915" iyz="-0.000002905" izz="0.000529257"></inertia>
		</inertial>
	</link>
	<link name="mcp_joint_1">
		<visual>
			<origin xyz="0.0084069022611744960438 0.0077662438597169954416 0.014657354985032912051" rpy="1.6375789613220999807e-15 -1.0210473302491019535e-30 1.7177968783327987474e-31"></origin>
			<geometry>
				<mesh filename="leap_hand/mcp_joint.stl"></mesh>
			</geometry>
			<material name="mcp_joint_1_material">
				<color rgba="0.86666666666666669627 0.86666666666666669627 0.050980392156862744391 1.0"></color>
			</material>
		</visual>
		<collision>
			<geometry>
				<sphere radius="0.008567"></sphere>
			</geometry>
			<origin xyz="-0.003739 0.018 0.026747" rpy="0 0 0"></origin>
		</collision>
		<collision>
			<geometry>
				<sphere radius="0.009493"></sphere>
			</geometry>
			<origin xyz="0.006494 0.018 0.023403" rpy="0 0 0"></origin>
		</collision>
		<collision>
			<geometry>
				<sphere radius="0.008916"></sphere>
			</geometry>
			<origin xyz="-0.005154 0.017998999999999998 0.014528999999999999" rpy="0 0 0"></origin>
		</collision>
		<collision>
			<geometry>
				<sphere radius="0.009578"></sphere>
			</geometry>
			<origin xyz="0.006998 0.018 0.006285999999999998" rpy="0 0 0"></origin>
		</collision>
		<collision>
			<geometry>
				<sphere radius="0.008954"></sphere>
			</geometry>
			<origin xyz="-0.003105 0.018 0.0025279999999999973" rpy="0 0 0"></origin>
		</collision>
		<collision>
			<geometry>
				<sphere radius="0.0199"></sphere>
			</geometry>
			<origin xyz="-0.027001 0.031999 0.015" rpy="0 0 0"></origin>
		</collision>
		<collision>
			<geometry>
				<sphere radius="0.0199"></sphere>
			</geometry>
			<origin xyz="-0.026999 0.052001000000000006 0.015" rpy="0 0 0"></origin>
		</collision>
		<collision>
			<geometry>
				<sphere radius="0.009333"></sphere>
			</geometry>
			<origin xyz="-0.036193 0.02 0.019267" rpy="0 0 0"></origin>
		</collision>
		<collision>
			<geometry>
				<sphere radius="0.009593"></sphere>
			</geometry>
			<origin xyz="-0.03524 0.02 0.009028999999999999" rpy="0 0 0"></origin>
		</collision>
		<collision>
			<geometry>
				<sphere radius="0.008799"></sphere>
			</geometry>
			<origin xyz="-0.02314 0.02 0.018738" rpy="0 0 0"></origin>
		</collision>
		<collision>
			<geometry>
				<sphere radius="0.009856"></sphere>
			</geometry>
			<origin xyz="-0.018096 0.02 0.007599" rpy="0 0 0"></origin>
		</collision>
		<collision>
			<geometry>
				<sphere radius="0.009171"></sphere>
			</geometry>
			<origin xyz="-0.013073000000000001 0.02 0.016885" rpy="0 0 0"></origin>
		</collision>
		<collision>
			<geometry>
				<sphere radius="0.011518"></sphere>
			</geometry>
			<origin xyz="-0.0295 0.042919000000000006 0.029" rpy="0 0 0"></origin>
		</collision>
		<collision>
			<geometry>
				<sphere radius="0.010394"></sphere>
			</geometry>
			<origin xyz="-0.025256999999999998 0.030674000000000003 0.029" rpy="0 0 0"></origin>
		</collision>
		<collision>
			<geometry>
				<sphere radius="0.009557"></sphere>
			</geometry>
			<origin xyz="-0.035439 0.030670000000000003 0.029" rpy="0 0 0"></origin>
		</collision>
		<collision>
			<geometry>
				<sphere radius="0.006279"></sphere>
			</geometry>
			<origin xyz="0.003189 -0.00046400000000000087 0.03" rpy="0 0 0"></origin>
		</collision>
		<collision>
			<geometry>
				<sphere radius="0.006312"></sphere>
			</geometry>
			<origin xyz="-0.003949 0.0001449999999999993 0.03" rpy="0 0 0"></origin>
		</collision>
		<collision>
			<geometry>
				<sphere radius="0.006229"></sphere>
			</geometry>
			<origin xyz="-0.003375 0.010346 0.03" rpy="0 0 0"></origin>
		</collision>
		<collision>
			<geometry>
				<sphere radius="0.006615"></sphere>
			</geometry>
			<origin xyz="0.003682 0.009655 0.03" rpy="0 0 0"></origin>
		</collision>
		<collision>
			<geometry>
				<sphere radius="0.006279"></sphere>
			</geometry>
			<origin xyz="0.003189 -0.00046400000000000087 -0.001" rpy="0 0 0"></origin>
		</collision>
		<collision>
			<geometry>
				<sphere radius="0.006312"></sphere>
			</geometry>
			<origin xyz="-0.003949 0.0001449999999999993 -0.001" rpy="0 0 0"></origin>
		</collision>
		<collision>
			<geometry>
				<sphere radius="0.006229"></sphere>
			</geometry>
			<origin xyz="-0.003375 0.010346 -0.001" rpy="0 0 0"></origin>
		</collision>
		<collision>
			<geometry>
				<sphere radius="0.006615"></sphere>
			</geometry>
			<origin xyz="0.003682 0.009655 -0.001" rpy="0 0 0"></origin>
		</collision>
		<inertial>
			<origin xyz="0 0 0" rpy="0 0 0"></origin>
			<mass value="0.044"></mass>
			<inertia ixx="0.000011499" ixy="0.000003049" ixz="0.000000121" iyy="0.000007796" iyz="0.000000112" izz="0.000014759"></inertia>
		</inertial>
	</link>
	<link name="pip_1">
		<visual>
			<origin xyz="0.0096433630922713280131 0.00029999999999998951117 0.00078403401041737645627" rpy="-1.570796326794896558 -1.570796326794896336 0"></origin>
			<geometry>
				<mesh filename="leap_hand/pip.stl"></mesh>
			</geometry>
			<material name="pip_1_material">
				<color rgba="0.74901960784313725839 0.74901960784313725839 0.74901960784313725839 1.0"></color>
			</material>
		</visual>
		<collision>
			<geometry>
				<sphere radius="0.020274"></sphere>
			</geometry>
			<origin xyz="0.0015009999999999997 -0.00020000000000000052 -0.011" rpy="0 0 0"></origin>
		</collision>
		<collision>
			<geometry>
				<sphere radius="0.020273"></sphere>
			</geometry>
			<origin xyz="0.013500999999999999 -0.00020000000000000052 -0.010999" rpy="0 0 0"></origin>
		</collision>
		<inertial>
			<origin xyz="0 0 0" rpy="0 0 0"></origin>
			<mass value="0.032"></mass>
			<inertia ixx="0.000004798" ixy="0.000000012" ixz="0.000000004" iyy="0.000002862" iyz="0.000000011" izz="0.000004234"></inertia>
		</inertial>
	</link>
	<link name="dip_1">
		<visual>
			<origin xyz="0.021133352895225002849 -0.0084321191467048792201 0.0097850881620952408213" rpy="-3.141592653589793116 4.5075111242164408299e-32 4.4395481053923607589e-32"></origin>
			<geometry>
				<mesh filename="leap_hand/dip.stl"></mesh>
			</geometry>
			<material name="dip_1_material">
				<color rgba="0.86666666666666669627 0.86666666666666669627 0.050980392156862744391 1.0"></color>
			</material>
		</visual>
		<collision>
			<geometry>
				<sphere radius="0.007791"></sphere>
			</geometry>
			<origin xyz="-0.003656 -0.02 0.022271" rpy="0 0 0"></origin>
		</collision>
		<collision>
			<geometry>
				<sphere radius="0.00826"></sphere>
			</geometry>
			<origin xyz="0.004477 -0.02 0.021214999999999998" rpy="0 0 0"></origin>
		</collision>
		<collision>
			<geometry>
				<sphere radius="0.008131"></sphere>
			</geometry>
			<origin xyz="0.003347 -0.02 0.007914" rpy="0 0 0"></origin>
		</collision>
		<collision>
			<geometry>
				<sphere radius="0.008407"></sphere>
			</geometry>
			<origin xyz="-0.004874 -0.02 0.009187" rpy="0 0 0"></origin>
		</collision>
		<collision>
			<geometry>
				<sphere radius="0.006739"></sphere>
			</geometry>
			<origin xyz="0.00553 -0.016 0.027371" rpy="0 0 0"></origin>
		</collision>
		<collision>
			<geometry>
				<sphere radius="0.006714"></sphere>
			</geometry>
			<origin xyz="-0.004669 -0.016 0.028471999999999997" rpy="0 0 0"></origin>
		</collision>
		<collision>
			<geometry>
				<sphere radius="0.006907"></sphere>
			</geometry>
			<origin xyz="-0.005092 -0.016 0.020145" rpy="0 0 0"></origin>
		</collision>
		<collision>
			<geometry>
				<sphere radius="0.007083"></sphere>
			</geometry>
			<origin xyz="0.006365 -0.016 0.017072" rpy="0 0 0"></origin>
		</collision>
		<collision>
			<geometry>
				<sphere radius="0.0069"></sphere>
			</geometry>
			<origin xyz="-0.005261 -0.016 0.010866999999999998" rpy="0 0 0"></origin>
		</collision>
		<collision>
			<geometry>
				<sphere radius="0.006504"></sphere>
			</geometry>
			<origin xyz="0.004918 -0.016 0.007208999999999999" rpy="0 0 0"></origin>
		</collision>
		<collision>
			<geometry>
				<sphere radius="0.006329"></sphere>
			</geometry>
			<origin xyz="-0.005632 -0.016 0.0021199999999999986" rpy="0 0 0"></origin>
		</collision>
		<collision>
			<geometry>
				<sphere radius="0.006527"></sphere>
			</geometry>
			<origin xyz="0.00448 -0.016 0.0008039999999999992" rpy="0 0 0"></origin>
		</collision>
		<collision>
			<geometry>
				<sphere radius="0.006279"></sphere>
			</geometry>
			<origin xyz="0.003189 -0.009963999999999999 0.03" rpy="0 0 0"></origin>
		</collision>
		<collision>
			<geometry>
				<sphere radius="0.006312"></sphere>
			</geometry>
			<origin xyz="-0.003949 -0.009354999999999999 0.03" rpy="0 0 0"></origin>
		</collision>
		<collision>
			<geometry>
				<sphere radius="0.006229"></sphere>
			</geometry>
			<origin xyz="-0.003375 0.0008460000000000013 0.03" rpy="0 0 0"></origin>
		</collision>
		<collision>
			<geometry>
				<sphere radius="0.006615"></sphere>
			</geometry>
			<origin xyz="0.003682 0.0001550000000000015 0.03" rpy="0 0 0"></origin>
		</collision>
		<collision>
			<geometry>
				<sphere radius="0.006279"></sphere>
			</geometry>
			<origin xyz="0.003189 -0.009963999999999999 0.0" rpy="0 0 0"></origin>
		</collision>
		<collision>
			<geometry>
				<sphere radius="0.006312"></sphere>
			</geometry>
			<origin xyz="-0.003949 -0.009354999999999999 0.0" rpy="0 0 0"></origin>
		</collision>
		<collision>
			<geometry>
				<sphere radius="0.006229"></sphere>
			</geometry>
			<origin xyz="-0.003375 0.0008460000000000013 0.0" rpy="0 0 0"></origin>
		</collision>
		<collision>
			<geometry>
				<sphere radius="0.006615"></sphere>
			</geometry>
			<origin xyz="0.003682 0.0001550000000000015 0.0" rpy="0 0 0"></origin>
		</collision>
		<collision>
			<geometry>
				<sphere radius="0.020274"></sphere>
			</geometry>
			<origin xyz="0.0014999999999999996 -0.035001000000000004 0.015" rpy="0 0 0"></origin>
		</collision>
		<collision>
			<geometry>
				<sphere radius="0.020273"></sphere>
			</geometry>
			<origin xyz="0.0135 -0.035 0.014999" rpy="0 0 0"></origin>
		</collision>
		<inertial>
			<origin xyz="0 0 0" rpy="0 0 0"></origin>
			<mass value="0.037"></mass>
			<inertia ixx="0.000005542" ixy="-0.000000607" ixz="-0.000000017" iyy="0.000005727" iyz="-0.000000023" izz="0.000006682"></inertia>
		</inertial>
	</link>
	<link name="fingertip_1">
		<visual>
			<origin xyz="0.013286424108533503169 -0.0061142383865419869249 0.014499999999999497666" rpy="3.141592653589793116 1.1993117970061734707e-33 4.4395481053923607589e-32"></origin>
			<geometry>
				<mesh filename="leap_hand/fingertip.stl"></mesh>
			</geometry>
			<material name="fingertip_1_material">
				<color rgba="0.86666666666666669627 0.86666666666666669627 0.050980392156862744391 1.0"></color>
			</material>
		</visual>
		<collision>
			<geometry>
				<sphere radius="0.009519"></sphere>
			</geometry>
			<origin xyz="0.003799 -0.017 0.006543" rpy="0 0 0"></origin>
		</collision>
		<collision>
			<geometry>
				<sphere radius="0.009911"></sphere>
			</geometry>
			<origin xyz="-0.006462 -0.017 0.008712" rpy="0 0 0"></origin>
		</collision>
		<collision>
			<geometry>
				<sphere radius="0.00922"></sphere>
			</geometry>
			<origin xyz="-0.003787 -0.017 0.023887" rpy="0 0 0"></origin>
		</collision>
		<collision>
			<geometry>
				<sphere radius="0.009556"></sphere>
			</geometry>
			<origin xyz="0.006409 -0.017 0.021671" rpy="0 0 0"></origin>
		</collision>
		<collision>
			<geometry>
				<sphere radius="0.005822"></sphere>
			</geometry>
			<origin xyz="-0.003256 -0.013027 0.03" rpy="0 0 0"></origin>
		</collision>
		<collision>
			<geometry>
				<sphere radius="0.006464"></sphere>
			</geometry>
			<origin xyz="0.00382 -0.011789 0.03" rpy="0 0 0"></origin>
		</collision>
		<collision>
			<geometry>
				<sphere radius="0.005801"></sphere>
			</geometry>
			<origin xyz="-0.003284 -0.0046440000000000006 0.03" rpy="0 0 0"></origin>
		</collision>
		<collision>
			<geometry>
				<sphere radius="0.006366"></sphere>
			</geometry>
			<origin xyz="0.004645 -0.0005660000000000014 0.03" rpy="0 0 0"></origin>
		</collision>
		<collision>
			<geometry>
				<sphere radius="0.006017"></sphere>
			</geometry>
			<origin xyz="-0.001974 0.0023889999999999996 0.03" rpy="0 0 0"></origin>
		</collision>
		<collision>
			<geometry>
				<sphere radius="0.005822"></sphere>
			</geometry>
			<origin xyz="-0.003256 -0.013027 -0.001" rpy="0 0 0"></origin>
		</collision>
		<collision>
			<geometry>
				<sphere radius="0.006464"></sphere>
			</geometry>
			<origin xyz="0.00382 -0.011789 -0.001" rpy="0 0 0"></origin>
		</collision>
		<collision>
			<geometry>
				<sphere radius="0.005801"></sphere>
			</geometry>
			<origin xyz="-0.003284 -0.0046440000000000006 -0.001" rpy="0 0 0"></origin>
		</collision>
		<collision>
			<geometry>
				<sphere radius="0.006366"></sphere>
			</geometry>
			<origin xyz="0.004645 -0.0005660000000000014 -0.001" rpy="0 0 0"></origin>
		</collision>
		<collision>
			<geometry>
				<sphere radius="0.006017"></sphere>
			</geometry>
			<origin xyz="-0.001974 0.0023889999999999996 -0.001" rpy="0 0 0"></origin>
		</collision>
		<collision>
			<geometry>
				<sphere radius="0.019248"></sphere>
			</geometry>
			<origin xyz="-0.0007842649999999995 -0.03298935 0.01451365" rpy="0 0 0"></origin>
		</collision>
		<inertial>
			<origin xyz="0 0 0" rpy="0 0 0"></origin>
			<mass value="0.016"></mass>
			<inertia ixx="0.000003368" ixy="0.000000115" ixz="0" iyy="0.000001556" iyz="0" izz="0.000002863"></inertia>
		</inertial>
	</link>
	<link name="mcp_joint_2">
		<visual>
			<origin xyz="0.0084069022611744960438 0.0077662438597169954416 0.014657354985032913786" rpy="1.6375789613220999807e-15 -1.0076465469034000467e-30 2.1209300131419907151e-61"></origin>
			<geometry>
				<mesh filename="leap_hand/mcp_joint.stl"></mesh>
			</geometry>
			<material name="mcp_joint_1_material">
				<color rgba="0.86666666666666669627 0.86666666666666669627 0.050980392156862744391 1.0"></color>
			</material>
		</visual>
		<collision>
			<geometry>
				<sphere radius="0.008567"></sphere>
			</geometry>
			<origin xyz="-0.003739 0.018 0.026747" rpy="0 0 0"></origin>
		</collision>
		<collision>
			<geometry>
				<sphere radius="0.009493"></sphere>
			</geometry>
			<origin xyz="0.006494 0.018 0.023403" rpy="0 0 0"></origin>
		</collision>
		<collision>
			<geometry>
				<sphere radius="0.008916"></sphere>
			</geometry>
			<origin xyz="-0.005154 0.017998999999999998 0.014528999999999999" rpy="0 0 0"></origin>
		</collision>
		<collision>
			<geometry>
				<sphere radius="0.009578"></sphere>
			</geometry>
			<origin xyz="0.006998 0.018 0.006285999999999998" rpy="0 0 0"></origin>
		</collision>
		<collision>
			<geometry>
				<sphere radius="0.008954"></sphere>
			</geometry>
			<origin xyz="-0.003105 0.018 0.0025279999999999973" rpy="0 0 0"></origin>
		</collision>
		<collision>
			<geometry>
				<sphere radius="0.0199"></sphere>
			</geometry>
			<origin xyz="-0.027001 0.031999 0.015" rpy="0 0 0"></origin>
		</collision>
		<collision>
			<geometry>
				<sphere radius="0.0199"></sphere>
			</geometry>
			<origin xyz="-0.026999 0.052001000000000006 0.015" rpy="0 0 0"></origin>
		</collision>
		<collision>
			<geometry>
				<sphere radius="0.009333"></sphere>
			</geometry>
			<origin xyz="-0.036193 0.02 0.019267" rpy="0 0 0"></origin>
		</collision>
		<collision>
			<geometry>
				<sphere radius="0.009593"></sphere>
			</geometry>
			<origin xyz="-0.03524 0.02 0.009028999999999999" rpy="0 0 0"></origin>
		</collision>
		<collision>
			<geometry>
				<sphere radius="0.008799"></sphere>
			</geometry>
			<origin xyz="-0.02314 0.02 0.018738" rpy="0 0 0"></origin>
		</collision>
		<collision>
			<geometry>
				<sphere radius="0.009856"></sphere>
			</geometry>
			<origin xyz="-0.018096 0.02 0.007599" rpy="0 0 0"></origin>
		</collision>
		<collision>
			<geometry>
				<sphere radius="0.009171"></sphere>
			</geometry>
			<origin xyz="-0.013073000000000001 0.02 0.016885" rpy="0 0 0"></origin>
		</collision>
		<collision>
			<geometry>
				<sphere radius="0.011518"></sphere>
			</geometry>
			<origin xyz="-0.0295 0.042919000000000006 0.029" rpy="0 0 0"></origin>
		</collision>
		<collision>
			<geometry>
				<sphere radius="0.010394"></sphere>
			</geometry>
			<origin xyz="-0.025256999999999998 0.030674000000000003 0.029" rpy="0 0 0"></origin>
		</collision>
		<collision>
			<geometry>
				<sphere radius="0.009557"></sphere>
			</geometry>
			<origin xyz="-0.035439 0.030670000000000003 0.029" rpy="0 0 0"></origin>
		</collision>
		<collision>
			<geometry>
				<sphere radius="0.006279"></sphere>
			</geometry>
			<origin xyz="0.003189 -0.00046400000000000087 0.03" rpy="0 0 0"></origin>
		</collision>
		<collision>
			<geometry>
				<sphere radius="0.006312"></sphere>
			</geometry>
			<origin xyz="-0.003949 0.0001449999999999993 0.03" rpy="0 0 0"></origin>
		</collision>
		<collision>
			<geometry>
				<sphere radius="0.006229"></sphere>
			</geometry>
			<origin xyz="-0.003375 0.010346 0.03" rpy="0 0 0"></origin>
		</collision>
		<collision>
			<geometry>
				<sphere radius="0.006615"></sphere>
			</geometry>
			<origin xyz="0.003682 0.009655 0.03" rpy="0 0 0"></origin>
		</collision>
		<collision>
			<geometry>
				<sphere radius="0.006279"></sphere>
			</geometry>
			<origin xyz="0.003189 -0.00046400000000000087 -0.001" rpy="0 0 0"></origin>
		</collision>
		<collision>
			<geometry>
				<sphere radius="0.006312"></sphere>
			</geometry>
			<origin xyz="-0.003949 0.0001449999999999993 -0.001" rpy="0 0 0"></origin>
		</collision>
		<collision>
			<geometry>
				<sphere radius="0.006229"></sphere>
			</geometry>
			<origin xyz="-0.003375 0.010346 -0.001" rpy="0 0 0"></origin>
		</collision>
		<collision>
			<geometry>
				<sphere radius="0.006615"></sphere>
			</geometry>
			<origin xyz="0.003682 0.009655 -0.001" rpy="0 0 0"></origin>
		</collision>
		<inertial>
			<origin xyz="0 0 0" rpy="0 0 0"></origin>
			<mass value="0.044"></mass>
			<inertia ixx="0.000011499" ixy="0.000003049" ixz="0.000000121" iyy="0.000007796" iyz="0.000000112" izz="0.000014759"></inertia>
		</inertial>
	</link>
	<link name="pip_2">
		<visual>
			<origin xyz="0.0096433630922713280131 0.00029999999999999471534 0.00078403401041737645627" rpy="-1.570796326794896558 -1.570796326794896336 0"></origin>
			<geometry>
				<mesh filename="leap_hand/pip.stl"></mesh>
			</geometry>
			<material name="pip_1_material">
				<color rgba="0.74901960784313725839 0.74901960784313725839 0.74901960784313725839 1.0"></color>
			</material>
		</visual>
		<collision>
			<geometry>
				<sphere radius="0.020274"></sphere>
			</geometry>
			<origin xyz="0.0015009999999999997 -0.00020000000000000052 -0.011" rpy="0 0 0"></origin>
		</collision>
		<collision>
			<geometry>
				<sphere radius="0.020273"></sphere>
			</geometry>
			<origin xyz="0.013500999999999999 -0.00020000000000000052 -0.010999" rpy="0 0 0"></origin>
		</collision>
		<inertial>
			<origin xyz="0 0 0" rpy="0 0 0"></origin>
			<mass value="0.032"></mass>
			<inertia ixx="0.000004798" ixy="0.000000012" ixz="0.000000004" iyy="0.000002862" iyz="0.000000011" izz="0.000004234"></inertia>
		</inertial>
	</link>
	<link name="dip_2">
		<visual>
			<origin xyz="0.021133352895225002849 -0.0084321191467048653423 0.0097850881620952373519" rpy="-3.141592653589793116 2.1146933785271955805e-32 1.4408183216511868558e-31"></origin>
			<geometry>
				<mesh filename="leap_hand/dip.stl"></mesh>
			</geometry>
			<material name="dip_1_material">
				<color rgba="0.86666666666666669627 0.86666666666666669627 0.050980392156862744391 1.0"></color>
			</material>
		</visual>
		<collision>
			<geometry>
				<sphere radius="0.007791"></sphere>
			</geometry>
			<origin xyz="-0.003656 -0.02 0.022271" rpy="0 0 0"></origin>
		</collision>
		<collision>
			<geometry>
				<sphere radius="0.00826"></sphere>
			</geometry>
			<origin xyz="0.004477 -0.02 0.021214999999999998" rpy="0 0 0"></origin>
		</collision>
		<collision>
			<geometry>
				<sphere radius="0.008131"></sphere>
			</geometry>
			<origin xyz="0.003347 -0.02 0.007914" rpy="0 0 0"></origin>
		</collision>
		<collision>
			<geometry>
				<sphere radius="0.008407"></sphere>
			</geometry>
			<origin xyz="-0.004874 -0.02 0.009187" rpy="0 0 0"></origin>
		</collision>
		<collision>
			<geometry>
				<sphere radius="0.006739"></sphere>
			</geometry>
			<origin xyz="0.00553 -0.016 0.027371" rpy="0 0 0"></origin>
		</collision>
		<collision>
			<geometry>
				<sphere radius="0.006714"></sphere>
			</geometry>
			<origin xyz="-0.004669 -0.016 0.028471999999999997" rpy="0 0 0"></origin>
		</collision>
		<collision>
			<geometry>
				<sphere radius="0.006907"></sphere>
			</geometry>
			<origin xyz="-0.005092 -0.016 0.020145" rpy="0 0 0"></origin>
		</collision>
		<collision>
			<geometry>
				<sphere radius="0.007083"></sphere>
			</geometry>
			<origin xyz="0.006365 -0.016 0.017072" rpy="0 0 0"></origin>
		</collision>
		<collision>
			<geometry>
				<sphere radius="0.0069"></sphere>
			</geometry>
			<origin xyz="-0.005261 -0.016 0.010866999999999998" rpy="0 0 0"></origin>
		</collision>
		<collision>
			<geometry>
				<sphere radius="0.006504"></sphere>
			</geometry>
			<origin xyz="0.004918 -0.016 0.007208999999999999" rpy="0 0 0"></origin>
		</collision>
		<collision>
			<geometry>
				<sphere radius="0.006329"></sphere>
			</geometry>
			<origin xyz="-0.005632 -0.016 0.0021199999999999986" rpy="0 0 0"></origin>
		</collision>
		<collision>
			<geometry>
				<sphere radius="0.006527"></sphere>
			</geometry>
			<origin xyz="0.00448 -0.016 0.0008039999999999992" rpy="0 0 0"></origin>
		</collision>
		<collision>
			<geometry>
				<sphere radius="0.006279"></sphere>
			</geometry>
			<origin xyz="0.003189 -0.009963999999999999 0.03" rpy="0 0 0"></origin>
		</collision>
		<collision>
			<geometry>
				<sphere radius="0.006312"></sphere>
			</geometry>
			<origin xyz="-0.003949 -0.009354999999999999 0.03" rpy="0 0 0"></origin>
		</collision>
		<collision>
			<geometry>
				<sphere radius="0.006229"></sphere>
			</geometry>
			<origin xyz="-0.003375 0.0008460000000000013 0.03" rpy="0 0 0"></origin>
		</collision>
		<collision>
			<geometry>
				<sphere radius="0.006615"></sphere>
			</geometry>
			<origin xyz="0.003682 0.0001550000000000015 0.03" rpy="0 0 0"></origin>
		</collision>
		<collision>
			<geometry>
				<sphere radius="0.006279"></sphere>
			</geometry>
			<origin xyz="0.003189 -0.009963999999999999 0.0" rpy="0 0 0"></origin>
		</collision>
		<collision>
			<geometry>
				<sphere radius="0.006312"></sphere>
			</geometry>
			<origin xyz="-0.003949 -0.009354999999999999 0.0" rpy="0 0 0"></origin>
		</collision>
		<collision>
			<geometry>
				<sphere radius="0.006229"></sphere>
			</geometry>
			<origin xyz="-0.003375 0.0008460000000000013 0.0" rpy="0 0 0"></origin>
		</collision>
		<collision>
			<geometry>
				<sphere radius="0.006615"></sphere>
			</geometry>
			<origin xyz="0.003682 0.0001550000000000015 0.0" rpy="0 0 0"></origin>
		</collision>
		<collision>
			<geometry>
				<sphere radius="0.020274"></sphere>
			</geometry>
			<origin xyz="0.0014999999999999996 -0.035001000000000004 0.015" rpy="0 0 0"></origin>
		</collision>
		<collision>
			<geometry>
				<sphere radius="0.020273"></sphere>
			</geometry>
			<origin xyz="0.0135 -0.035 0.014999" rpy="0 0 0"></origin>
		</collision>
		<inertial>
			<origin xyz="0 0 0" rpy="0 0 0"></origin>
			<mass value="0.037"></mass>
			<inertia ixx="0.000005542" ixy="-0.000000607" ixz="-0.000000017" iyy="0.000005727" iyz="-0.000000023" izz="0.000006682"></inertia>
		</inertial>
	</link>
	<link name="fingertip_2">
		<visual>
			<origin xyz="0.01328642410853349623 -0.0061142383865420008027 0.014499999999999495931" rpy="3.141592653589793116 -4.3179597882835943107e-33 1.4408183216511868558e-31"></origin>
			<geometry>
				<mesh filename="leap_hand/fingertip.stl"></mesh>
			</geometry>
			<material name="fingertip_1_material">
				<color rgba="0.86666666666666669627 0.86666666666666669627 0.050980392156862744391 1.0"></color>
			</material>
		</visual>
		<collision>
			<geometry>
				<sphere radius="0.009519"></sphere>
			</geometry>
			<origin xyz="0.003799 -0.017 0.006543" rpy="0 0 0"></origin>
		</collision>
		<collision>
			<geometry>
				<sphere radius="0.009911"></sphere>
			</geometry>
			<origin xyz="-0.006462 -0.017 0.008712" rpy="0 0 0"></origin>
		</collision>
		<collision>
			<geometry>
				<sphere radius="0.00922"></sphere>
			</geometry>
			<origin xyz="-0.003787 -0.017 0.023887" rpy="0 0 0"></origin>
		</collision>
		<collision>
			<geometry>
				<sphere radius="0.009556"></sphere>
			</geometry>
			<origin xyz="0.006409 -0.017 0.021671" rpy="0 0 0"></origin>
		</collision>
		<collision>
			<geometry>
				<sphere radius="0.005822"></sphere>
			</geometry>
			<origin xyz="-0.003256 -0.013027 0.03" rpy="0 0 0"></origin>
		</collision>
		<collision>
			<geometry>
				<sphere radius="0.006464"></sphere>
			</geometry>
			<origin xyz="0.00382 -0.011789 0.03" rpy="0 0 0"></origin>
		</collision>
		<collision>
			<geometry>
				<sphere radius="0.005801"></sphere>
			</geometry>
			<origin xyz="-0.003284 -0.0046440000000000006 0.03" rpy="0 0 0"></origin>
		</collision>
		<collision>
			<geometry>
				<sphere radius="0.006366"></sphere>
			</geometry>
			<origin xyz="0.004645 -0.0005660000000000014 0.03" rpy="0 0 0"></origin>
		</collision>
		<collision>
			<geometry>
				<sphere radius="0.006017"></sphere>
			</geometry>
			<origin xyz="-0.001974 0.0023889999999999996 0.03" rpy="0 0 0"></origin>
		</collision>
		<collision>
			<geometry>
				<sphere radius="0.005822"></sphere>
			</geometry>
			<origin xyz="-0.003256 -0.013027 -0.001" rpy="0 0 0"></origin>
		</collision>
		<collision>
			<geometry>
				<sphere radius="0.006464"></sphere>
			</geometry>
			<origin xyz="0.00382 -0.011789 -0.001" rpy="0 0 0"></origin>
		</collision>
		<collision>
			<geometry>
				<sphere radius="0.005801"></sphere>
			</geometry>
			<origin xyz="-0.003284 -0.0046440000000000006 -0.001" rpy="0 0 0"></origin>
		</collision>
		<collision>
			<geometry>
				<sphere radius="0.006366"></sphere>
			</geometry>
			<origin xyz="0.004645 -0.0005660000000000014 -0.001" rpy="0 0 0"></origin>
		</collision>
		<collision>
			<geometry>
				<sphere radius="0.006017"></sphere>
			</geometry>
			<origin xyz="-0.001974 0.0023889999999999996 -0.001" rpy="0 0 0"></origin>
		</collision>
		<collision>
			<geometry>
				<sphere radius="0.019248"></sphere>
			</geometry>
			<origin xyz="-0.0007842649999999995 -0.03298935 0.01451365" rpy="0 0 0"></origin>
		</collision>
		<inertial>
			<origin xyz="0 0 0" rpy="0 0 0"></origin>
			<mass value="0.016"></mass>
			<inertia ixx="0.000003368" ixy="0.000000115" ixz="0" iyy="0.000001556" iyz="0" izz="0.000002863"></inertia>
		</inertial>
	</link>
	<link name="mcp_joint_3">
		<visual>
			<origin xyz="0.0084069022611744995133 0.0077662438597169963089 0.014657354985032913786" rpy="1.6375789613220999807e-15 -1.0059504988632626953e-30 5.729641584552035421e-32"></origin>
			<geometry>
				<mesh filename="leap_hand/mcp_joint.stl"></mesh>
			</geometry>
			<material name="mcp_joint_1_material">
				<color rgba="0.86666666666666669627 0.86666666666666669627 0.050980392156862744391 1.0"></color>
			</material>
		</visual>
		<collision>
			<geometry>
				<sphere radius="0.008567"></sphere>
			</geometry>
			<origin xyz="-0.003739 0.018 0.026747" rpy="0 0 0"></origin>
		</collision>
		<collision>
			<geometry>
				<sphere radius="0.009493"></sphere>
			</geometry>
			<origin xyz="0.006494 0.018 0.023403" rpy="0 0 0"></origin>
		</collision>
		<collision>
			<geometry>
				<sphere radius="0.008916"></sphere>
			</geometry>
			<origin xyz="-0.005154 0.017998999999999998 0.014528999999999999" rpy="0 0 0"></origin>
		</collision>
		<collision>
			<geometry>
				<sphere radius="0.009578"></sphere>
			</geometry>
			<origin xyz="0.006998 0.018 0.006285999999999998" rpy="0 0 0"></origin>
		</collision>
		<collision>
			<geometry>
				<sphere radius="0.008954"></sphere>
			</geometry>
			<origin xyz="-0.003105 0.018 0.0025279999999999973" rpy="0 0 0"></origin>
		</collision>
		<collision>
			<geometry>
				<sphere radius="0.0199"></sphere>
			</geometry>
			<origin xyz="-0.027001 0.031999 0.015" rpy="0 0 0"></origin>
		</collision>
		<collision>
			<geometry>
				<sphere radius="0.0199"></sphere>
			</geometry>
			<origin xyz="-0.026999 0.052001000000000006 0.015" rpy="0 0 0"></origin>
		</collision>
		<collision>
			<geometry>
				<sphere radius="0.009333"></sphere>
			</geometry>
			<origin xyz="-0.036193 0.02 0.019267" rpy="0 0 0"></origin>
		</collision>
		<collision>
			<geometry>
				<sphere radius="0.009593"></sphere>
			</geometry>
			<origin xyz="-0.03524 0.02 0.009028999999999999" rpy="0 0 0"></origin>
		</collision>
		<collision>
			<geometry>
				<sphere radius="0.008799"></sphere>
			</geometry>
			<origin xyz="-0.02314 0.02 0.018738" rpy="0 0 0"></origin>
		</collision>
		<collision>
			<geometry>
				<sphere radius="0.009856"></sphere>
			</geometry>
			<origin xyz="-0.018096 0.02 0.007599" rpy="0 0 0"></origin>
		</collision>
		<collision>
			<geometry>
				<sphere radius="0.009171"></sphere>
			</geometry>
			<origin xyz="-0.013073000000000001 0.02 0.016885" rpy="0 0 0"></origin>
		</collision>
		<collision>
			<geometry>
				<sphere radius="0.011518"></sphere>
			</geometry>
			<origin xyz="-0.0295 0.042919000000000006 0.029" rpy="0 0 0"></origin>
		</collision>
		<collision>
			<geometry>
				<sphere radius="0.010394"></sphere>
			</geometry>
			<origin xyz="-0.025256999999999998 0.030674000000000003 0.029" rpy="0 0 0"></origin>
		</collision>
		<collision>
			<geometry>
				<sphere radius="0.009557"></sphere>
			</geometry>
			<origin xyz="-0.035439 0.030670000000000003 0.029" rpy="0 0 0"></origin>
		</collision>
		<collision>
			<geometry>
				<sphere radius="0.006279"></sphere>
			</geometry>
			<origin xyz="0.003189 -0.00046400000000000087 0.03" rpy="0 0 0"></origin>
		</collision>
		<collision>
			<geometry>
				<sphere radius="0.006312"></sphere>
			</geometry>
			<origin xyz="-0.003949 0.0001449999999999993 0.03" rpy="0 0 0"></origin>
		</collision>
		<collision>
			<geometry>
				<sphere radius="0.006229"></sphere>
			</geometry>
			<origin xyz="-0.003375 0.010346 0.03" rpy="0 0 0"></origin>
		</collision>
		<collision>
			<geometry>
				<sphere radius="0.006615"></sphere>
			</geometry>
			<origin xyz="0.003682 0.009655 0.03" rpy="0 0 0"></origin>
		</collision>
		<collision>
			<geometry>
				<sphere radius="0.006279"></sphere>
			</geometry>
			<origin xyz="0.003189 -0.00046400000000000087 -0.001" rpy="0 0 0"></origin>
		</collision>
		<collision>
			<geometry>
				<sphere radius="0.006312"></sphere>
			</geometry>
			<origin xyz="-0.003949 0.0001449999999999993 -0.001" rpy="0 0 0"></origin>
		</collision>
		<collision>
			<geometry>
				<sphere radius="0.006229"></sphere>
			</geometry>
			<origin xyz="-0.003375 0.010346 -0.001" rpy="0 0 0"></origin>
		</collision>
		<collision>
			<geometry>
				<sphere radius="0.006615"></sphere>
			</geometry>
			<origin xyz="0.003682 0.009655 -0.001" rpy="0 0 0"></origin>
		</collision>
		<inertial>
			<origin xyz="0 0 0" rpy="0 0 0"></origin>
			<mass value="0.044"></mass>
			<inertia ixx="0.000011499" ixy="0.000003049" ixz="0.000000121" iyy="0.000007796" iyz="0.000000112" izz="0.000014759"></inertia>
		</inertial>
	</link>
	<link name="pip_3">
		<visual>
			<origin xyz="0.0096433630922713314826 0.00029999999999998083755 0.00078403401041737645627" rpy="-1.570796326794896558 -1.570796326794896336 0"></origin>
			<geometry>
				<mesh filename="leap_hand/pip.stl"></mesh>
			</geometry>
			<material name="pip_1_material">
				<color rgba="0.74901960784313725839 0.74901960784313725839 0.74901960784313725839 1.0"></color>
			</material>
		</visual>
		<collision>
			<geometry>
				<sphere radius="0.020274"></sphere>
			</geometry>
			<origin xyz="0.0015009999999999997 -0.00020000000000000052 -0.011" rpy="0 0 0"></origin>
		</collision>
		<collision>
			<geometry>
				<sphere radius="0.020273"></sphere>
			</geometry>
			<origin xyz="0.013500999999999999 -0.00020000000000000052 -0.010999" rpy="0 0 0"></origin>
		</collision>
		<inertial>
			<origin xyz="0 0 0" rpy="0 0 0"></origin>
			<mass value="0.032"></mass>
			<inertia ixx="0.000004798" ixy="0.000000012" ixz="0.000000004" iyy="0.000002862" iyz="0.000000011" izz="0.000004234"></inertia>
		</inertial>
	</link>
	<link name="dip_3">
		<visual>
			<origin xyz="0.021133352895225006318 -0.0084321191467048653423 0.0097850881620952373519" rpy="-3.141592653589793116 -1.4095651113919093005e-33 1.5565411607615035382e-32"></origin>
			<geometry>
				<mesh filename="leap_hand/dip.stl"></mesh>
			</geometry>
			<material name="dip_1_material">
				<color rgba="0.86666666666666669627 0.86666666666666669627 0.050980392156862744391 1.0"></color>
			</material>
		</visual>
		<collision>
			<geometry>
				<sphere radius="0.007791"></sphere>
			</geometry>
			<origin xyz="-0.003656 -0.02 0.022271" rpy="0 0 0"></origin>
		</collision>
		<collision>
			<geometry>
				<sphere radius="0.00826"></sphere>
			</geometry>
			<origin xyz="0.004477 -0.02 0.021214999999999998" rpy="0 0 0"></origin>
		</collision>
		<collision>
			<geometry>
				<sphere radius="0.008131"></sphere>
			</geometry>
			<origin xyz="0.003347 -0.02 0.007914" rpy="0 0 0"></origin>
		</collision>
		<collision>
			<geometry>
				<sphere radius="0.008407"></sphere>
			</geometry>
			<origin xyz="-0.004874 -0.02 0.009187" rpy="0 0 0"></origin>
		</collision>
		<collision>
			<geometry>
				<sphere radius="0.006739"></sphere>
			</geometry>
			<origin xyz="0.00553 -0.016 0.027371" rpy="0 0 0"></origin>
		</collision>
		<collision>
			<geometry>
				<sphere radius="0.006714"></sphere>
			</geometry>
			<origin xyz="-0.004669 -0.016 0.028471999999999997" rpy="0 0 0"></origin>
		</collision>
		<collision>
			<geometry>
				<sphere radius="0.006907"></sphere>
			</geometry>
			<origin xyz="-0.005092 -0.016 0.020145" rpy="0 0 0"></origin>
		</collision>
		<collision>
			<geometry>
				<sphere radius="0.007083"></sphere>
			</geometry>
			<origin xyz="0.006365 -0.016 0.017072" rpy="0 0 0"></origin>
		</collision>
		<collision>
			<geometry>
				<sphere radius="0.0069"></sphere>
			</geometry>
			<origin xyz="-0.005261 -0.016 0.010866999999999998" rpy="0 0 0"></origin>
		</collision>
		<collision>
			<geometry>
				<sphere radius="0.006504"></sphere>
			</geometry>
			<origin xyz="0.004918 -0.016 0.007208999999999999" rpy="0 0 0"></origin>
		</collision>
		<collision>
			<geometry>
				<sphere radius="0.006329"></sphere>
			</geometry>
			<origin xyz="-0.005632 -0.016 0.0021199999999999986" rpy="0 0 0"></origin>
		</collision>
		<collision>
			<geometry>
				<sphere radius="0.006527"></sphere>
			</geometry>
			<origin xyz="0.00448 -0.016 0.0008039999999999992" rpy="0 0 0"></origin>
		</collision>
		<collision>
			<geometry>
				<sphere radius="0.006279"></sphere>
			</geometry>
			<origin xyz="0.003189 -0.009963999999999999 0.03" rpy="0 0 0"></origin>
		</collision>
		<collision>
			<geometry>
				<sphere radius="0.006312"></sphere>
			</geometry>
			<origin xyz="-0.003949 -0.009354999999999999 0.03" rpy="0 0 0"></origin>
		</collision>
		<collision>
			<geometry>
				<sphere radius="0.006229"></sphere>
			</geometry>
			<origin xyz="-0.003375 0.0008460000000000013 0.03" rpy="0 0 0"></origin>
		</collision>
		<collision>
			<geometry>
				<sphere radius="0.006615"></sphere>
			</geometry>
			<origin xyz="0.003682 0.0001550000000000015 0.03" rpy="0 0 0"></origin>
		</collision>
		<collision>
			<geometry>
				<sphere radius="0.006279"></sphere>
			</geometry>
			<origin xyz="0.003189 -0.009963999999999999 0.0" rpy="0 0 0"></origin>
		</collision>
		<collision>
			<geometry>
				<sphere radius="0.006312"></sphere>
			</geometry>
			<origin xyz="-0.003949 -0.009354999999999999 0.0" rpy="0 0 0"></origin>
		</collision>
		<collision>
			<geometry>
				<sphere radius="0.006229"></sphere>
			</geometry>
			<origin xyz="-0.003375 0.0008460000000000013 0.0" rpy="0 0 0"></origin>
		</collision>
		<collision>
			<geometry>
				<sphere radius="0.006615"></sphere>
			</geometry>
			<origin xyz="0.003682 0.0001550000000000015 0.0" rpy="0 0 0"></origin>
		</collision>
		<collision>
			<geometry>
				<sphere radius="0.020274"></sphere>
			</geometry>
			<origin xyz="0.0014999999999999996 -0.035001000000000004 0.015" rpy="0 0 0"></origin>
		</collision>
		<collision>
			<geometry>
				<sphere radius="0.020273"></sphere>
			</geometry>
			<origin xyz="0.0135 -0.035 0.014999" rpy="0 0 0"></origin>
		</collision>
		<inertial>
			<origin xyz="0 0 0" rpy="0 0 0"></origin>
			<mass value="0.037"></mass>
			<inertia ixx="0.000005542" ixy="-0.000000607" ixz="-0.000000017" iyy="0.000005727" iyz="-0.000000023" izz="0.000006682"></inertia>
		</inertial>
	</link>
	<link name="fingertip_3">
		<visual>
			<origin xyz="0.013286424108533501434 -0.0061142383865419869249 0.0144999999999994994" rpy="3.141592653589793116 8.6170716950575402125e-33 1.5565411607615035382e-32"></origin>
			<geometry>
				<mesh filename="leap_hand/fingertip.stl"></mesh>
			</geometry>
			<material name="fingertip_1_material">
				<color rgba="0.86666666666666669627 0.86666666666666669627 0.050980392156862744391 1.0"></color>
			</material>
		</visual>
		<collision>
			<geometry>
				<sphere radius="0.009519"></sphere>
			</geometry>
			<origin xyz="0.003799 -0.017 0.006543" rpy="0 0 0"></origin>
		</collision>
		<collision>
			<geometry>
				<sphere radius="0.009911"></sphere>
			</geometry>
			<origin xyz="-0.006462 -0.017 0.008712" rpy="0 0 0"></origin>
		</collision>
		<collision>
			<geometry>
				<sphere radius="0.00922"></sphere>
			</geometry>
			<origin xyz="-0.003787 -0.017 0.023887" rpy="0 0 0"></origin>
		</collision>
		<collision>
			<geometry>
				<sphere radius="0.009556"></sphere>
			</geometry>
			<origin xyz="0.006409 -0.017 0.021671" rpy="0 0 0"></origin>
		</collision>
		<collision>
			<geometry>
				<sphere radius="0.005822"></sphere>
			</geometry>
			<origin xyz="-0.003256 -0.013027 0.03" rpy="0 0 0"></origin>
		</collision>
		<collision>
			<geometry>
				<sphere radius="0.006464"></sphere>
			</geometry>
			<origin xyz="0.00382 -0.011789 0.03" rpy="0 0 0"></origin>
		</collision>
		<collision>
			<geometry>
				<sphere radius="0.005801"></sphere>
			</geometry>
			<origin xyz="-0.003284 -0.0046440000000000006 0.03" rpy="0 0 0"></origin>
		</collision>
		<collision>
			<geometry>
				<sphere radius="0.006366"></sphere>
			</geometry>
			<origin xyz="0.004645 -0.0005660000000000014 0.03" rpy="0 0 0"></origin>
		</collision>
		<collision>
			<geometry>
				<sphere radius="0.006017"></sphere>
			</geometry>
			<origin xyz="-0.001974 0.0023889999999999996 0.03" rpy="0 0 0"></origin>
		</collision>
		<collision>
			<geometry>
				<sphere radius="0.005822"></sphere>
			</geometry>
			<origin xyz="-0.003256 -0.013027 -0.001" rpy="0 0 0"></origin>
		</collision>
		<collision>
			<geometry>
				<sphere radius="0.006464"></sphere>
			</geometry>
			<origin xyz="0.00382 -0.011789 -0.001" rpy="0 0 0"></origin>
		</collision>
		<collision>
			<geometry>
				<sphere radius="0.005801"></sphere>
			</geometry>
			<origin xyz="-0.003284 -0.0046440000000000006 -0.001" rpy="0 0 0"></origin>
		</collision>
		<collision>
			<geometry>
				<sphere radius="0.006366"></sphere>
			</geometry>
			<origin xyz="0.004645 -0.0005660000000000014 -0.001" rpy="0 0 0"></origin>
		</collision>
		<collision>
			<geometry>
				<sphere radius="0.006017"></sphere>
			</geometry>
			<origin xyz="-0.001974 0.0023889999999999996 -0.001" rpy="0 0 0"></origin>
		</collision>
		<collision>
			<geometry>
				<sphere radius="0.019248"></sphere>
			</geometry>
			<origin xyz="-0.0007842649999999995 -0.03298935 0.01451365" rpy="0 0 0"></origin>
		</collision>
		<inertial>
			<origin xyz="0 0 0" rpy="0 0 0"></origin>
			<mass value="0.016"></mass>
			<inertia ixx="0.000003368" ixy="0.000000115" ixz="0" iyy="0.000001556" iyz="0" izz="0.000002863"></inertia>
		</inertial>
	</link>
	<link name="pip_4">
		<visual>
			<origin xyz="-0.0053566369077286714317 0.00029999999999999991951 0.00078403401041737819099" rpy="-1.570796326794896558 -1.570796326794896336 0"></origin>
			<geometry>
				<mesh filename="leap_hand/pip.stl"></mesh>
			</geometry>
			<material name="pip_1_material">
				<color rgba="0.74901960784313725839 0.74901960784313725839 0.74901960784313725839 1.0"></color>
			</material>
		</visual>
		<collision>
			<geometry>
				<sphere radius="0.020274"></sphere>
			</geometry>
			<origin xyz="0.0015009999999999997 -0.00020000000000000052 -0.011" rpy="0 0 0"></origin>
		</collision>
		<collision>
			<geometry>
				<sphere radius="0.020273"></sphere>
			</geometry>
			<origin xyz="0.013500999999999999 -0.00020000000000000052 -0.010999" rpy="0 0 0"></origin>
		</collision>
		<inertial>
			<origin xyz="0 0 0" rpy="0 0 0"></origin>
			<mass value="0.032"></mass>
			<inertia ixx="0.000004798" ixy="0.000000012" ixz="0.000000004" iyy="0.000002862" iyz="0.000000011" izz="0.000004234"></inertia>
		</inertial>
	</link>
	<link name="thumb_pip">
		<visual>
			<origin xyz="0.011961920770611186859 -5.3082538364890297089e-16 -0.015852648956664199681" rpy="1.570796326794896558 1.6050198443300152637e-46 -3.9204996250525192755e-59"></origin>
			<geometry>
				<mesh filename="leap_hand/thumb_pip.stl"></mesh>
			</geometry>
			<material name="thumb_pip_material">
				<color rgba="0.86666666666666669627 0.86666666666666669627 0.050980392156862744391 1.0"></color>
			</material>
		</visual>
		<collision>
			<geometry>
				<sphere radius="0.006535"></sphere>
			</geometry>
			<origin xyz="0.004401 0.004301 -0.0015" rpy="0 0 0"></origin>
		</collision>
		<collision>
			<geometry>
				<sphere radius="0.006299"></sphere>
			</geometry>
			<origin xyz="-0.004461 -0.012631 -0.0015" rpy="0 0 0"></origin>
		</collision>
		<collision>
			<geometry>
				<sphere radius="0.006324"></sphere>
			</geometry>
			<origin xyz="-0.004508 0.006102 -0.0015" rpy="0 0 0"></origin>
		</collision>
		<collision>
			<geometry>
				<sphere radius="0.005614"></sphere>
			</geometry>
			<origin xyz="0.005552 0.012547 -0.0015" rpy="0 0 0"></origin>
		</collision>
		<collision>
			<geometry>
				<sphere radius="0.006342"></sphere>
			</geometry>
			<origin xyz="-0.005628 -0.003209 -0.0015" rpy="0 0 0"></origin>
		</collision>
		<collision>
			<geometry>
				<sphere radius="0.006281"></sphere>
			</geometry>
			<origin xyz="0.004752 -0.012366 -0.0015" rpy="0 0 0"></origin>
		</collision>
		<collision>
			<geometry>
				<sphere radius="0.006371"></sphere>
			</geometry>
			<origin xyz="-0.003716 0.013577 -0.0015" rpy="0 0 0"></origin>
		</collision>
		<collision>
			<geometry>
				<sphere radius="0.006486"></sphere>
			</geometry>
			<origin xyz="0.004003 -0.004061 -0.0015" rpy="0 0 0"></origin>
		</collision>
		<collision>
			<geometry>
				<sphere radius="0.006767"></sphere>
			</geometry>
			<origin xyz="0.002056 -0.015 -0.007150999999999999" rpy="0 0 0"></origin>
		</collision>
		<collision>
			<geometry>
				<sphere radius="0.006156"></sphere>
			</geometry>
			<origin xyz="-0.002656 -0.015 -0.019151" rpy="0 0 0"></origin>
		</collision>
		<collision>
			<geometry>
				<sphere radius="0.006637"></sphere>
			</geometry>
			<origin xyz="0.004444 -0.015 -0.017227" rpy="0 0 0"></origin>
		</collision>
		<collision>
			<geometry>
				<sphere radius="0.006677"></sphere>
			</geometry>
			<origin xyz="-0.004976 -0.015 -0.00904" rpy="0 0 0"></origin>
		</collision>
		<collision>
			<geometry>
				<sphere radius="0.006767"></sphere>
			</geometry>
			<origin xyz="0.002056 0.015 -0.007150999999999999" rpy="0 0 0"></origin>
		</collision>
		<collision>
			<geometry>
				<sphere radius="0.006156"></sphere>
			</geometry>
			<origin xyz="-0.002656 0.015 -0.019151" rpy="0 0 0"></origin>
		</collision>
		<collision>
			<geometry>
				<sphere radius="0.006637"></sphere>
			</geometry>
			<origin xyz="0.004444 0.015 -0.017227" rpy="0 0 0"></origin>
		</collision>
		<collision>
			<geometry>
				<sphere radius="0.006677"></sphere>
			</geometry>
			<origin xyz="-0.004976 0.015 -0.00904" rpy="0 0 0"></origin>
		</collision>
		<inertial>
			<origin xyz="0 0 0" rpy="0 0 0"></origin>
			<mass value="0.003"></mass>
			<inertia ixx="0.000000593" ixy="0" ixz="0" iyy="0.000000549" iyz="0" izz="0.000000224"></inertia>
		</inertial>
	</link>
	<link name="thumb_dip">
		<visual>
			<origin xyz="0.043968715707239175439 0.057952952973709198625 -0.0086286764493694757122" rpy="1.9428902930940098942e-16 3.2751579226442200773e-15 1.1123758529657360012e-46"></origin>
			<geometry>
				<mesh filename="leap_hand/thumb_dip.stl"></mesh>
			</geometry>
			<material name="thumb_dip_material">
				<color rgba="0.86666666666666669627 0.86666666666666669627 0.050980392156862744391 1.0"></color>
			</material>
		</visual>
		<collision>
			<geometry>
				<sphere radius="0.018547"></sphere>
			</geometry>
			<origin xyz="1e-06 0.0004989999999999994 -0.014000000000000002" rpy="0 0 0"></origin>
		</collision>
		<collision>
			<geometry>
				<sphere radius="0.018547"></sphere>
			</geometry>
			<origin xyz="1e-06 0.020501 -0.014001000000000001" rpy="0 0 0"></origin>
		</collision>
		<collision>
			<geometry>
				<sphere radius="0.007024"></sphere>
			</geometry>
			<origin xyz="-0.005091 0.031 -0.003608" rpy="0 0 0"></origin>
		</collision>
		<collision>
			<geometry>
				<sphere radius="0.006841"></sphere>
			</geometry>
			<origin xyz="0.004964 0.031 -0.003176" rpy="0 0 0"></origin>
		</collision>
		<collision>
			<geometry>
				<sphere radius="0.007262"></sphere>
			</geometry>
			<origin xyz="-0.005324 0.031 -0.01372" rpy="0 0 0"></origin>
		</collision>
		<collision>
			<geometry>
				<sphere radius="0.007227"></sphere>
			</geometry>
			<origin xyz="0.005379 0.031 -0.012823" rpy="0 0 0"></origin>
		</collision>
		<collision>
			<geometry>
				<sphere radius="0.007345"></sphere>
			</geometry>
			<origin xyz="-0.006144 0.031 -0.025077" rpy="0 0 0"></origin>
		</collision>
		<collision>
			<geometry>
				<sphere radius="0.006753"></sphere>
			</geometry>
			<origin xyz="0.004766 0.031 -0.022303999999999997" rpy="0 0 0"></origin>
		</collision>
		<collision>
			<geometry>
				<sphere radius="0.00714"></sphere>
			</geometry>
			<origin xyz="0.0035 0.031 -0.028824" rpy="0 0 0"></origin>
		</collision>
		<collision>
			<geometry>
				<sphere radius="0.006279"></sphere>
			</geometry>
			<origin xyz="0.003189 0.036536 0.001" rpy="0 0 0"></origin>
		</collision>
		<collision>
			<geometry>
				<sphere radius="0.006312"></sphere>
			</geometry>
			<origin xyz="-0.003949 0.037145000000000004 0.001" rpy="0 0 0"></origin>
		</collision>
		<collision>
			<geometry>
				<sphere radius="0.006229"></sphere>
			</geometry>
			<origin xyz="-0.003375 0.047346 0.001" rpy="0 0 0"></origin>
		</collision>
		<collision>
			<geometry>
				<sphere radius="0.006615"></sphere>
			</geometry>
			<origin xyz="0.003682 0.046655 0.001" rpy="0 0 0"></origin>
		</collision>
		<collision>
			<geometry>
				<sphere radius="0.006279"></sphere>
			</geometry>
			<origin xyz="0.003189 0.036536 -0.029" rpy="0 0 0"></origin>
		</collision>
		<collision>
			<geometry>
				<sphere radius="0.006312"></sphere>
			</geometry>
			<origin xyz="-0.003949 0.037145000000000004 -0.029" rpy="0 0 0"></origin>
		</collision>
		<collision>
			<geometry>
				<sphere radius="0.006229"></sphere>
			</geometry>
			<origin xyz="-0.003375 0.047346 -0.029" rpy="0 0 0"></origin>
		</collision>
		<collision>
			<geometry>
				<sphere radius="0.006615"></sphere>
			</geometry>
			<origin xyz="0.003682 0.046655 -0.029" rpy="0 0 0"></origin>
		</collision>
		<collision>
			<geometry>
				<sphere radius="0.011947"></sphere>
			</geometry>
			<origin xyz="-0.0135 0.023452 -0.011648" rpy="0 0 0"></origin>
		</collision>
		<collision>
			<geometry>
				<sphere radius="0.011886"></sphere>
			</geometry>
			<origin xyz="-0.0135 0.011412000000000002 -0.011674" rpy="0 0 0"></origin>
		</collision>
		<inertial>
			<origin xyz="0 0 0" rpy="0 0 0"></origin>
			<mass value="0.038"></mass>
			<inertia ixx="0.000008474" ixy="0.000000241" ixz="0.000000026" iyy="0.000003841" iyz="0.000000025" izz="0.000007679"></inertia>
		</inertial>
	</link>
	<link name="thumb_fingertip">
		<visual>
			<origin xyz="0.062559538462667388381 0.078459682911396988469 0.048992911807332215068" rpy="4.3790577010156367543e-47 -3.3306690738754701143e-16 1.2042408677791935383e-46"></origin>
			<geometry>
				<mesh filename="leap_hand/thumb_fingertip.stl"></mesh>
			</geometry>
			<material name="thumb_fingertip_material">
				<color rgba="0.60392156862745094426 0.14901960784313725283 0.14901960784313725283 1.0"></color>
			</material>
		</visual>
		<collision>
			<geometry>
				<sphere radius="0.018548"></sphere>
			</geometry>
			<origin xyz="0.0 -0.0165 -0.015" rpy="0 0 0"></origin>
		</collision>
		<collision>
			<geometry>
				<sphere radius="0.018547"></sphere>
			</geometry>
			<origin xyz="0.0 -0.0005000000000000004 -0.015" rpy="0 0 0"></origin>
		</collision>
		<collision>
			<geometry>
				<sphere radius="0.007167"></sphere>
			</geometry>
			<origin xyz="-0.004963 -0.029 -0.0036609999999999993" rpy="0 0 0"></origin>
		</collision>
		<collision>
			<geometry>
				<sphere radius="0.006794"></sphere>
			</geometry>
			<origin xyz="0.00523 -0.029 -0.0033949999999999987" rpy="0 0 0"></origin>
		</collision>
		<collision>
			<geometry>
				<sphere radius="0.006932"></sphere>
			</geometry>
			<origin xyz="0.003843 -0.029 -0.010821999999999998" rpy="0 0 0"></origin>
		</collision>
		<collision>
			<geometry>
				<sphere radius="0.007145"></sphere>
			</geometry>
			<origin xyz="-0.007195 -0.029 -0.014758999999999998" rpy="0 0 0"></origin>
		</collision>
		<collision>
			<geometry>
				<sphere radius="0.0067"></sphere>
			</geometry>
			<origin xyz="-0.004973 -0.029 -0.025105999999999996" rpy="0 0 0"></origin>
		</collision>
		<collision>
			<geometry>
				<sphere radius="0.006789"></sphere>
			</geometry>
			<origin xyz="0.004415 -0.029 -0.017151" rpy="0 0 0"></origin>
		</collision>
		<collision>
			<geometry>
				<sphere radius="0.006542"></sphere>
			</geometry>
			<origin xyz="0.005241 -0.029 -0.025019" rpy="0 0 0"></origin>
		</collision>
		<collision>
			<geometry>
				<sphere radius="0.011364"></sphere>
			</geometry>
			<origin xyz="0.015 -0.023846000000000003 -0.01151" rpy="0 0 0"></origin>
		</collision>
		<collision>
			<geometry>
				<sphere radius="0.009374"></sphere>
			</geometry>
			<origin xyz="0.015 -0.011575000000000002 -0.014589" rpy="0 0 0"></origin>
		</collision>
		<collision>
			<geometry>
				<sphere radius="0.01025"></sphere>
			</geometry>
			<origin xyz="0.015 -0.014047000000000002 -0.006501" rpy="0 0 0"></origin>
		</collision>
		<collision>
			<geometry>
				<sphere radius="0.019117"></sphere>
			</geometry>
			<origin xyz="-0.000828 -0.0449801 -0.014352875" rpy="0 0 0"></origin>
		</collision>
		<inertial>
			<origin xyz="0 0 0" rpy="0 0 0"></origin>
			<mass value="0.049"></mass>
			<inertia ixx="0.000020372" ixy="-0.000000489" ixz="-0.00000003" iyy="0.000004336" iyz="-0.000000097" izz="0.000019845"></inertia>
		</inertial>
	</link>
	<joint name="xarm7_joint1" type="revolute">
		<origin rpy="0 0 0" xyz="0 0 0.267"></origin>
		<parent link="link_base"></parent>
		<child link="link1"></child>
		<axis xyz="0 0 1"></axis>
		<limit effort="50" lower="-6.28318530718" upper="6.28318530718" velocity="3.14"></limit>
		<dynamics damping="10" friction="1"></dynamics>
	</joint>
	<joint name="xarm7_joint2" type="revolute">
		<origin rpy="-1.5708 0 0" xyz="0 0 0"></origin>
		<parent link="link1"></parent>
		<child link="link2"></child>
		<axis xyz="0 0 1"></axis>
		<limit effort="50" lower="-2.059" upper="2.0944" velocity="3.14"></limit>
		<dynamics damping="10" friction="1"></dynamics>
	</joint>
	<joint name="xarm7_joint3" type="revolute">
		<origin rpy="1.5708 0 0" xyz="0 -0.293 0"></origin>
		<parent link="link2"></parent>
		<child link="link3"></child>
		<axis xyz="0 0 1"></axis>
		<limit effort="30" lower="-6.28318530718" upper="6.28318530718" velocity="3.14"></limit>
		<dynamics damping="5" friction="1"></dynamics>
	</joint>
	<joint name="xarm7_joint4" type="revolute">
		<origin rpy="1.5708 0 0" xyz="0.0525 0 0"></origin>
		<parent link="link3"></parent>
		<child link="link4"></child>
		<axis xyz="0 0 1"></axis>
		<limit effort="30" lower="-0.19198" upper="3.927" velocity="3.14"></limit>
		<dynamics damping="5" friction="1"></dynamics>
	</joint>
	<joint name="xarm7_joint5" type="revolute">
		<origin rpy="1.5708 0 0" xyz="0.0775 -0.3425 0"></origin>
		<parent link="link4"></parent>
		<child link="link5"></child>
		<axis xyz="0 0 1"></axis>
		<limit effort="30" lower="-6.28318530718" upper="6.28318530718" velocity="3.14"></limit>
		<dynamics damping="5" friction="1"></dynamics>
	</joint>
	<joint name="xarm7_joint6" type="revolute">
		<origin rpy="1.5708 0 0" xyz="0 0 0"></origin>
		<parent link="link5"></parent>
		<child link="link6"></child>
		<axis xyz="0 0 1"></axis>
		<limit effort="20" lower="-1.69297" upper="3.14159265359" velocity="3.14"></limit>
		<dynamics damping="2" friction="1"></dynamics>
	</joint>
	<joint name="xarm7_joint7" type="revolute">
		<origin rpy="-1.5708 0 0" xyz="0.076 0.097 0"></origin>
		<parent link="link6"></parent>
		<child link="link7"></child>
		<axis xyz="0 0 1"></axis>
		<limit effort="20" lower="-6.28318530718" upper="6.28318530718" velocity="3.14"></limit>
		<dynamics damping="2" friction="1"></dynamics>
	</joint>
	<joint name="part_studio_joint" type="fixed">
		<parent link="link7"></parent>
		<child link="palm_link"></child>
		<origin rpy="3.14 0 0" xyz="0.06 -0.0375 0.0135"></origin>
	</joint>
	<joint name="leap_joint0" type="revolute">
		<origin xyz="-0.012200000000000007713 0.038099999999999994982 0.014500000000000000736" rpy="-1.570796326794896558 -1.0065212660796336576e-15 1.5707963267948943376"></origin>
		<parent link="mcp_joint_1"></parent>
		<child link="pip_1"></child>
		<axis xyz="0 0 -1"></axis>
		<limit effort="0.95" velocity="8.48" lower="-1.047" upper="1.047"></limit>
		<joint_properties friction="0.0"></joint_properties>
	</joint>
	<joint name="leap_joint1" type="revolute">
		<origin xyz="-0.0070952496528625457958 0.023057756134899472233 -0.01872240357846021927" rpy="1.5707963267948950037 1.5707963267948945596 0"></origin>
		<parent link="palm_link"></parent>
		<child link="mcp_joint_1"></child>
		<axis xyz="0 0 -1"></axis>
		<limit effort="0.95" velocity="8.48" lower="-0.314" upper="2.23"></limit>
		<joint_properties friction="0.0"></joint_properties>
	</joint>
	<joint name="leap_joint2" type="revolute">
		<origin xyz="0.01499999999999996822 0.014299999999999904801 -0.012999999999999824196" rpy="1.5707963267948958919 -1.570796326794896336 0"></origin>
		<parent link="pip_1"></parent>
		<child link="dip_1"></child>
		<axis xyz="0 0 -1"></axis>
		<limit effort="0.95" velocity="8.48" lower="-0.506" upper="1.885"></limit>
		<joint_properties friction="0.0"></joint_properties>
	</joint>
	<joint name="leap_joint3" type="revolute">
		<origin xyz="-4.0880582495572692636e-09 -0.036100004210367367397 0.00020000000000007858714" rpy="4.5935029425113685044e-17 -2.8730071914463794583e-16 4.4395481053923607589e-32"></origin>
		<parent link="dip_1"></parent>
		<child link="fingertip_1"></child>
		<axis xyz="0 0 -1"></axis>
		<limit effort="0.95" velocity="8.48" lower="-0.366" upper="2.042"></limit>
		<joint_properties friction="0.0"></joint_properties>
	</joint>
	<joint name="leap_joint4" type="revolute">
		<origin xyz="-0.012200000000000019856 0.038099999999999981104 0.01450000000000000594" rpy="-1.570796326794896558 -1.0065212760057939085e-15 1.5707963267948943376"></origin>
		<parent link="mcp_joint_2"></parent>
		<child link="pip_2"></child>
		<axis xyz="0 0 -1"></axis>
		<limit effort="0.95" velocity="8.48" lower="-1.047" upper="1.047"></limit>
		<joint_properties friction="0.0"></joint_properties>
	</joint>
	<joint name="leap_joint5" type="revolute">
		<origin xyz="-0.0070952496528625388569 -0.022392243865100525113 -0.018722403578460229678" rpy="1.570796326794896558 1.570796326794896558 0"></origin>
		<parent link="palm_link"></parent>
		<child link="mcp_joint_2"></child>
		<axis xyz="0 0 -1"></axis>
		<limit effort="0.95" velocity="8.48" lower="-0.314" upper="2.23"></limit>
		<joint_properties friction="0.0"></joint_properties>
	</joint>
	<joint name="leap_joint6" type="revolute">
		<origin xyz="0.014999999999999975159 0.014300000000000000211 -0.013000000000000018485" rpy="1.5707963267948958919 -1.570796326794896336 0"></origin>
		<parent link="pip_2"></parent>
		<child link="dip_2"></child>
		<axis xyz="0 0 -1"></axis>
		<limit effort="0.95" velocity="8.48" lower="-0.506" upper="1.885"></limit>
		<joint_properties friction="0.0"></joint_properties>
	</joint>
	<joint name="leap_joint7" type="revolute">
		<origin xyz="1.0061396160665481148e-16 -0.036099999999999854428 0.00020000000000007858714" rpy="4.5935029425113654229e-17 -2.8730071914463794583e-16 1.4408183216511868558e-31"></origin>
		<parent link="dip_2"></parent>
		<child link="fingertip_2"></child>
		<axis xyz="0 0 -1"></axis>
		<limit effort="0.95" velocity="8.48" lower="-0.366" upper="2.042"></limit>
		<joint_properties friction="0.0"></joint_properties>
	</joint>
	<joint name="leap_joint8" type="revolute">
		<origin xyz="-0.012200000000000004244 0.038100000000000001921 0.014499999999999999001" rpy="-1.570796326794896558 -1.0065212660796360242e-15 1.5707963267948943376"></origin>
		<parent link="mcp_joint_3"></parent>
		<child link="pip_3"></child>
		<axis xyz="0 0 -1"></axis>
		<limit effort="0.95" velocity="8.48" lower="-1.047" upper="1.047"></limit>
		<joint_properties friction="0.0"></joint_properties>
	</joint>
	<joint name="leap_joint9" type="revolute">
		<origin xyz="-0.0070952454426398371343 -0.067842243865100515521 -0.018722407666402932774" rpy="1.5707963267948950037 1.5707963267948945596 0"></origin>
		<parent link="palm_link"></parent>
		<child link="mcp_joint_3"></child>
		<axis xyz="0 0 -1"></axis>
		<limit effort="0.95" velocity="8.48" lower="-0.314" upper="2.23"></limit>
		<joint_properties friction="0.0"></joint_properties>
	</joint>
	<joint name="leap_joint10" type="revolute">
		<origin xyz="0.014999999999999971689 0.014299999999999951639 -0.012999999999999959505" rpy="1.5707963267948958919 -1.570796326794896336 0"></origin>
		<parent link="pip_3"></parent>
		<child link="dip_3"></child>
		<axis xyz="0 0 -1"></axis>
		<limit effort="0.95" velocity="8.48" lower="-0.506" upper="1.885"></limit>
		<joint_properties friction="0.0"></joint_properties>
	</joint>
	<joint name="leap_joint11" type="revolute">
		<origin xyz="9.7144514654701197287e-17 -0.036099999999999868305 0.00020000000000007511769" rpy="4.5935029425113685044e-17 -2.8730071914463799514e-16 1.5565411607615035382e-32"></origin>
		<parent link="dip_3"></parent>
		<child link="fingertip_3"></child>
		<axis xyz="0 0 -1"></axis>
		<limit effort="0.95" velocity="8.48" lower="-0.366" upper="2.042"></limit>
		<joint_properties friction="0.0"></joint_properties>
	</joint>
	<joint name="leap_joint12" type="revolute">
		<origin xyz="-0.069395249652862533996 -0.0012422438651005258004 -0.021622403578460215601" rpy="-8.2381766464939424156e-17 1.5707963267948956698 0"></origin>
		<parent link="palm_link"></parent>
		<child link="pip_4"></child>
		<axis xyz="0 0 -1"></axis>
		<limit effort="0.95" velocity="8.48" lower="-0.349" upper="2.094"></limit>
		<joint_properties friction="0.0"></joint_properties>
	</joint>
	<joint name="leap_joint13" type="revolute">
		<origin xyz="-2.7755575615628913511e-17 0.014300000000000005415 -0.013000000000000011546" rpy="1.5707963267948958919 -1.570796326794896336 0"></origin>
		<parent link="pip_4"></parent>
		<child link="thumb_pip"></child>
		<axis xyz="0 0 -1"></axis>
		<limit effort="0.95" velocity="8.48" lower="-0.47" upper="2.443"></limit>
		<joint_properties friction="0.0"></joint_properties>
	</joint>
	<joint name="leap_joint14" type="revolute">
		<origin xyz="0 0.014499999999999966041 -0.017000000000000053263" rpy="-1.570796326794896558 1.6050198443300131245e-46 -1.9721522630516624601e-31"></origin>
		<parent link="thumb_pip"></parent>
		<child link="thumb_dip"></child>
		<axis xyz="0 0 -1"></axis>
		<limit effort="0.95" velocity="8.48" lower="-1.20" upper="1.90"></limit>
		<joint_properties friction="0.0"></joint_properties>
	</joint>
	<joint name="leap_joint15" type="revolute">
		<origin xyz="-1.249000902703301108e-16 0.046599999999999863753 0.00019999999999997710581" rpy="1.5063958491491781023e-44 5.4234187233935260503e-31 3.141592653589793116"></origin>
		<parent link="thumb_dip"></parent>
		<child link="thumb_fingertip"></child>
		<axis xyz="0 0 -1"></axis>
		<limit effort="0.95" velocity="8.48" lower="-1.34" upper="1.88"></limit>
		<joint_properties friction="0.0"></joint_properties>
	</joint>
</robot>